Workbook
Name _1_0BS_minor: #REF!
Name _10_0IS_straightpref: #REF!
Name _106J–Ï__íÇ: #REF!,#REF!,#REF!,#REF!,#REF!,#REF!,#REF!,#REF!,#REF!,#REF!,#REF!,#REF!
Name _107_0: #REF!,#REF!,#REF!,#REF!,#REF!,#REF!,#REF!,#REF!,#REF!,#REF!,#REF!,#REF!,#REF!,#REF!
Name _108_0_0BS_minor: #REF!
Name _109_0_0CF_minor: #REF!
Name _11_0Interc_Rev_LD_: #REF!
Name _110_0_0IS_convpref: #REF!
Name _111_0_0IS_intconv: #REF!
Name _112_0_0IS_intexist: #REF!
Name _113_0_0IS_minor: #REF!
Name _114_0_0IS_straightpref: #REF!
Name _115_0_0IS_synerg: #REF!
Name _116_0IS_synerg: #REF!
Name _117_0s: #REF!
Name _118_0Sfu: #REF!
Name _119_1: #REF!
Name _12_0Interc_Rev_Loc_: #REF!
Name _120_10: #REF!
Name _121_11: #REF!
Name _122_12: #REF!
Name _123_13: #REF!
Name _124_14: #REF!
Name _125_15: #REF!
Name _126_16: #REF!
Name _127_17: #REF!
Name _128_18: #REF!
Name _129_2: #REF!
Name _13_0OutGoingTraf: #REF!
Name _130_3: #REF!
Name _131_4: #REF!
Name _132_5: #REF!
Name _133_6: #REF!
Name _134p0t: #REF!,#REF!,#REF!,#REF!,#REF!
Name _135ÿ_0CAPEX: #REF!
Name _136ÿ_0CAPEX_: #REF!
Name _137ÿ_0CAPEX_billing_VMS_: #REF!
Name _138ÿ_0CAPEX_Civil_Wo: #REF!
Name _139ÿ_0CAPEX_computer_softw: #REF!
Name _14_0Perc_Reg_of: #REF!
Name _140ÿ_0CAPEX_Equipm: #REF!
Name _141ÿ_0CAPEX_Gateway_Equipm: #REF!
Name _142ÿ_0CAPEX_Licence_: #REF!
Name _143ÿ_0CAPEX_Microw: #REF!
Name _144ÿ_0CAPEX_office_furnit: #REF!
Name _145ÿ_0CAPEX_Subscri: #REF!
Name _146ÿ_0Cum._Invest_bill: #REF!
Name _147ÿ_0Depr_base_bill: #REF!
Name _148ÿ_0Depr_base_equipm: #REF!
Name _149ÿ_0Depr_bill: #REF!
Name _15_0BS_minor: #REF!
Name _150ÿ_0Depr_civil_wo: #REF!
Name _151ÿ_0Depr_computer_softw: #REF!
Name _152ÿ_0Depr_equipm: #REF!
Name _153ÿ_0Depr_lice: #REF!
Name _154ÿ_0Depr_office_furnit: #REF!
Name _155ÿ_0GSM_In: #REF!
Name _156ÿ_0Invest: #REF!
Name _157ÿ_0Invest_: #REF!
Name _158ÿ_0Invest_Gatew: #REF!

Sheet Macro
A2: =DCF!$A$2 -> Cury - TP: R$48
A3: Status | B3: =B4&RIGHT(B5,2)&B6 -> 1Q04 | C3: =C4&RIGHT(C5,2)&C6 -> 2Q04 | D3: =D4&RIGHT(D5,2)&D6 -> 3Q04 | E3: =E4&RIGHT(E5,2)&E6 -> 4Q04 | F3: =F4&RIGHT(F5,2)&F6 -> 2004 | G3: =G4&RIGHT(G5,2)&G6 -> 1Q05 | H3: =H4&RIGHT(H5,2)&H6 -> 2Q05 | I3: =I4&RIGHT(I5,2)&I6 -> 3Q05 | ... EF3: =EF4&RIGHT(EF5,2)&EF6 -> 2030E
A4: Quarter | B4: 1Q | C4: 2Q | D4: 3Q | E4: 4Q | F4: 20 | G4: 1Q | H4: 2Q | I4: 3Q | J4: 4Q | K4: 20 | L4: 1Q | M4: 2Q | N4: 3Q | O4: 4Q | P4: 20 | Q4: 1Q | R4: 2Q | S4: 3Q | T4: 4Q | U4: 20 | V4: 1Q | W4: 2Q | X4: 3Q | Y4: 4Q | Z4: 20 | AA4: 1Q | AB4: 2Q | AC4: 3Q | AD4: 4Q | AE4: 20 | AF4: 1Q | AG4: 2Q | AH4: 3Q | AI4: 4Q | AJ4: 20 | AK4: 1Q | AL4: 2Q | AM4: 3Q | AN4: 4Q | AO4: 20 | AP4: 1Q | AQ4: 2Q | AR4: 3Q | AS4: 4Q | AT4: 20 | AU4: 1Q | AV4: 2Q | AW4: 3Q | AX4: 4Q | AY4: 20 | AZ4: 1Q | BA4: 2Q | BB4: 3Q | BC4: 4Q | BD4: 20 | BE4: 1Q | BF4: 2Q | BG4: 3Q | BH4: 4Q | BI4: 20 | BJ4: 1Q | BK4: 2Q | BL4: 3Q | BM4: 4Q | BN4: 20 | BO4: 1Q | BP4: 2Q | BQ4: 3Q | BR4: 4Q | BS4: 20 | BT4: 1Q | BU4: 2Q | BV4: 3Q | BW4: 4Q | BX4: 20 | BY4: 1Q | BZ4: 2Q | CA4: 3Q | CB4: 4Q | CC4: 20 | CD4: 1Q | CE4: 2Q | CF4: 3Q | CG4: 4Q | CH4: 20 | CI4: 1Q | CJ4: 2Q | CK4: 3Q | CL4: 4Q | CM4: 20 | CN4: 1Q | CO4: 2Q | CP4: 3Q | CQ4: 4Q | CR4: 20 | CS4: 1Q | CT4: 2Q | CU4: 3Q | CV4: 4Q | CW4: 20 | CX4: 1Q | CY4: 2Q | CZ4: 3Q | DA4: 4Q | DB4: 20 | DC4: 1Q | DD4: 2Q | DE4: 3Q | DF4: 4Q | DG4: 20 | DH4: 1Q | DI4: 2Q | DJ4: 3Q | DK4: 4Q | DL4: 20 | DM4: 1Q | DN4: 2Q | DO4: 3Q | DP4: 4Q | DQ4: 20 | DR4: 1Q | DS4: 2Q | DT4: 3Q | DU4: 4Q | DV4: 20 | DW4: 1Q | DX4: 2Q | DY4: 3Q | DZ4: 4Q | EA4: 20 | EB4: 1Q | EC4: 2Q | ED4: 3Q | EE4: 4Q | EF4: 20
A5: Year | B5: 2004 | C5: 2004 | D5: 2004 | E5: 2004 | F5: =E5 -> 2004 | G5: =B5+1 -> 2005 | H5: =C5+1 -> 2005 | I5: =D5+1 -> 2005 | J5: =E5+1 -> 2005 | K5: =J5 -> 2005 | L5: =G5+1 -> 2006 | M5: =H5+1 -> 2006 | N5: =I5+1 -> 2006 | O5: =J5+1 -> 2006 | P5: =O5 -> 2006 | Q5: =L5+1 -> 2007 | R5: =M5+1 -> 2007 | S5: =N5+1 -> 2007 | T5: =O5+1 -> 2007 | U5: =T5 -> 2007 | V5: =Q5+1 -> 2008 | W5: =R5+1 -> 2008 | X5: =S5+1 -> 2008 | Y5: =T5+1 -> 2008 | Z5: =Y5 -> 2008 | AA5: =V5+1 -> 2009 | AB5: =W5+1 -> 2009 | AC5: =X5+1 -> 2009 | AD5: =Y5+1 -> 2009 | AE5: =AD5 -> 2009 | AF5: =AA5+1 -> 2010 | AG5: =AB5+1 -> 2010 | AH5: =AC5+1 -> 2010 | AI5: =AD5+1 -> 2010 | AJ5: =AI5 -> 2010 | AK5: =AF5+1 -> 2011 | AL5: =AG5+1 -> 2011 | AM5: =AH5+1 -> 2011 | AN5: =AI5+1 -> 2011 | AO5: =AN5 -> 2011 | AP5: =AK5+1 -> 2012 | AQ5: =AL5+1 -> 2012 | AR5: =AM5+1 -> 2012 | AS5: =AN5+1 -> 2012 | AT5: =AO5+1 -> 2012 | AU5: =AP5+1 -> 2013 | AV5: =AQ5+1 -> 2013 | AW5: =AR5+1 -> 2013 | ... EF5: =EA5+1 -> 2030
A6: Actual/Estimate | DJ6: E | DK6: E | DL6: E | DM6: E | DN6: E | DO6: E | DP6: E | DQ6: E | DR6: E | DS6: E | DT6: E | DU6: E | DV6: E | DW6: E | DX6: E | DY6: E | DZ6: E | EA6: E | EB6: E | EC6: E | ED6: E | EE6: E | EF6: E
A7: Days in Quarter | B7: 91 | C7: 91 | D7: 92 | E7: 92 | F7: =SUM(B7:E7) -> 366 | G7: 90 | H7: 91 | I7: 92 | J7: 92 | K7: =SUM(G7:J7) -> 365 | L7: 90 | M7: 91 | N7: 92 | O7: 92 | P7: =SUM(L7:O7) -> 365 | Q7: 90 | R7: 91 | S7: 92 | T7: 92 | U7: =SUM(Q7:T7) -> 365 | V7: 91 | W7: 91 | X7: 92 | Y7: 92 | Z7: =SUM(V7:Y7) -> 366 | AA7: 90 | AB7: 91 | AC7: 92 | AD7: 92 | AE7: =SUM(AA7:AD7) -> 365 | AF7: 90 | AG7: 91 | AH7: 92 | AI7: 92 | AJ7: =SUM(AF7:AI7) -> 365 | AK7: 90 | AL7: 91 | AM7: 92 | AN7: 92 | AO7: =SUM(AK7:AN7) -> 365 | AP7: 90 | AQ7: 91 | AR7: 92 | AS7: 92 | AT7: 366 | AU7: 90 | AV7: 91 | AW7: 92 | AX7: 92 | AY7: =SUM(AU7:AX7) -> 365 | AZ7: 90 | BA7: 91 | BB7: 92 | BC7: 92 | BD7: =SUM(AZ7:BC7) -> 365 | BE7: 90 | BF7: 91 | BG7: 92 | BH7: 92 | BI7: =SUM(BE7:BH7) -> 365 | BJ7: 90 | BK7: 91 | BL7: 92 | BM7: 92 | BN7: =SUM(BJ7:BM7) -> 365 | BO7: 90 | BP7: 91 | BQ7: 92 | BR7: 92 | BS7: =SUM(BO7:BR7) -> 365 | BT7: 90 | BU7: 91 | BV7: 92 | BW7: 92 | BX7: =SUM(BT7:BW7) -> 365 | BY7: 90 | BZ7: 91 | CA7: 92 | CB7: 92 | CC7: =SUM(BY7:CB7) -> 365 | CD7: 90 | CE7: 91 | CF7: 92 | CG7: 92 | CH7: =SUM(CD7:CG7) -> 365 | CI7: 90 | CJ7: 91 | CK7: 92 | CL7: 92 | CM7: =SUM(CI7:CL7) -> 365 | CN7: 90 | CO7: 91 | CP7: 92 | CQ7: 92 | CR7: =SUM(CN7:CQ7) -> 365 | CS7: 90 | CT7: 91 | CU7: 92 | CV7: 92 | CW7: =SUM(CS7:CV7) -> 365 | CX7: 90 | CY7: 91 | CZ7: 92 | DA7: 92 | DB7: =SUM(CX7:DA7) -> 365 | DC7: 90 | DD7: 91 | DE7: 92 | DF7: 92 | DG7: =SUM(DC7:DF7) -> 365 | DH7: 90 | DI7: 91 | DJ7: 92 | DK7: 92 | DL7: =SUM(DH7:DK7) -> 365 | DM7: 90 | DN7: 91 | DO7: 92 | DP7: 92 | DQ7: =SUM(DM7:DP7) -> 365 | DR7: 90 | DS7: 91 | DT7: 92 | DU7: 92 | DV7: =SUM(DR7:DU7) -> 365 | DW7: 90 | DX7: 91 | DY7: 92 | DZ7: 92 | EA7: =SUM(DW7:DZ7) -> 365 | EB7: 90 | EC7: 91 | ED7: 92 | EE7: 92 | EF7: =SUM(EB7:EE7) -> 365
B9: =B$3 -> 1Q04 | C9: =C$3 -> 2Q04 | D9: =D$3 -> 3Q04 | E9: =E$3 -> 4Q04 | F9: =F$3 -> 2004 | G9: =G$3 -> 1Q05 | H9: =H$3 -> 2Q05 | I9: =I$3 -> 3Q05 | ... EF9: =EF$3 -> 2030E
A10: GDP Growth | B10: 0.018625076 | C10: 0.034978624 | D10: 0.046182359 | E10: 0.05690445 | F10: 0.05690445 | G10: 0.050839899 | H10: 0.040117662 | I10: 0.035368516 | J10: 0.031478279 | K10: 0.031478279 | L10: 0.035123174 | M10: 0.03287402 | N10: 0.035871317 | O10: 0.039296141 | P10: 0.039296141 | Q10: 0.041838309 | R10: 0.05276138 | S10: 0.0558906 | T10: 0.060872371 | U10: 0.060872371 | V10: 0.063938236 | W10: 0.063785439 | X10: 0.066447177 | Y10: 0.051439409 | Z10: 0.051439409 | AA10: 0.029907003 | AB10: 0.0094328172 | AC10: -0.010336182 | AD10: -0.0017527142 | AE10: -0.0017527142 | AF10: 0.092714294 | AG10: 0.091562714 | AH10: 0.067385174 | AI10: 0.050367589 | AJ10: 0.075 | AK10: 0.04235654 | AL10: 0.03314358 | AM10: 0.021219664 | AN10: 0.013664596 | AO10: 0.027325092 | AP10: 0.007973 | AQ10: 0.005509 | AR10: 0.009444 | AS10: 0.01825 | AT10: 0.01 | AU10: 0.0189 | AV10: 0.0346 | AW10: 0.0243 | AX10: 0.0217 | AY10: 0.025 | AZ10: 0.0191 | BA10: 0.004 | BB10: 0.011 | BC10: 0.01 | BD10: 0.0014458389 | BE10: -0.0081656208 | BF10: -0.017777081 | BG10: -0.02738854 | BH10: -0.037 | BI10: -0.037 | BJ10: -0.03475 | BK10: -0.0325 | BL10: -0.03025 | BM10: -0.028 | BN10: -0.028 | BO10: 0.005 | BP10: 0.005 | BQ10: 0.005 | BR10: 0.005 | BS10: 0.01 | BT10: 0.0032837896 | BU10: 0.0032837896 | BV10: 0.0032837896 | BW10: 0.0032837896 | BX10: 0.0132 | BY10: 0.0027387285 | BZ10: 0.0027387285 | CA10: 0.0027387285 | CB10: 0.0027387285 | CC10: 0.011 | CD10: -0.01 | CE10: -0.01 | CF10: -0.01 | CG10: -0.01 | CH10: -0.041 | CI10: 0.03 | CJ10: 0.03 | CK10: 0.03 | CL10: 0.03 | CM10: 0.046 | CN10: 0.02 | CO10: 0.02 | CP10: 0.02 | CQ10: 0.02 | CR10: 0.03 | CS10: 0.02 | CT10: 0.02 | CU10: 0.02 | CV10: 0.02 | CW10: 0.029 | CX10: 0.02 | CY10: 0.02 | CZ10: 0.02 | DA10: 0.02 | DB10: 0.034 | DC10: 0.02 | DD10: 0.02 | DE10: 0.02 | DF10: 0.02 | DG10: 0.02 | DH10: 0.02 | DI10: 0.02 | DJ10: 0.02 | DK10: 0.02 | DL10: 0.02 | DM10: 0.02 | DN10: 0.02 | DO10: 0.02 | DP10: 0.02 | DQ10: 0.02 | DR10: 0.02 | DS10: 0.02 | DT10: 0.02 | DU10: 0.02 | DV10: 0.02 | DW10: 0.02 | DX10: 0.02 | DY10: 0.02 | DZ10: 0.02 | EA10: 0.02 | EB10: 0.02 | EC10: 0.02 | ED10: 0.02 | EE10: 0.02 | EF10: 0.02
A11: R$/US$ EoP | B11: 2.9086 | C11: 3.1075 | D11: 2.8586 | E11: 2.6544 | F11: 2.6544 | G11: 2.6662 | H11: 2.3504 | I11: 2.2222 | J11: 2.3407 | K11: 2.3407 | L11: 2.1724 | M11: 2.1643 | N11: 2.1742 | O11: 2.138 | P11: 2.138 | Q11: 2.0504 | R11: 1.9262 | S11: 1.8389 | T11: 1.7713 | U11: 1.7713 | V11: 1.7491 | W11: 1.5919 | X11: 1.9143 | Y11: 2.337 | Z11: 2.337 | AA11: 2.3152 | AB11: 1.9516 | AC11: 1.7781 | AD11: 1.7412 | AE11: 1.7412 | AF11: 1.781 | AG11: 1.8015 | AH11: 1.6942 | AI11: 1.7161 | AJ11: 1.6662 | AK11: 1.6318 | AL11: 1.5633 | AM11: 1.8793 | AN11: 1.8668 | AO11: 1.8758 | AP11: 1.82 | AQ11: 2.02 | AR11: 2.03 | AS11: 2.04 | AT11: 2.04 | AU11: 2.0138 | AV11: 2.2156 | AW11: 2.23 | AX11: 2.3426 | AY11: 2.34 | AZ11: 2.263 | BA11: 2.29 | BB11: 2.34 | BC11: 2.4 | BD11: 2.6562 | BE11: 3.208 | BF11: 3.1026 | BG11: 3.9729 | BH11: 3.9048 | BI11: 3.8 | BJ11: 3.5589 | BK11: 3.2098 | BL11: 3.2462 | BM11: 3.2591 | BN11: 3.2591 | BO11: 3.2 | BP11: 3.12 | BQ11: 3.31 | BR11: 3.308 | BS11: 3.308 | BT11: 3.3238 | BU11: 3.8558 | BV11: 4.0039 | BW11: 3.88 | BX11: 3.88 | BY11: 3.9017478 | BZ11: 3.9236175 | CA11: 3.9456098 | CB11: 3.9677253 | CC11: 4.0307 | CD11: 5 | CE11: 5.0084136 | CF11: 5.0168413 | CG11: 5.0252832 | CH11: 4.8 | CI11: 4.872642 | CJ11: 4.9463833 | CK11: 5.0212406 | CL11: 5.0972308 | CM11: 5.5805 | CN11: 5.6316783 | CO11: 5.683326 | CP11: 5.7354473 | CQ11: 5.7880467 | CR11: 5.2177 | CS11: 5.2508591 | CT11: 5.284229 | CU11: 5.3178109 | CV11: 5.3516063 | CW11: 4.8513 | CX11: 4.8845909 | CY11: 4.9181102 | CZ11: 4.9518595 | DA11: 4.9858404 | DB11: 6.1923 | DC11: 5.9623333 | DD11: 5.7323667 | DE11: 5.6173833 | DF11: 5.5024 | DG11: 5.5024 | DH11: 5.5291054 | DI11: 5.5559404 | DJ11: 5.5829056 | DK11: 5.6100017 | DL11: 5.6100017 | DM11: 5.6372293 | DN11: 5.6645891 | DO11: 5.6920817 | DP11: 5.7197077 | DQ11: 5.7197077 | DR11: 5.7474677 | DS11: 5.7753625 | DT11: 5.8033927 | DU11: 5.8315589 | DV11: 5.8315589 | DW11: 5.8598619 | DX11: 5.8883021 | DY11: 5.9168805 | DZ11: 5.9455975 | EA11: 5.9455975 | EB11: 5.9744539 | EC11: 6.0034503 | ED11: 6.0325875 | EE11: 6.0618661 | EF11: 6.0618661
A12: Sequential Change | B12: 0.0067146615 | C12: 0.068383415 | D12: -0.080096541 | E12: -0.071433569 | F12: -0.081268171 | G12: 0.0044454491 | H12: -0.11844573 | I12: -0.054543907 | J12: 0.053325533 | K12: -0.11818113 | L12: -0.071901568 | M12: -0.0037285951 | N12: 0.0045742272 | O12: -0.016649802 | P12: -0.086598026 | Q12: -0.040972872 | R12: -0.060573547 | S12: -0.045322396 | T12: -0.036761107 | U12: -0.17151543 | V12: -0.012533168 | W12: -0.089874793 | X12: 0.20252528 | Y12: 0.22081178 | Z12: 0.31936995 | AA12: -0.0093281985 | AB12: -0.15704907 | AC12: -0.088901414 | AD12: -0.020752489 | AE12: -0.25494223 | AF12: -0.0069287358 | AG12: -0.0069770782 | AH12: -0.0070260998 | AI12: -0.0070758152 | AJ12: -0.027714943 | AK12: -0.049123011 | AL12: -0.041978184 | AM12: 0.20213651 | AN12: -0.0066514128 | AO12: 0.12579522 | AP12: -0.025069638 | AQ12: 0.10989011 | AR12: 0.004950495 | AS12: 0.0049261084 | AT12: 0.087535985 | AU12: -0.012843137 | AV12: 0.10020856 | AW12: 0.0064993681 | AX12: 0.050493274 | AY12: 0.14705882 | AZ12: -0.033979339 | BA12: 0.011931065 | BB12: 0.021834061 | BC12: 0.025641026 | BD12: 0.13512821 | BE12: 0.33666667 | BF12: -0.032855362 | BG12: 0.28050667 | BH12: -0.017141131 | BI12: 0.43061515 | BJ12: -0.088583282 | BK12: -0.098092107 | BL12: 0.01134027 | BM12: 0.0039738771 | BN12: -0.14234209 | BO12: -0.018133841 | BP12: -0.025 | BQ12: 0.060897436 | BR12: -0.00060422961 | BS12: 0.015004142 | BT12: 0.0047762999 | BU12: 0.16005777 | BV12: 0.038409669 | BW12: -0.030944829 | BX12: 0.17291415 | BY12: 0.0056051018 | BZ12: 0.0056051018 | CA12: 0.0056051018 | CB12: 0.0056051018 | CC12: 0.038840206 | CD12: 0.0056051018 | CE12: 0.0056051018 | CF12: 0.0056051018 | CG12: 0.0056051018 | CH12: 0.19086015 | CI12: 0.0056051018 | CJ12: 0.0056051018 | CK12: 0.0056051018 | CL12: 0.0056051018 | CM12: 0.16260417 | CN12: 0.0056051018 | CO12: 0.0056051018 | CP12: 0.0056051018 | CQ12: 0.0056051018 | CR12: -0.065012096 | CS12: 0.0056051018 | CT12: 0.0056051018 | CU12: 0.0056051018 | CV12: 0.0056051018 | CW12: -0.070222512 | CX12: 0.0056051018 | CY12: 0.0056051018 | CZ12: 0.0056051018 | DA12: 0.0056051018 | DB12: 0.27642075 | DC12: 0.0056051018 | DD12: 0.0056051018 | DE12: 0.0056051018 | DF12: 0.0056051018 | DG12: -0.11141256 | DH12: 0.0056051018 | DI12: 0.0056051018 | DJ12: 0.0056051018 | DK12: 0.0056051018 | DL12: 0.019555417 | DM12: 0.0056051018 | DN12: 0.0056051018 | DO12: 0.0056051018 | DP12: 0.0056051018 | DQ12: 0.019555417 | DR12: 0.0056051018 | DS12: 0.0056051018 | DT12: 0.0056051018 | DU12: 0.0056051018 | DV12: 0.019555417 | DW12: 0.0056051018 | DX12: 0.0056051018 | DY12: 0.0056051018 | DZ12: 0.0056051018 | EA12: 0.019555417 | EB12: 0.0056051018 | EC12: 0.0056051018 | ED12: 0.0056051018 | EE12: 0.0056051018 | EF12: 0.019555417
A13: R$/US$ Average | B13: 2.8958667 | C13: 3.0451667 | D13: 2.9769333 | E13: 2.7857 | F13: 2.9259167 | G13: 2.6651667 | H13: 2.4818333 | I13: 2.3428333 | J13: 2.2509333 | K13: 2.4351917 | L13: 2.1959333 | M13: 2.1852333 | N13: 2.1713 | O13: 2.1520333 | P13: 2.176125 | Q13: 2.1078167 | R13: 1.9818333 | S13: 1.9161333 | T13: 1.7856333 | U13: 1.9478542 | V13: 1.7365333 | W13: 1.6561 | X13: 1.6677667 | Y13: 2.2778667 | Z13: 1.8345667 | AA13: 2.3113 | AB13: 2.0748 | AC13: 1.8659333 | AD13: 1.7383667 | AE13: 1.9976 | AF13: 1.8416333 | AG13: 1.8131905 | AH13: 1.7595636 | AI13: 1.71333 | AJ13: 1.7593 | AK13: 1.6668306 | AL13: 1.5953516 | AM13: 1.6363954 | AN13: 1.8029258 | AO13: 1.6746 | AP13: 1.7687873 | AQ13: 1.9633 | AR13: 2.0279 | AS13: 2.06 | AT13: 1.9549968 | AU13: 1.9957333 | AV13: 2.07 | AW13: 2.2883 | AX13: 2.2765 | AY13: 2.1576333 | AZ13: 2.3639965 | BA13: 2.268832 | BB13: 2.33 | BC13: 2.38 | BD13: 2.3357071 | BE13: 2.8691 | BF13: 3.0709 | BG13: 3.5399 | BH13: 3.8471 | BI13: 3.33175 | BJ13: 3.67945 | BK13: 3.38435 | BL13: 3.228 | BM13: 3.25265 | BN13: 3.3861125 | BO13: 3.22955 | BP13: 3.16 | BQ13: 3.215 | BR13: 3.309 | BS13: 3.2283875 | BT13: 3.3159 | BU13: 3.5898 | BV13: 3.92985 | BW13: 3.94195 | BX13: 3.694375 | BY13: 3.8908739 | BZ13: 3.9126826 | CA13: 3.9346136 | CB13: 3.9566675 | CC13: 3.9237094 | CD13: 4.51535 | CE13: 5.0042068 | CF13: 5.0126274 | CG13: 5.0210622 | CH13: 4.8883116 | CI13: 4.836321 | CJ13: 4.9095126 | CK13: 4.983812 | CL13: 5.0592357 | CM13: 4.9472203 | CN13: 5.6060892 | CO13: 5.6575022 | CP13: 5.7093867 | CQ13: 5.761747 | CR13: 5.6836813 | CS13: 5.2342796 | CT13: 5.2675441 | CU13: 5.3010199 | CV13: 5.3347086 | CW13: 5.284388 | CX13: 4.8679454 | CY13: 4.9013505 | CZ13: 4.9349848 | DA13: 4.96885 | DB13: 4.9182827 | DC13: 6.0773167 | DD13: 5.84735 | DE13: 5.674875 | DF13: 5.5598917 | DG13: 5.7898583 | DH13: 5.5157527 | DI13: 5.5425229 | DJ13: 5.569423 | DK13: 5.5964537 | DL13: 5.5560381 | DM13: 5.6236155 | DN13: 5.6509092 | DO13: 5.6783354 | DP13: 5.7058947 | DQ13: 5.6646887 | DR13: 5.7335877 | DS13: 5.7614151 | DT13: 5.7893776 | DU13: 5.8174758 | DV13: 5.7754641 | DW13: 5.8457104 | DX13: 5.874082 | DY13: 5.9025913 | DZ13: 5.931239 | EA13: 5.8884057 | EB13: 5.9600257 | EC13: 5.9889521 | ED13: 6.0180189 | EE13: 6.0472268 | EF13: 6.0035559
A14: Sequential Change | B14: -0.0014941498 | C14: 0.051556241 | D14: -0.022407093 | E14: -0.064238366 | F14: -0.049497285 | G14: -0.043268598 | H14: -0.068788694 | I14: -0.056006984 | J14: -0.039226008 | K14: -0.16771667 | L14: -0.024434309 | M14: -0.0048726434 | N14: -0.0063761307 | O14: -0.0088733324 | P14: -0.10638451 | Q14: -0.02054646 | R14: -0.059769588 | S14: -0.033151123 | T14: -0.068105908 | U14: -0.10489785 | V14: -0.027497247 | W14: -0.046318335 | X14: 0.0070446632 | Y14: 0.36581856 | Z14: -0.058160155 | AA14: 0.014677476 | AB14: -0.10232337 | AC14: -0.10066834 | AD14: -0.068366144 | AE14: 0.088867489 | AF14: -0.04434007 | AG14: -0.006952823 | AH14: -0.0070015032 | AI14: -0.0070508699 | AJ14: -0.15792685 | AK14: -0.027139754 | AL14: -0.0428832 | AM14: 0.025727101 | AN14: 0.10176662 | AO14: -0.048144148 | AP14: -0.018935058 | AQ14: 0.10996952 | AR14: 0.032903784 | AS14: 0.015829183 | AT14: 0.16744108 | AU14: -0.031197411 | AV14: 0.03721272 | AW14: 0.10545894 | AX14: -0.0051566665 | AY14: 0.10365056 | AZ14: 0.038434655 | BA14: -0.040255779 | BB14: 0.02696014 | BC14: 0.021459227 | BD14: 0.082531995 | BE14: 0.2055042 | BF14: 0.070335645 | BG14: 0.15272396 | BH14: 0.086782112 | BI14: 0.42644169 | BJ14: -0.043578286 | BK14: -0.080202198 | BL14: -0.046197941 | BM14: 0.0076363073 | BN14: 0.016316499 | BO14: -0.0071019015 | BP14: -0.021535508 | BQ14: 0.017405063 | BR14: 0.029237947 | BS14: -0.046579963 | BT14: 0.027107186 | BU14: 0.082602009 | BV14: 0.094726726 | BW14: 0.0030789979 | BX14: 0.14434063 | BY14: 0.0030789979 | BZ14: 0.0030789979 | CA14: 0.0030789979 | CB14: 0.0030789979 | CC14: 0.06207665 | CD14: 0.0030789979 | CE14: 0.0030789979 | CF14: 0.0030789979 | CG14: 0.0030789979 | CH14: 0.24583935 | CI14: 0.0030789979 | CJ14: 0.0030789979 | CK14: 0.0030789979 | CL14: 0.0030789979 | CM14: 0.012050932 | CN14: 0.0030789979 | CO14: 0.0030789979 | CP14: 0.0030789979 | CQ14: 0.0030789979 | CR14: 0.14886358 | CS14: 0.0030789979 | CT14: 0.0030789979 | CU14: 0.0030789979 | CV14: 0.0030789979 | CW14: -0.07025257 | CX14: 0.0030789979 | CY14: 0.0030789979 | CZ14: 0.0030789979 | DA14: 0.0030789979 | DB14: -0.069280557 | DC14: 0.0030789979 | DD14: 0.0030789979 | DE14: 0.0030789979 | DF14: 0.0030789979 | DG14: 0.17721138 | DH14: 0.0030789979 | DI14: 0.0030789979 | DJ14: 0.0030789979 | DK14: 0.0030789979 | DL14: -0.040384455 | DM14: 0.0030789979 | DN14: 0.0030789979 | DO14: 0.0030789979 | DP14: 0.0030789979 | DQ14: 0.019555417 | DR14: 0.0030789979 | DS14: 0.0030789979 | DT14: 0.0030789979 | DU14: 0.0030789979 | DV14: 0.019555417 | DW14: 0.0030789979 | DX14: 0.0030789979 | DY14: 0.0030789979 | DZ14: 0.0030789979 | EA14: 0.019555417 | EB14: 0.0030789979 | EC14: 0.0030789979 | ED14: 0.0030789979 | EE14: 0.0030789979 | EF14: 0.019555417
A15: IGP-M | B15: 0.027238816 | C15: 0.039508457 | D15: 0.032535493 | E15: 0.019621757 | F15: 0.12419987 | G15: 0.015470449 | H15: 0.0019530032 | I15: -0.015125547 | J15: 0.0099229976 | K15: 0.012007603 | L15: 0.0069795279 | M15: 0.0070809203 | N15: 0.0084226293 | O15: 0.015474403 | P15: 0.03847626 | Q15: 0.011139726 | R15: 0.0034022404 | S15: 0.025690334 | T15: 0.035379965 | U15: 0.077462737 | V15: 0.023778077 | W15: 0.04336869 | X15: 0.015459458 | Y15: 0.012319512 | Z15: 0.098054313 | AA15: -0.0091980353 | AB15: -0.0031967511 | AC15: -0.003717635 | AD15: -0.0011034013 | AE15: -0.017122754 | AF15: 0.027745179 | AG15: 0.028359009 | AH15: 0.020817483 | AI15: 0.031817201 | AJ15: 0.113 | AK15: 0.024312626 | AL15: 0.0069680368 | AM15: 0.0097144444 | AN15: 0.0091198891 | AO15: 0.05096813 | AP15: 0.0061573961 | AQ15: 0.025570914 | AR15: 0.037862169 | AS15: 0.0066992596 | AT15: 0.0782 | AU15: 0.0084 | AV15: 0.009 | AW15: 0.0192 | AX15: 0.0176 | AY15: 0.055 | AZ15: 0.025462165 | BA15: 0 | BB15: 0.014 | BC15: 0.012 | BD15: 0.0369 | BE15: 0.020221661 | BF15: 0.022654151 | BG15: 0.019311654 | BH15: 0.039455778 | BI15: 0.107 | BJ15: 0.029665632 | BK15: 0.028562255 | BL15: 0.0051997258 | BM15: 0.0067134119 | BN15: 0.071729083 | BO15: -0.0013025427 | BP15: -0.0013025427 | BQ15: -0.0013025427 | BR15: -0.0013025427 | BS15: -0.0052 | BT15: 0.018244601 | BU15: 0.018244601 | BV15: 0.018244601 | BW15: 0.018244601 | BX15: 0.075 | BY15: 0.017813112 | BZ15: 0.017813112 | CA15: 0.017813112 | CB15: 0.017813112 | CC15: 0.073179 | CD15: 0.053413777 | CE15: 0.053413777 | CF15: 0.053413777 | CG15: 0.053413777 | CH15: 0.231391 | CI15: 0.041760503 | CJ15: 0.041760503 | CK15: 0.041760503 | CL15: 0.041760503 | CM15: 0.1778 | CN15: 0.013355073 | CO15: 0.013355073 | CP15: 0.013355073 | CQ15: 0.013355073 | CR15: 0.0545 | CS15: -0.0080466017 | CT15: -0.0080466017 | CU15: -0.0080466017 | CV15: -0.0080466017 | CW15: -0.0318 | CX15: 0.015963658 | CY15: 0.015963658 | CZ15: 0.015963658 | DA15: 0.015963658 | DB15: 0.0654 | DC15: -0.0026353997 | DD15: -0.0026353997 | DE15: -0.0026353997 | DF15: -0.0026353997 | DG15: -0.0105 | DH15: 0.01106499 | DI15: 0.01106499 | DJ15: 0.01106499 | DK15: 0.01106499 | DL15: 0.045 | DM15: 0.01106499 | DN15: 0.01106499 | DO15: 0.01106499 | DP15: 0.01106499 | DQ15: 0.045 | DR15: 0.01106499 | DS15: 0.01106499 | DT15: 0.01106499 | DU15: 0.01106499 | DV15: 0.045 | DW15: 0.01106499 | DX15: 0.01106499 | DY15: 0.01106499 | DZ15: 0.01106499 | EA15: 0.045 | EB15: 0.01106499 | EC15: 0.01106499 | ED15: 0.01106499 | EE15: 0.01106499 | EF15: 0.045
A16: IPCA | B16: 0.018510968 | C16: 0.015981484 | D16: 0.019415797 | E16: 0.020027801 | F16: 0.076006441 | G16: 0.017905799 | H16: 0.013439901 | I16: 0.0077189649 | J16: 0.016688199 | K16: 0.056897333 | L16: 0.014367294 | M16: 0.00099558559 | N16: 0.004505992 | O16: 0.011240999 | P16: 0.03141775 | Q16: 0.012551992 | R16: 0.0081218596 | S16: 0.0089240803 | T16: 0.014261804 | U16: 0.044573304 | V16: 0.015176027 | W16: 0.020942932 | X16: 0.010735939 | Y16: 0.010938925 | Z16: 0.059023134 | AA16: 0.012347053 | AB16: 0.013156841 | AC16: 0.0063129686 | AD16: 0.010637052 | AE16: 0.043120283 | AF16: 0.020638364 | AG16: 0.01002451 | AH16: 0.0050022902 | AI16: 0.022262182 | AJ16: 0.0591 | AK16: 0.02439696 | AL16: 0.013956003 | AM16: 0.010634041 | AN16: 0.014569972 | AO16: 0.065033527 | AP16: 0.01224539 | AQ16: 0.0108289 | AR16: 0.01416561 | AS16: 0.01992 | AT16: 0.0584 | AU16: 0.019420463 | AV16: 0.011844323 | AW16: 0.0062 | AX16: 0.0204 | AY16: 0.059 | AZ16: 0.021752379 | BA16: 0.0154 | BB16: 0.0066 | BC16: 0.0191 | BD16: 0.0641 | BE16: 0.038277997 | BF16: 0.022567505 | BG16: 0.013859074 | BH16: 0.028159295 | BI16: 0.107 | BJ16: 0.026208101 | BK16: 0.017496397 | BL16: 0.010430578 | BM16: 0.007417894 | BN16: 0.062880551 | BO16: 0.0072947902 | BP16: 0.0072947902 | BQ16: 0.0072947902 | BR16: 0.0072947902 | BS16: 0.0295 | BT16: 0.0092459757 | BU16: 0.0092459757 | BV16: 0.0092459757 | BW16: 0.0092459757 | BX16: 0.0375 | BY16: 0.010605102 | BZ16: 0.010605102 | CA16: 0.010605102 | CB16: 0.010605102 | CC16: 0.0431 | CD16: 0.0066827131 | CE16: 0.0066827131 | CF16: 0.0066827131 | CG16: 0.0066827131 | CH16: 0.027 | CI16: 0.020133746 | CJ16: 0.020133746 | CK16: 0.020133746 | CL16: 0.020133746 | CM16: 0.083 | CN16: 0.014170922 | CO16: 0.014170922 | CP16: 0.014170922 | CQ16: 0.014170922 | CR16: 0.0579 | CS16: 0.011355123 | CT16: 0.011355123 | CU16: 0.011355123 | CV16: 0.011355123 | CW16: 0.0462 | CX16: 0.011862256 | CY16: 0.011862256 | CZ16: 0.011862256 | DA16: 0.011862256 | DB16: 0.0483 | DC16: 0.010483974 | DD16: 0.010483974 | DE16: 0.010483974 | DF16: 0.010483974 | DG16: 0.0426 | DH16: 0.0098534065 | DI16: 0.0098534065 | DJ16: 0.0098534065 | DK16: 0.0098534065 | DL16: 0.04 | DM16: 0.0098534065 | DN16: 0.0098534065 | DO16: 0.0098534065 | DP16: 0.0098534065 | DQ16: 0.04 | DR16: 0.0098534065 | DS16: 0.0098534065 | DT16: 0.0098534065 | DU16: 0.0098534065 | DV16: 0.04 | DW16: 0.0098534065 | DX16: 0.0098534065 | DY16: 0.0098534065 | DZ16: 0.0098534065 | EA16: 0.04 | EB16: 0.0098534065 | EC16: 0.0098534065 | ED16: 0.0098534065 | EE16: 0.0098534065 | EF16: 0.04
A17: CDI | B17: 0.15891187 | C17: 0.15435042 | D17: 0.16350861 | E17: 0.16948771 | F17: 0.16155114 | G17: 0.1778254 | H17: 0.19514372 | I17: 0.20317559 | J17: 0.1838907 | K17: 0.18996837 | L17: 0.17179576 | M17: 0.15115659 | N17: 0.14797492 | O17: 0.13084663 | P17: 0.15035162 | Q17: 0.12681933 | R17: 0.1205915 | S17: 0.11615637 | T17: 0.10910245 | U17: 0.11814874 | V17: 0.10734371 | W17: 0.11439214 | X17: 0.13443413 | Y17: 0.1393809 | Z17: 0.12380815 | AA17: 0.12058908 | AB17: 0.098592428 | AC17: 0.08990374 | AD17: 0.086015281 | AE17: 0.098694035 | AF17: 0.0875 | AG17: 0.0975 | AH17: 0.1075 | AI17: 0.1075 | AJ17: 0.1 | AK17: 0.11333333 | AL17: 0.12012097 | AM17: 0.12280769 | AN17: 0.11415385 | AO17: 0.11708333 | AP17: 0.1025 | AQ17: 0.086666667 | AR17: 0.076666667 | AS17: 0.0725 | AT17: 0.08458 | AU17: 0.0725 | AV17: 0.078333333 | AW17: 0.088333333 | AX17: 0.098333333 | AY17: 0.0844 | AZ17: 0.10666667 | BA17: 0.11 | BB17: 0.11 | BC17: 0.11 | BD17: 0.11020833 | BE17: 0.1225 | BF17: 0.1325 | BG17: 0.14 | BH17: 0.1425 | BI17: 0.13583333 | BJ17: 0.1425 | BK17: 0.1425 | BL17: 0.1425 | BM17: 0.14 | BN17: 0.14 | BO17: 0.13 | BP17: 0.1125 | BQ17: 0.095 | BR17: 0.07875 | BS17: 0.095625 | BT17: 0.069166667 | BU17: 0.0675 | BV17: 0.065833333 | BW17: 0.065 | BX17: 0.06625 | BY17: 0.0625 | BZ17: 0.0575 | CA17: 0.0525 | CB17: 0.0475 | CC17: 0.0525 | CD17: 0.04125 | CE17: 0.03375 | CF17: 0.02625 | CG17: 0.0225 | CH17: 0.028125 | CI17: 0.031875 | CJ17: 0.050625 | CK17: 0.069375 | CL17: 0.088125 | CM17: 0.069375 | CN17: 0.1075 | CO17: 0.125 | CP17: 0.135 | CQ17: 0.1375 | CR17: 0.13125 | CS17: 0.135 | CT17: 0.13 | CU17: 0.125 | CV17: 0.12 | CW17: 0.125 | CX17: 0.114375 | CY17: 0.108125 | CZ17: 0.10625 | DA17: 0.115 | DB17: 0.1115625 | DC17: 0.1325 | DD17: 0.14625 | DE17: 0.15 | DF17: 0.15 | DG17: 0.148125 | DH17: 0.1475 | DI17: 0.1425 | DJ17: 0.1375 | DK17: 0.1325 | DL17: 0.1375 | DM17: 0.13 | DN17: 0.13 | DO17: 0.13 | DP17: 0.13 | DQ17: 0.13 | DR17: 0.13 | DS17: 0.13 | DT17: 0.13 | DU17: 0.13 | DV17: 0.13 | DW17: 0.13 | DX17: 0.13 | DY17: 0.13 | DZ17: 0.13 | EA17: 0.13 | EB17: 0.13 | EC17: 0.13 | ED17: 0.13 | EE17: 0.13 | EF17: 0.13
A18: INCC (lag) | U18: =U15 -> 0.077462737 | V18: =V15 -> 0.023778077 | W18: =W15 -> 0.04336869 | X18: =X15 -> 0.015459458 | Y18: =Y15 -> 0.012319512 | Z18: =Z15 -> 0.098054313 | AA18: 0.007 | AB18: 0.008 | AC18: 0.015 | AD18: 0.005 | AE18: =AE19 -> 0.035 | AF18: 0.010336071 | AG18: 0.01967952 | AH18: 0.033810947 | AI18: 0.0054064582 | AJ18: =(1+AF18)*(1+AG18)*(1+AH18)*(1+AI18)-1 -> 0.070809838 | AK18: 0.014508921 | AL18: 0.0177 | AM18: 0.0376 | AN18: 0.005 | AO18: =(1+AK18)*(1+AL18)*(1+AM18)*(1+AN18)-1 -> 0.076642873 | AP18: 0.017256562 | AQ18: 0.015616554 | AR18: 0.0329 | AS18: 0.0069 | AT18: =(1+AP18)*(1+AQ18)*(1+AR18)*(1+AS18)-1 -> 0.074496214 | AU18: 0.0114 | AV18: 0.0184 | AW18: 0.035 | AX18: =AW15 -> 0.0192 | AY18: =(1+AU18)*(1+AV18)*(1+AW18)*(1+AX18)-1 -> 0.086528456 | AZ18: =AX15 -> 0.0176 | BA18: =AZ15*0.8 -> 0.020369732 | BB18: 0.02 | BC18: =BB15 -> 0.014 | BD18: =(1+AZ18)*(1+BA18)*(1+BB18)*(1+BC18)-1 -> 0.073922131 | BE18: =BC15 -> 0.012 | BF18: =BE15 -> 0.020221661 | BG18: =BF15*1.5 -> 0.033981227 | BH18: =BG15 -> 0.019311654 | BI18: =(1+BE18)*(1+BF18)*(1+BG18)*(1+BH18)-1 -> 0.088164857 | BJ18: =BH15 -> 0.039455778 | BK18: =BJ15 -> 0.029665632 | BL18: =BK15*1.5 -> 0.042843382 | BM18: =BL15 -> 0.0051997258 | BN18: =(1+BJ18)*(1+BK18)*(1+BL18)*(1+BM18)-1 -> 0.12195047 | BO18: =BM15 -> 0.0067134119 | BP18: =BO15 -> -0.0013025427 | BQ18: =BP15*1.5 -> -0.0019538141 | BR18: =BQ15 -> -0.0013025427 | BS18: =(1+BO18)*(1+BP18)*(1+BQ18)*(1+BR18)-1 -> 0.0021307353 | BT18: =BR15 -> -0.0013025427 | BU18: =BT15 -> 0.018244601 | BV18: =BU15*1.5 -> 0.027366902 | BW18: =BV15 -> 0.018244601 | BX18: =(1+BT18)*(1+BU18)*(1+BV18)*(1+BW18)-1 -> 0.063809211 | BY18: =BW15 -> 0.018244601 | BZ18: =BY15 -> 0.017813112 | CA18: =BZ15*1.5 -> 0.026719668 | CB18: =CA15 -> 0.017813112 | CC18: =(1+BY18)*(1+BZ18)*(1+CA18)*(1+CB18)-1 -> 0.083028987 | CD18: =CB15 -> 0.017813112 | CE18: =CD15 -> 0.053413777 | CF18: =CE15*1.5 -> 0.080120665 | CG18: =CF15 -> 0.053413777 | CH18: =(1+CD18)*(1+CE18)*(1+CF18)*(1+CG18)-1 -> 0.21993953 | CI18: =CG15 -> 0.053413777 | CJ18: =CI15 -> 0.041760503 | CK18: =CJ15*1.5 -> 0.062640754 | CL18: =CK15 -> 0.041760503 | CM18: =(1+CI18)*(1+CJ18)*(1+CK18)*(1+CL18)-1 -> 0.21484602 | CN18: =CL15 -> 0.041760503 | CO18: =CN15 -> 0.013355073 | CP18: =CO15*1.5 -> 0.02003261 | CQ18: =CP15 -> 0.013355073 | CR18: =(1+CN18)*(1+CO18)*(1+CP18)*(1+CQ18)-1 -> 0.091202207 | CS18: =CQ15 -> 0.013355073 | CT18: =CS15 -> -0.0080466017 | CU18: =CT15*1.5 -> -0.012069903 | CV18: =CU15 -> -0.0080466017 | CW18: =(1+CS18)*(1+CT18)*(1+CU18)*(1+CV18)-1 -> -0.014922495 | CX18: =CV15 -> -0.0080466017 | CY18: =CX15 -> 0.015963658 | CZ18: =CY15*1.5 -> 0.023945487 | DA18: =CZ15 -> 0.015963658 | DB18: =(1+CX18)*(1+CY18)*(1+CZ18)*(1+DA18)-1 -> 0.04839382 | DC18: =DA15 -> 0.015963658 | DD18: =DC15 -> -0.0026353997 | DE18: =DD15*1.5 -> -0.0039530996 | DF18: =DE15 -> -0.0026353997 | DG18: =(1+DC18)*(1+DD18)*(1+DE18)*(1+DF18)-1 -> 0.0066207088 | DH18: =DF15 -> -0.0026353997 | DI18: =DH15 -> 0.01106499 | DJ18: =DI15*1.5 -> 0.016597486 | DK18: =DJ15 -> 0.01106499 | DL18: =(1+DH18)*(1+DI18)*(1+DJ18)*(1+DK18)-1 -> 0.036480477 | DM18: =DK15 -> 0.01106499 | DN18: =DM15 -> 0.01106499 | DO18: =DN15*1.5 -> 0.016597486 | DP18: =DO15 -> 0.01106499 | DQ18: =(1+DM18)*(1+DN18)*(1+DO18)*(1+DP18)-1 -> 0.050718186 | DR18: =DP15 -> 0.01106499 | DS18: =DR15 -> 0.01106499 | DT18: =DS15*1.5 -> 0.016597486 | DU18: =DT15 -> 0.01106499 | DV18: =(1+DR18)*(1+DS18)*(1+DT18)*(1+DU18)-1 -> 0.050718186 | DW18: =DU15 -> 0.01106499 | DX18: =DW15 -> 0.01106499 | DY18: =DX15*1.5 -> 0.016597486 | DZ18: =DY15 -> 0.01106499 | EA18: =(1+DW18)*(1+DX18)*(1+DY18)*(1+DZ18)-1 -> 0.050718186 | EB18: =DZ15 -> 0.01106499 | EC18: =EB15 -> 0.01106499 | ED18: =EC15*1.5 -> 0.016597486 | EE18: =ED15 -> 0.01106499 | EF18: =(1+EB18)*(1+EC18)*(1+ED18)*(1+EE18)-1 -> 0.050718186
B19: =#REF!+#REF!+#REF!+B15 -> #REF! | C19: =#REF!+#REF!+B15+C15 -> #REF! | D19: =#REF!+B15+C15+D15 -> #REF! | E19: =B15+C15+D15+E15 -> 0.11890452 | F19: =F15 -> 0.12419987 | G19: =C15+D15+E15+G15 -> 0.10713616 | H19: =D15+E15+G15+H15 -> 0.069580702 | I19: =E15+G15+H15+I15 -> 0.021919662 | J19: =G15+H15+I15+J15 -> 0.012220903 | K19: =K15 -> 0.012007603 | L19: =H15+I15+J15+L15 -> 0.0037299816 | M19: =I15+J15+L15+M15 -> 0.0088578987 | N19: =J15+L15+M15+N15 -> 0.032406075 | O19: =L15+M15+N15+O15 -> 0.03795748 | P19: =P15 -> 0.03847626 | Q19: =M15+N15+O15+Q15 -> 0.042117678 | R19: =N15+O15+Q15+R15 -> 0.038438998 | S19: =O15+Q15+R15+S15 -> 0.055706703 | T19: =Q15+R15+S15+T15 -> 0.075612265 | U19: =U15 -> 0.077462737 | V19: =R15+S15+T15+V15 -> 0.088250617 | W19: =S15+T15+V15+W15 -> 0.12821707 | X19: =T15+V15+W15+X15 -> 0.11798619 | Y19: =V15+W15+X15+Y15 -> 0.094925737 | Z19: =Z15 -> 0.098054313 | AA19: =W15+X15+Y15+AA15 -> 0.061949624 | AB19: 0.05 | AC19: 0.04 | AD19: 0.035 | AE19: =AD19 -> 0.035 | AF19: =AB15+AC15+AD15+AF15 -> 0.019727391 | AG19: =AC15+AD15+AF15+AG15 -> 0.051283151 | AH19: =AD15+AF15+AG15+AH15 -> 0.075818269 | AI19: =AF15+AG15+AH15+AI15 -> 0.10873887 | AJ19: =AJ15 -> 0.113 | AK19: =AG15+AH15+AI15+AK15 -> 0.10530632 | AL19: =AH15+AI15+AK15+AL15 -> 0.083915347 | AM19: =AI15+AK15+AL15+AM15 -> 0.072812308 | AN19: =AK15+AL15+AM15+AN15 -> 0.050114997 | AO19: =AO15 -> 0.05096813 | AP19: =AL15+AM15+AN15+AP15 -> 0.031959766 | AQ19: =AM15+AN15+AP15+AQ15 -> 0.050562644 | AR19: =AN15+AP15+AQ15+AR15 -> 0.078710368 | AS19: =AP15+AQ15+AR15+AS15 -> 0.076289739 | AT19: =AT15 -> 0.0782 | AU19: =AQ15+AR15+AS15+AU15 -> 0.078532343 | AV19: =AR15+AS15+AU15+AV15 -> 0.061961428 | AW19: =AS15+AU15+AV15+AW15 -> 0.04329926 | AX19: =AU15+AV15+AW15+AX15 -> 0.0542 | AY19: =AY15 -> 0.055 | AZ19: =AV15+AW15+AX15+AZ15 -> 0.071262165 | BA19: =AW15+AX15+AZ15+BA15 -> 0.062262165 | BB19: =AX15+AZ15+BA15+BB15 -> 0.057062165 | BC19: =AZ15+BA15+BB15+BC15 -> 0.051462165 | BD19: =BD15 -> 0.0369 | BE19: =BA15+BB15+BC15+BE15 -> 0.046221661 | BF19: =BB15+BC15+BE15+BF15 -> 0.068875812 | BG19: =BC15+BE15+BF15+BG15 -> 0.074187466 | BH19: =BE15+BF15+BG15+BH15 -> 0.10164324 | BI19: =BI15 -> 0.107 | BJ19: =BF15+BG15+BH15+BJ15 -> 0.11108721 | BK19: =BG15+BH15+BJ15+BK15 -> 0.11699532 | BL19: =BH15+BJ15+BK15+BL15 -> 0.10288339 | BM19: =BJ15+BK15+BL15+BM15 -> 0.070141024 | BN19: =BN15 -> 0.071729083 | BO19: =BK15+BL15+BM15+BO15 -> 0.03917285 | BP19: =BL15+BM15+BO15+BP15 -> 0.0093080523 | BQ19: =BM15+BO15+BP15+BQ15 -> 0.0028057838 | BR19: =BO15+BP15+BQ15+BR15 -> -0.0052101709 | BS19: =BS15 -> -0.0052 | BT19: =BP15+BQ15+BR15+BT15 -> 0.014336973 | BU19: =BQ15+BR15+BT15+BU15 -> 0.033884117 | BV19: =BR15+BT15+BU15+BV15 -> 0.053431261 | BW19: =BT15+BU15+BV15+BW15 -> 0.072978404 | BX19: =BX15 -> 0.075 | BY19: =BU15+BV15+BW15+BY15 -> 0.072546915 | BZ19: =BV15+BW15+BY15+BZ15 -> 0.072115427 | CA19: =BW15+BY15+BZ15+CA15 -> 0.071683938 | CB19: =BY15+BZ15+CA15+CB15 -> 0.071252449 | CC19: =CC15 -> 0.073179 | CD19: =BZ15+CA15+CB15+CD15 -> 0.10685311 | CE19: =CA15+CB15+CD15+CE15 -> 0.14245378 | CF19: =CB15+CD15+CE15+CF15 -> 0.17805444 | CG19: =CD15+CE15+CF15+CG15 -> 0.21365511 | CH19: =CH15 -> 0.231391 | CI19: =CE15+CF15+CG15+CI15 -> 0.20200183 | CJ19: =CF15+CG15+CI15+CJ15 -> 0.19034856 | CK19: =CG15+CI15+CJ15+CK15 -> 0.17869528 | CL19: =CI15+CJ15+CK15+CL15 -> 0.16704201 | CM19: =CM15 -> 0.1778 | CN19: =CJ15+CK15+CL15+CN15 -> 0.13863658 | CO19: =CK15+CL15+CN15+CO15 -> 0.11023115 | CP19: =CL15+CN15+CO15+CP15 -> 0.081825722 | CQ19: =CN15+CO15+CP15+CQ15 -> 0.053420292 | CR19: =CR15 -> 0.0545 | CS19: =CO15+CP15+CQ15+CS15 -> 0.032018618 | CT19: =CP15+CQ15+CS15+CT15 -> 0.010616943 | CU19: =CQ15+CS15+CT15+CU15 -> -0.010784732 | CV19: =CS15+CT15+CU15+CV15 -> -0.032186407 | CW19: =CW15 -> -0.0318 | CX19: =CT15+CU15+CV15+CX15 -> -0.0081761472 | CY19: =CU15+CV15+CX15+CY15 -> 0.015834113 | CZ19: =CV15+CX15+CY15+CZ15 -> 0.039844372 | DA19: =CX15+CY15+CZ15+DA15 -> 0.063854632 | DB19: =DB15 -> 0.0654 | DC19: =CY15+CZ15+DA15+DC15 -> 0.045255574 | DD19: =CZ15+DA15+DC15+DD15 -> 0.026656517 | DE19: =DA15+DC15+DD15+DE15 -> 0.0080574589 | DF19: =DC15+DD15+DE15+DF15 -> -0.010541599 | DG19: =DG15 -> -0.0105 | DH19: =DD15+DE15+DF15+DH15 -> 0.0031587914 | DI19: =DE15+DF15+DH15+DI15 -> 0.016859182 | DJ19: =DF15+DH15+DI15+DJ15 -> 0.030559572 | DK19: =DH15+DI15+DJ15+DK15 -> 0.044259962 | DL19: =DL15 -> 0.045 | DM19: =DI15+DJ15+DK15+DM15 -> 0.044259962 | DN19: =DJ15+DK15+DM15+DN15 -> 0.044259962 | DO19: =DK15+DM15+DN15+DO15 -> 0.044259962 | DP19: =DM15+DN15+DO15+DP15 -> 0.044259962 | DQ19: =DQ15 -> 0.045 | DR19: =DN15+DO15+DP15+DR15 -> 0.044259962 | DS19: =DO15+DP15+DR15+DS15 -> 0.044259962 | DT19: =DP15+DR15+DS15+DT15 -> 0.044259962 | DU19: =DR15+DS15+DT15+DU15 -> 0.044259962 | DV19: =DV15 -> 0.045 | DW19: =DS15+DT15+DU15+DW15 -> 0.044259962 | DX19: =DT15+DU15+DW15+DX15 -> 0.044259962 | DY19: =DU15+DW15+DX15+DY15 -> 0.044259962 | DZ19: =DW15+DX15+DY15+DZ15 -> 0.044259962 | EA19: =EA15 -> 0.045 | EB19: =DX15+DY15+DZ15+EB15 -> 0.044259962 | EC19: =DY15+DZ15+EB15+EC15 -> 0.044259962 | ED19: =DZ15+EB15+EC15+ED15 -> 0.044259962 | EE19: =EB15+EC15+ED15+EE15 -> 0.044259962 | EF19: =EF15 -> 0.045

Sheet Income Statement
BH1: =BH14/BH5 -> -0.03132943 | BM1: =BM14/BM5 -> -0.028155458 | BR1: =BR14/BR5 -> -0.02431711 | BW1: =BW14/BW5 -> -0.014585466
A2: =DCF!$A$2 -> Cury - TP: R$48 | AI2: =AI16/AI11 -> 0.33979978 | AJ2: =AJ16/AJ11 -> 0.33979978 | AN2: =AN16/AN11 -> 0.30448685 | AO2: =AO16/AO11 -> 0.30448685 | AS2: =AS16/AS11 -> 0.39647812 | AT2: =AT16/AT11 -> 0.39647812 | AX2: =AX16/AX11 -> 0.34601825 | AY2: =AY16/AY11 -> 0.34601825 | BC2: =(BC5*(1-2.08%)+BC13+BC14)/(BC5*(1-2.08%)) -> 0.36837541 | BD2: =(BD5+BD9+BD13)/(BD5+BD9) -> 0.3844607 | BH2: =(BH5*(1-2.08%)+BH13+BH14)/(BH5*(1-2.08%)) -> 0.36049391 | BI2: =(BI5+BI9+BI13)/(BI5+BI9) -> 0.38988821 | BM2: =(BM5*(1-2.08%)+BM13+BM14)/(BM5*(1-2.08%)) -> 0.33464547 | BN2: =(BN5+BN9+BN13)/(BN5+BN9) -> 0.36168617 | BR2: =(BR5*(1-2.08%)+BR13+BR14)/(BR5*(1-2.08%)) -> 0.35324277 | BS2: =(BS5+BS9+BS13)/(BS5+BS9) -> 0.37600902 | BW2: =(BW5*(1-2.08%)+BW13+BW14)/(BW5*(1-2.08%)) -> 0.38265246 | BX2: =(BX5+BX9+BX13)/(BX5+BX9) -> 0.39516181 | CB2: =(CB11+CB13)/(CB11) -> 0.41366816 | CC2: =CC16/CC11 -> 0.34915435 | CD2: =CD16/CD11 -> 0.34374299 | CE2: =CE16/CE11 -> 0.35363763 | CF2: =CF16/CF11 -> 0.37851223 | CG2: =CG16/CG11 -> 0.40499044 | CH2: =CH16/CH11 -> 0.37424368 | CI2: =CI16/CI11 -> 0.35469191 | CJ2: =CJ16/CJ11 -> 0.36096309 | ... EF2: =EF16/EF11 -> 0.37216648
B3: =Macro!B$9 -> 1Q04 | C3: =Macro!C$9 -> 2Q04 | D3: =Macro!D$9 -> 3Q04 | E3: =Macro!E$9 -> 4Q04 | F3: =Macro!F$9 -> 2004 | G3: =Macro!G$9 -> 1Q05 | H3: =Macro!H$9 -> 2Q05 | I3: =Macro!I$9 -> 3Q05 | ... EF3: =Macro!EF$9 -> 2030E
A4: Gross Revenues | B4: =B5+B7 -> 0 | C4: =C5+C7 -> 0 | D4: =D5+D7 -> 0 | E4: =E5+E7 -> 0 | F4: =SUM(B4:E4) -> 0 | G4: =G5+G7 -> 0 | H4: =H5+H7 -> 0 | I4: =I5+I7 -> 0 | J4: =J5+J7 -> 0 | K4: =SUM(G4:J4) -> 0 | L4: =L5+L7 -> 0 | M4: =M5+M7 -> 0 | N4: =N5+N7 -> 0 | O4: =O5+O7 -> 0 | P4: =SUM(L4:O4) -> 0 | Q4: =Q5+Q7 -> 0 | R4: =R5+R7 -> 0 | S4: =S5+S7 -> 0 | T4: =T5+T7 -> 0 | U4: =SUM(Q4:T4) -> 0 | V4: =V5+V7 -> 0 | W4: =W5+W7 -> 0 | X4: =X5+X7 -> 0 | Y4: =Y5+Y7 -> 0 | Z4: =SUM(V4:Y4) -> 0 | AA4: =AA5+AA7 -> 0 | AB4: =AB5+AB7 -> 0 | AC4: =AC5+AC7 -> 0 | AD4: =AD5+AD7 -> 0 | AE4: =SUM(AA4:AD4) -> 0 | AF4: =AF5+AF6+AF7 -> 0 | AG4: =AG5+AG6+AG7 -> 0 | AH4: =AH5+AH6+AH7 -> 0 | AI4: =AI5+AI6+AI7 -> 244646.21 | AJ4: =SUM(AF4:AI4) -> 244646.21 | AK4: =AK5+AK6+AK7 -> 0 | AL4: =AL5+AL6+AL7 -> 0 | AM4: =AM5+AM6+AM7 -> 0 | AN4: =AN5+AN6+AN7 -> 433385.81 | AO4: =SUM(AK4:AN4) -> 433385.81 | AP4: =AP5+AP6+AP7 -> 0 | AQ4: =AQ5+AQ6+AQ7 -> 0 | AR4: =AR5+AR6+AR7 -> 0 | AS4: =AS5+AS6+AS7 -> 494249.75 | AT4: =SUM(AP4:AS4) -> 494249.75 | AU4: =AU5+AU6+AU7 -> 0 | AV4: =AV5+AV6+AV7 -> 0 | AW4: =AW5+AW6+AW7 -> 0 | AX4: =AX5+AX6+AX7 -> 753085.35 | AY4: =SUM(AU4:AX4) -> 753085.35 | AZ4: =AZ5+AZ6+AZ7 -> 0 | BA4: =BA5+BA6+BA7 -> 0 | BB4: =BB5+BB6+BB7 -> 0 | BC4: =BC5+BC6+BC7 -> 912966 | BD4: =SUM(AZ4:BC4) -> 912966 | BE4: =BE5+BE6+BE7 -> 0 | BF4: =BF5+BF6+BF7 -> 0 | BG4: =BG5+BG6+BG7 -> 0 | BH4: =BH5+BH6+BH7 -> 871724 | BI4: =SUM(BE4:BH4) -> 871724 | BJ4: =BJ5+BJ6+BJ7 -> 0 | BK4: =BK5+BK6+BK7 -> 0 | BL4: =BL5+BL6+BL7 -> 0 | BM4: =BM5+BM6+BM7 -> 821810 | BN4: =SUM(BJ4:BM4) -> 821810 | BO4: =BO5+BO6+BO7 -> 0 | BP4: =BP5+BP6+BP7 -> 0 | BQ4: =BQ5+BQ6+BQ7 -> 0 | BR4: =BR5+BR6+BR7 -> 831922 | BS4: =SUM(BO4:BR4) -> 831922 | BT4: =BT5+BT6+BT7 -> 0 | BU4: =BU5+BU6+BU7 -> 0 | BV4: =BV5+BV6+BV7 -> 0 | BW4: =BW5+BW6+BW7 -> 942945 | BX4: =SUM(BT4:BW4) -> 942945 | BY4: =BY5+BY6+BY7 -> 193287 | BZ4: =BZ5+BZ6+BZ7 -> 273610 | CA4: =CA5+CA6+CA7 -> 268175 | CB4: =CB5+CB6+CB7 -> 308715 | CC4: =SUM(BY4:CB4) -> 1043787 | CD4: =CD5+CD6+CD7 -> 233098 | CE4: =CE5+CE6+CE7 -> 252454 | CF4: =CF5+CF6+CF7 -> 334505 | CG4: =CG5+CG6+CG7 -> 353014 | CH4: =SUM(CD4:CG4) -> 1173071 | CI4: =CI5+CI6+CI7 -> 346976 | CJ4: =CJ5+CJ6+CJ7 -> 462074 | CK4: =CK5+CK6+CK7 -> 466696 | CL4: =CL5+CL6+CL7 -> 502424 | CM4: =SUM(CI4:CL4) -> 1778170 | CN4: =CN5+CN6+CN7 -> 458170 | CO4: =CO5+CO6+CO7 -> 616407 | CP4: =CP5+CP6+CP7 -> 640437 | CQ4: =CQ5+CQ6+CQ7 -> 593421 | CR4: =SUM(CN4:CQ4) -> 2308435 | CS4: =CS5+CS6+CS7 -> 607423 | CT4: =CT5+CT6+CT7 -> 743352 | CU4: =CU5+CU6+CU7 -> 768155 | CV4: =CV5+CV6+CV7 -> 829075 | CW4: =SUM(CS4:CV4) -> 2948005 | CX4: =CX5+CX6+CX7 -> 854925 | CY4: =CY5+CY6+CY7 -> 1017876 | CZ4: =CZ5+CZ6+CZ7 -> 1078346 | DA4: =DA5+DA6+DA7 -> 1056476 | DB4: =SUM(CX4:DA4) -> 4007623 | DC4: =DC5+DC6+DC7 -> 1244407 | DD4: =DD5+DD6+DD7 -> 1375487 | DE4: =DE5+DE6+DE7 -> 1449421 | DF4: =DF5+DF6+DF7 -> 1453820 | DG4: =SUM(DC4:DF4) -> 5523135 | DH4: =DH5+DH6+DH7 -> 1644474 | DI4: =DI5+DI6+DI7 -> 1725754 | DJ4: =DJ5+DJ6+DJ7 -> 1717525.6 | DK4: =DK5+DK6+DK7 -> 1859826.6 | DL4: =SUM(DH4:DK4) -> 6947580.2 | DM4: =DM5+DM6+DM7 -> 1899921.8 | DN4: =DN5+DN6+DN7 -> 1962486 | DO4: =DO5+DO6+DO7 -> 2015562.5 | DP4: =DP5+DP6+DP7 -> 2064555.3 | DQ4: =SUM(DM4:DP4) -> 7942525.6 | DR4: =DR5+DR6+DR7 -> 2110530.9 | DS4: =DS5+DS6+DS7 -> 2154229.7 | DT4: =DT5+DT6+DT7 -> 2196132.6 | DU4: =DU5+DU6+DU7 -> 2236572.1 | DV4: =SUM(DR4:DU4) -> 8697465.4 | DW4: =DW5+DW6+DW7 -> 2275792.6 | DX4: =DX5+DX6+DX7 -> 2313983.1 | DY4: =DY5+DY6+DY7 -> 2351297.5 | DZ4: =DZ5+DZ6+DZ7 -> 2387865.2 | EA4: =SUM(DW4:DZ4) -> 9328938.3 | EB4: =EB5+EB6+EB7 -> 2423798.2 | EC4: =EC5+EC6+EC7 -> 2459194.6 | ED4: =ED5+ED6+ED7 -> 2494142.1 | EE4: =EE5+EE6+EE7 -> 2528718.8 | EF4: =SUM(EB4:EE4) -> 9905853.6
A5: Development Sales | F5: =SUM(B5:E5) -> 0 | K5: =SUM(G5:J5) -> 0 | P5: =SUM(L5:O5) -> 0 | U5: =SUM(Q5:T5) -> 0 | Z5: =SUM(V5:Y5) -> 0 | AE5: =SUM(AA5:AD5) -> 0 | AI5: =AI11/(1-AI10) -> 244646.21 | AJ5: =SUM(AF5:AI5) -> 244646.21 | AN5: =AN11/(1-AN10) -> 433385.81 | AO5: =SUM(AK5:AN5) -> 433385.81 | AS5: =AS11/(1-AS10) -> 494249.75 | AT5: =SUM(AP5:AS5) -> 494249.75 | AX5: =AX11/(1-AX10) -> 753085.35 | AY5: =SUM(AU5:AX5) -> 753085.35 | BC5: =472254-3130 -> 469124 | BD5: =SUM(AZ5:BC5) -> 469124 | BH5: =458609-5776 -> 452833 | BI5: =SUM(BE5:BH5) -> 452833 | BM5: =565504-8596 -> 556908 | BN5: =SUM(BJ5:BM5) -> 556908 | BR5: =738498-9135 -> 729363 | BS5: =SUM(BO5:BR5) -> 729363 | BW5: =930049-9955 -> 920094 | BX5: =SUM(BT5:BW5) -> 920094 | BY5: =193732-2076 -> 191656 | BZ5: =248291-3205 -> 245086 | CA5: =268629-1695 -> 266934 | CB5: =1063367-24443-8342+100-SUM(BY5:CA5) -> 327006 | CC5: =SUM(BY5:CB5) -> 1030682 | CD5: =234242-1985 -> 232257 | CE5: =263860-11578-507 -> 251775 | CF5: =830029-8974-3617-SUM(CD5:CE5) -> 333406 | CG5: =1183813-16767-4243-SUM(CD5:CF5) -> 345365 | CH5: =SUM(CD5:CG5) -> 1162803 | CI5: =348556-1130-1564 -> 345862 | CJ5: =467360-4492-2158 -> 460710 | CK5: =1290410-12155-6059-SUM(CI5:CJ5) -> 465624 | CL5: =1795292-13083-8289-SUM(CI5:CK5) -> 501724 | CM5: =SUM(CI5:CL5) -> 1773920 | CN5: =459417-740-1572 -> 457105 | CO5: =619527-4298-578 -> 614651 | CP5: =1720898-8316-1765-SUM(CN5:CO5) -> 639061 | CQ5: =2318165-11358-3745-SUM(CN5:CP5) -> 592245 | CR5: =SUM(CN5:CQ5) -> 2303062 | CS5: =608998-1086-2065 -> 605847 | CT5: =743265-382-704 -> 742179 | CU5: =767232-2543+1829 -> 766518 | CV5: =2950126-1185-6289-SUM(CS5:CU5) -> 828108 | CW5: =SUM(CS5:CV5) -> 2942652 | CX5: =851906-1722+2980 -> 853164 | CY5: =1016524+2082-1667 -> 1016939 | CZ5: =1084539-6033-160 -> 1078346 | DA5: =4016820+2114-14025-SUM(CX5:CZ5) -> 1056460 | DB5: =SUM(CX5:DA5) -> 4004909 | DC5: =1246115-6033-2089 -> 1237993 | DD5: =1393733-4822-13805 -> 1375106 | DE5: =1461895-11780-3018 -> 1447097 | DF5: =5567252-11984-42968-SUM(DC5:DE5) -> 1452104 | DG5: =SUM(DC5:DF5) -> 5512300 | DH5: =1660432-17750+353 -> 1643035 | DI5: =1742831-3187-14445 -> 1725199 | DJ5: =Forecasts!DJ36 -> 1714097.4 | DK5: =Forecasts!DK36 -> 1856114.4 | DL5: =SUM(DH5:DK5) -> 6938445.8 | DM5: =Forecasts!DM36 -> 1896129.5 | DN5: =Forecasts!DN36 -> 1958568.9 | DO5: =Forecasts!DO36 -> 2011539.4 | DP5: =Forecasts!DP36 -> 2060434.4 | DQ5: =SUM(DM5:DP5) -> 7926672.2 | DR5: =Forecasts!DR36 -> 2106318.3 | DS5: =Forecasts!DS36 -> 2149929.9 | DT5: =Forecasts!DT36 -> 2191749.1 | DU5: =Forecasts!DU36 -> 2232107.9 | DV5: =SUM(DR5:DU5) -> 8680105.1 | DW5: =Forecasts!DW36 -> 2271250.1 | DX5: =Forecasts!DX36 -> 2309364.4 | DY5: =Forecasts!DY36 -> 2346604.3 | DZ5: =Forecasts!DZ36 -> 2383099 | EA5: =SUM(DW5:DZ5) -> 9310317.7 | EB5: =Forecasts!EB36 -> 2418960.3 | EC5: =Forecasts!EC36 -> 2454286.1 | ED5: =Forecasts!ED36 -> 2489163.7 | EE5: =Forecasts!EE36 -> 2523671.4 | EF5: =SUM(EB5:EE5) -> 9886081.5
A6: INCC | F6: =SUM(B6:E6) -> 0 | K6: =SUM(G6:J6) -> 0 | P6: =SUM(L6:O6) -> 0 | U6: =SUM(Q6:T6) -> 0 | Z6: =SUM(V6:Y6) -> 0 | AE6: =SUM(AA6:AD6) -> 0 | AJ6: =SUM(AF6:AI6) -> 0 | AO6: =SUM(AK6:AN6) -> 0 | AT6: =SUM(AP6:AS6) -> 0 | AY6: =SUM(AU6:AX6) -> 0 | BD6: =SUM(AZ6:BC6) -> 0 | BI6: =SUM(BE6:BH6) -> 0 | BN6: =SUM(BJ6:BM6) -> 0 | BS6: =SUM(BO6:BR6) -> 0 | BX6: =SUM(BT6:BW6) -> 0 | CC6: =SUM(BY6:CB6) -> 0 | CH6: =SUM(CD6:CG6) -> 0 | CM6: =SUM(CI6:CL6) -> 0 | CR6: =SUM(CN6:CQ6) -> 0 | CW6: =SUM(CS6:CV6) -> 0 | DB6: =SUM(CX6:DA6) -> 0 | DG6: =SUM(DC6:DF6) -> 0 | DJ6: =AVERAGE(DE6/Macro!DE18,DF6/Macro!DF18,DH6/Macro!DH18,DI6/Macro!DI18)*'Balance Sheet'!DJ9/'Balance Sheet'!DE9*Macro!DJ18*0.95 -> 0 | DK6: =AVERAGE(DF6/Macro!DF18,DH6/Macro!DH18,DI6/Macro!DI18,DJ6/Macro!DJ18)*'Balance Sheet'!DK9/'Balance Sheet'!DF9*Macro!DK18*0.95 -> 0 | DL6: =SUM(DH6:DK6) -> 0 | DM6: =AVERAGE(DH6/Macro!DH18,DI6/Macro!DI18,DJ6/Macro!DJ18,DK6/Macro!DK18)*'Balance Sheet'!DM9/'Balance Sheet'!DH9*Macro!DM18*0.95 -> 0 | DN6: =AVERAGE(DI6/Macro!DI18,DJ6/Macro!DJ18,DK6/Macro!DK18,DM6/Macro!DM18)*'Balance Sheet'!DN9/'Balance Sheet'!DI9*Macro!DN18*0.95 -> 0 | DO6: =AVERAGE(DJ6/Macro!DJ18,DK6/Macro!DK18,DM6/Macro!DM18,DN6/Macro!DN18)*'Balance Sheet'!DO9/'Balance Sheet'!DJ9*Macro!DO18*0.95 -> 0 | DP6: =AVERAGE(DK6/Macro!DK18,DM6/Macro!DM18,DN6/Macro!DN18,DO6/Macro!DO18)*'Balance Sheet'!DP9/'Balance Sheet'!DK9*Macro!DP18*0.95 -> 0 | DQ6: =SUM(DM6:DP6) -> 0 | DR6: =AVERAGE(DM6/Macro!DM18,DN6/Macro!DN18,DO6/Macro!DO18,DP6/Macro!DP18)*'Balance Sheet'!DR9/'Balance Sheet'!DM9*Macro!DR18*0.95 -> 0 | DS6: =AVERAGE(DN6/Macro!DN18,DO6/Macro!DO18,DP6/Macro!DP18,DR6/Macro!DR18)*'Balance Sheet'!DS9/'Balance Sheet'!DN9*Macro!DS18*0.95 -> 0 | DT6: =AVERAGE(DO6/Macro!DO18,DP6/Macro!DP18,DR6/Macro!DR18,DS6/Macro!DS18)*'Balance Sheet'!DT9/'Balance Sheet'!DO9*Macro!DT18*0.95 -> 0 | DU6: =AVERAGE(DP6/Macro!DP18,DR6/Macro!DR18,DS6/Macro!DS18,DT6/Macro!DT18)*'Balance Sheet'!DU9/'Balance Sheet'!DP9*Macro!DU18*0.95 -> 0 | DV6: =SUM(DR6:DU6) -> 0 | DW6: =AVERAGE(DR6/Macro!DR18,DS6/Macro!DS18,DT6/Macro!DT18,DU6/Macro!DU18)*'Balance Sheet'!DW9/'Balance Sheet'!DR9*Macro!DW18*0.95 -> 0 | DX6: =AVERAGE(DS6/Macro!DS18,DT6/Macro!DT18,DU6/Macro!DU18,DW6/Macro!DW18)*'Balance Sheet'!DX9/'Balance Sheet'!DS9*Macro!DX18*0.95 -> 0 | DY6: =AVERAGE(DT6/Macro!DT18,DU6/Macro!DU18,DW6/Macro!DW18,DX6/Macro!DX18)*'Balance Sheet'!DY9/'Balance Sheet'!DT9*Macro!DY18*0.95 -> 0 | DZ6: =AVERAGE(DU6/Macro!DU18,DW6/Macro!DW18,DX6/Macro!DX18,DY6/Macro!DY18)*'Balance Sheet'!DZ9/'Balance Sheet'!DU9*Macro!DZ18*0.95 -> 0 | EA6: =SUM(DW6:DZ6) -> 0 | EB6: =AVERAGE(DW6/Macro!DW18,DX6/Macro!DX18,DY6/Macro!DY18,DZ6/Macro!DZ18)*'Balance Sheet'!EB9/'Balance Sheet'!DW9*Macro!EB18*0.95 -> 0 | EC6: =AVERAGE(DX6/Macro!DX18,DY6/Macro!DY18,DZ6/Macro!DZ18,EB6/Macro!EB18)*'Balance Sheet'!EC9/'Balance Sheet'!DX9*Macro!EC18*0.95 -> 0 | ED6: =AVERAGE(DY6/Macro!DY18,DZ6/Macro!DZ18,EB6/Macro!EB18,EC6/Macro!EC18)*'Balance Sheet'!ED9/'Balance Sheet'!DY9*Macro!ED18*0.95 -> 0 | EE6: =AVERAGE(DZ6/Macro!DZ18,EB6/Macro!EB18,EC6/Macro!EC18,ED6/Macro!ED18)*'Balance Sheet'!EE9/'Balance Sheet'!DZ9*Macro!EE18*0.95 -> 0 | EF6: =SUM(EB6:EE6) -> 0
A7: Services | F7: =SUM(B7:E7) -> 0 | K7: =SUM(G7:J7) -> 0 | P7: =SUM(L7:O7) -> 0 | U7: =SUM(Q7:T7) -> 0 | Z7: =SUM(V7:Y7) -> 0 | AE7: =SUM(AA7:AD7) -> 0 | AJ7: =SUM(AF7:AI7) -> 0 | AO7: =SUM(AK7:AN7) -> 0 | AT7: =SUM(AP7:AS7) -> 0 | AY7: =SUM(AU7:AX7) -> 0 | BC7: 443842 | BD7: =SUM(AZ7:BC7) -> 443842 | BH7: 418891 | BI7: =SUM(BE7:BH7) -> 418891 | BM7: 264902 | BN7: =SUM(BJ7:BM7) -> 264902 | BR7: =102559 -> 102559 | BS7: =SUM(BO7:BR7) -> 102559 | BW7: =22851 -> 22851 | BX7: =SUM(BT7:BW7) -> 22851 | BY7: 1631 | BZ7: 28524 | CA7: 1241 | CB7: =13105-SUM(BY7:CA7) -> -18291 | CC7: =SUM(BY7:CB7) -> 13105 | CD7: 841 | CE7: 679 | CF7: =2619-SUM(CD7:CE7) -> 1099 | CG7: =10268-SUM(CD7:CF7) -> 7649 | CH7: =SUM(CD7:CG7) -> 10268 | CI7: 1114 | CJ7: 1364 | CK7: =3550-SUM(CI7:CJ7) -> 1072 | CL7: =4250-SUM(CI7:CK7) -> 700 | CM7: =SUM(CI7:CL7) -> 4250 | CN7: 1065 | CO7: 1756 | CP7: =4197-SUM(CN7:CO7) -> 1376 | CQ7: =5373-SUM(CN7:CP7) -> 1176 | CR7: =SUM(CN7:CQ7) -> 5373 | CS7: 1576 | CT7: 1173 | CU7: 1637 | CV7: =5353-SUM(CS7:CU7) -> 967 | CW7: =SUM(CS7:CV7) -> 5353 | CX7: 1761 | CY7: 937 | CZ7: 0 | DA7: =2714-SUM(CX7:CZ7) -> 16 | DB7: =SUM(CX7:DA7) -> 2714 | DC7: 6414 | DD7: 381 | DE7: 2324 | DF7: =10835-SUM(DC7:DE7) -> 1716 | DG7: =SUM(DC7:DF7) -> 10835 | DH7: 1439 | DI7: 555 | DJ7: =Forecasts!DJ42 -> 3428.1948 | DK7: =Forecasts!DK42 -> 3712.2288 | DL7: =SUM(DH7:DK7) -> 9134.4236 | DM7: =Forecasts!DM42 -> 3792.259 | DN7: =Forecasts!DN42 -> 3917.1378 | DO7: =Forecasts!DO42 -> 4023.0789 | DP7: =Forecasts!DP42 -> 4120.8688 | DQ7: =SUM(DM7:DP7) -> 15853.344 | DR7: =Forecasts!DR42 -> 4212.6366 | DS7: =Forecasts!DS42 -> 4299.8597 | DT7: =Forecasts!DT42 -> 4383.4981 | DU7: =Forecasts!DU42 -> 4464.2159 | DV7: =SUM(DR7:DU7) -> 17360.21 | DW7: =Forecasts!DW42 -> 4542.5001 | DX7: =Forecasts!DX42 -> 4618.7287 | DY7: =Forecasts!DY42 -> 4693.2085 | DZ7: =Forecasts!DZ42 -> 4766.1981 | EA7: =SUM(DW7:DZ7) -> 18620.635 | EB7: =Forecasts!EB42 -> 4837.9205 | EC7: =Forecasts!EC42 -> 4908.5721 | ED7: =Forecasts!ED42 -> 4978.3275 | EE7: =Forecasts!EE42 -> 5047.3428 | EF7: =SUM(EB7:EE7) -> 19772.163
A8: Deductions | B8: =B9 -> 0 | C8: =C9 -> 0 | D8: =D9 -> 0 | E8: =E9 -> 0 | F8: =SUM(B8:E8) -> 0 | G8: =G9 -> 0 | H8: =H9 -> 0 | I8: =I9 -> 0 | J8: =J9 -> 0 | K8: =SUM(G8:J8) -> 0 | L8: =L9 -> 0 | M8: =M9 -> 0 | N8: =N9 -> 0 | O8: =O9 -> 0 | P8: =SUM(L8:O8) -> 0 | Q8: =Q9 -> 0 | R8: =R9 -> 0 | S8: =S9 -> 0 | T8: =T9 -> 0 | U8: =SUM(Q8:T8) -> 0 | V8: =V9 -> 0 | W8: =W9 -> 0 | X8: =X9 -> 0 | Y8: =Y9 -> 0 | Z8: =SUM(V8:Y8) -> 0 | AA8: =AA9 -> 0 | AB8: =AB9 -> 0 | AC8: =AC9 -> 0 | AD8: =AD9 -> 0 | AE8: =SUM(AA8:AD8) -> 0 | AF8: =AF9 -> 0 | AG8: =AG9 -> 0 | AH8: =AH9 -> 0 | AI8: =AI9 -> -5088.6411 | AJ8: =SUM(AF8:AI8) -> -5088.6411 | AK8: =AK9 -> 0 | AL8: =AL9 -> 0 | AM8: =AM9 -> 0 | AN8: =AN9 -> -9014.4249 | AO8: =SUM(AK8:AN8) -> -9014.4249 | AP8: =AP9 -> 0 | AQ8: =AQ9 -> 0 | AR8: =AR9 -> 0 | AS8: =AS9 -> -10280.395 | AT8: =SUM(AP8:AS8) -> -10280.395 | AU8: =AU9 -> 0 | AV8: =AV9 -> 0 | AW8: =AW9 -> 0 | AX8: =AX9 -> -15664.175 | AY8: =SUM(AU8:AX8) -> -15664.175 | AZ8: =AZ9 -> 0 | BA8: =BA9 -> 0 | BB8: =BB9 -> 0 | BC8: =BC9 -> -13595 | BD8: =SUM(AZ8:BC8) -> -13595 | BE8: =BE9 -> 0 | BF8: =BF9 -> 0 | BG8: =BG9 -> 0 | BH8: =BH9 -> -11309 | BI8: =SUM(BE8:BH8) -> -11309 | BJ8: =BJ9 -> 0 | BK8: =BK9 -> 0 | BL8: =BL9 -> 0 | BM8: =BM9 -> -13047 | BN8: =SUM(BJ8:BM8) -> -13047 | BO8: =BO9 -> 0 | BP8: =BP9 -> 0 | BQ8: =BQ9 -> 0 | BR8: =BR9 -> -17537 | BS8: =SUM(BO8:BR8) -> -17537 | BT8: =BT9 -> 0 | BU8: =BU9 -> 0 | BV8: =BV9 -> 0 | BW8: =BW9 -> -22692 | BX8: =SUM(BT8:BW8) -> -22692 | BY8: =BY9 -> -4917 | BZ8: =BZ9 -> -5877 | CA8: =CA9 -> -6651 | CB8: =CB9 -> -7065 | CC8: =SUM(BY8:CB8) -> -24510 | CD8: =CD9 -> -5777 | CE8: =CE9 -> -6250 | CF8: =CF9 -> -8608 | CG8: =CG9 -> -7754 | CH8: =SUM(CD8:CG8) -> -28389 | CI8: =CI9 -> -7690 | CJ8: =CJ9 -> -10737 | CK8: =CK9 -> -10247 | CL8: =CL9 -> -11201 | CM8: =SUM(CI8:CL8) -> -39875 | CN8: =CN9 -> -10796 | CO8: =CO9 -> -13624 | CP8: =CP9 -> -13778 | CQ8: =CQ9 -> -12943 | CR8: =SUM(CN8:CQ8) -> -51141 | CS8: =CS9 -> -12467 | CT8: =CT9 -> -15606 | CU8: =CU9 -> -16281 | CV8: =CV9 -> -17479 | CW8: =SUM(CS8:CV8) -> -61833 | CX8: =CX9 -> -17543 | CY8: =CY9 -> -19791 | CZ8: =CZ9 -> -22474 | DA8: =DA9 -> -21505 | DB8: =SUM(CX8:DA8) -> -81313 | DC8: =DC9 -> -28223 | DD8: =DD9 -> -28888 | DE8: =DE9 -> -32495 | DF8: =DF9 -> -34105 | DG8: =SUM(DC8:DF8) -> -123711 | DH8: =DH9 -> -31903 | DI8: =DI9 -> -35160 | DJ8: =DJ9 -> -35724.533 | DK8: =DK9 -> -38684.394 | DL8: =SUM(DH8:DK8) -> -141471.93 | DM8: =DM9 -> -39518.372 | DN8: =DN9 -> -40819.71 | DO8: =DO9 -> -41923.7 | DP8: =DP9 -> -42942.749 | DQ8: =SUM(DM8:DP8) -> -165204.53 | DR8: =DR9 -> -43899.044 | DS8: =DS9 -> -44807.978 | DT8: =DT9 -> -45679.557 | DU8: =DU9 -> -46520.701 | DV8: =SUM(DR8:DU8) -> -180907.28 | DW8: =DW9 -> -47336.485 | DX8: =DX9 -> -48130.848 | DY8: =DY9 -> -48906.987 | DZ8: =DZ9 -> -49667.597 | EA8: =SUM(DW8:DZ8) -> -194041.92 | EB8: =EB9 -> -50415.002 | EC8: =EC9 -> -51151.249 | ED8: =ED9 -> -51878.155 | EE8: =EE9 -> -52597.35 | EF8: =SUM(EB8:EE8) -> -206041.76
A9: Taxes and other deductions | F9: =SUM(B9:E9) -> 0 | K9: =SUM(G9:J9) -> 0 | P9: =SUM(L9:O9) -> 0 | U9: =SUM(Q9:T9) -> 0 | Z9: =SUM(V9:Y9) -> 0 | AE9: =SUM(AA9:AD9) -> 0 | AI9: =-AI10*AI5 -> -5088.6411 | AJ9: =SUM(AF9:AI9) -> -5088.6411 | AN9: =-AN10*AN5 -> -9014.4249 | AO9: =SUM(AK9:AN9) -> -9014.4249 | AS9: =-AS10*AS5 -> -10280.395 | AT9: =SUM(AP9:AS9) -> -10280.395 | AX9: =-AX10*AX5 -> -15664.175 | AY9: =SUM(AU9:AX9) -> -15664.175 | BC9: -13595 | BD9: =SUM(AZ9:BC9) -> -13595 | BH9: -11309 | BI9: =SUM(BE9:BH9) -> -11309 | BM9: -13047 | BN9: =SUM(BJ9:BM9) -> -13047 | BR9: =-17537 -> -17537 | BS9: =SUM(BO9:BR9) -> -17537 | BW9: =-22692 -> -22692 | BX9: =SUM(BT9:BW9) -> -22692 | BY9: -4917 | BZ9: -5877 | CA9: -6651 | CB9: =-24510-SUM(BY9:CA9) -> -7065 | CC9: =SUM(BY9:CB9) -> -24510 | CD9: -5777 | CE9: -6250 | CF9: =-20635-SUM(CD9:CE9) -> -8608 | CG9: =-28389-SUM(CD9:CF9) -> -7754 | CH9: =SUM(CD9:CG9) -> -28389 | CI9: -7690 | CJ9: -10737 | CK9: =-28674-SUM(CI9:CJ9) -> -10247 | CL9: =-39875-SUM(CI9:CK9) -> -11201 | CM9: =SUM(CI9:CL9) -> -39875 | CN9: -10796 | CO9: -13624 | CP9: =-38198-SUM(CN9:CO9) -> -13778 | CQ9: =-51141-SUM(CN9:CP9) -> -12943 | CR9: =SUM(CN9:CQ9) -> -51141 | CS9: -12467 | CT9: -15606 | CU9: -16281 | CV9: =-61833-SUM(CS9:CU9) -> -17479 | CW9: =SUM(CS9:CV9) -> -61833 | CX9: -17543 | CY9: -19791 | CZ9: -22474 | DA9: =-81313-SUM(CX9:CZ9) -> -21505 | DB9: =SUM(CX9:DA9) -> -81313 | DC9: -28223 | DD9: -28888 | DE9: -32495 | DF9: =-123711-SUM(DC9:DE9) -> -34105 | DG9: =SUM(DC9:DF9) -> -123711 | DH9: -31903 | DI9: -35160 | DJ9: =-DJ10*DJ$4 -> -35724.533 | DK9: =-DK10*DK$4 -> -38684.394 | DL9: =SUM(DH9:DK9) -> -141471.93 | DM9: =-DM10*DM$4 -> -39518.372 | DN9: =-DN10*DN$4 -> -40819.71 | DO9: =-DO10*DO$4 -> -41923.7 | DP9: =-DP10*DP$4 -> -42942.749 | DQ9: =SUM(DM9:DP9) -> -165204.53 | DR9: =-DR10*DR$4 -> -43899.044 | DS9: =-DS10*DS$4 -> -44807.978 | DT9: =-DT10*DT$4 -> -45679.557 | DU9: =-DU10*DU$4 -> -46520.701 | DV9: =SUM(DR9:DU9) -> -180907.28 | DW9: =-DW10*DW$4 -> -47336.485 | DX9: =-DX10*DX$4 -> -48130.848 | DY9: =-DY10*DY$4 -> -48906.987 | DZ9: =-DZ10*DZ$4 -> -49667.597 | EA9: =SUM(DW9:DZ9) -> -194041.92 | EB9: =-EB10*EB$4 -> -50415.002 | EC9: =-EC10*EC$4 -> -51151.249 | ED9: =-ED10*ED$4 -> -51878.155 | EE9: =-EE10*EE$4 -> -52597.35 | EF9: =SUM(EB9:EE9) -> -206041.76
A10: % of Gross revenues | B10: =-B9/B$4 -> #DIV/0! | C10: =-C9/C$4 -> #DIV/0! | D10: =-D9/D$4 -> #DIV/0! | E10: =-E9/E$4 -> #DIV/0! | F10: =-F9/F$4 -> #DIV/0! | G10: =-G9/G$4 -> #DIV/0! | H10: =-H9/H$4 -> #DIV/0! | I10: =-I9/I$4 -> #DIV/0! | ... AH10: =-AH9/AH$4 -> #DIV/0! | AI10: 0.0208 | AJ10: =-AJ9/AJ$4 -> 0.0208 | AK10: =-AK9/AK$4 -> #DIV/0! | AL10: =-AL9/AL$4 -> #DIV/0! | AM10: =-AM9/AM$4 -> #DIV/0! | AN10: 0.0208 | AO10: =-AO9/AO$4 -> 0.0208 | AP10: =-AP9/AP$4 -> #DIV/0! | AQ10: =-AQ9/AQ$4 -> #DIV/0! | AR10: =-AR9/AR$4 -> #DIV/0! | AS10: 0.0208 | AT10: =-AT9/AT$4 -> 0.0208 | AU10: =-AU9/AU$4 -> #DIV/0! | AV10: =-AV9/AV$4 -> #DIV/0! | AW10: =-AW9/AW$4 -> #DIV/0! | AX10: 0.0208 | AY10: =-AY9/AY$4 -> 0.0208 | AZ10: =-AZ9/AZ$4 -> #DIV/0! | BA10: =-BA9/BA$4 -> #DIV/0! | BB10: =-BB9/BB$4 -> #DIV/0! | BC10: =-BC9/BC$4 -> 0.014891026 | BD10: =-BD9/BD$4 -> 0.014891026 | BE10: =-BE9/BE$4 -> #DIV/0! | BF10: =-BF9/BF$4 -> #DIV/0! | ... DI10: =-DI9/DI$4 -> 0.020373703 | DJ10: =0.37%+1.71% -> 0.0208 | DK10: =0.37%+1.71% -> 0.0208 | DL10: =-DL9/DL$4 -> 0.020362763 | DM10: =0.37%+1.71% -> 0.0208 | DN10: =0.37%+1.71% -> 0.0208 | DO10: =0.37%+1.71% -> 0.0208 | DP10: =0.37%+1.71% -> 0.0208 | DQ10: =-DQ9/DQ$4 -> 0.0208 | DR10: =0.37%+1.71% -> 0.0208 | DS10: =DR10 -> 0.0208 | DT10: =DS10 -> 0.0208 | DU10: =DT10 -> 0.0208 | DV10: =-DV9/DV$4 -> 0.0208 | DW10: =DU10 -> 0.0208 | DX10: =DW10 -> 0.0208 | DY10: =DX10 -> 0.0208 | DZ10: =DY10 -> 0.0208 | EA10: =-EA9/EA$4 -> 0.0208 | EB10: =DZ10 -> 0.0208 | EC10: =EB10 -> 0.0208 | ED10: =EC10 -> 0.0208 | EE10: =ED10 -> 0.0208 | EF10: =-EF9/EF$4 -> 0.0208
A11: Net Revenues | B11: =B4+B8 -> 0 | C11: =C4+C8 -> 0 | D11: =D4+D8 -> 0 | E11: =E4+E8 -> 0 | F11: =SUM(B11:E11) -> 0 | G11: =G4+G8 -> 0 | H11: =H4+H8 -> 0 | I11: =I4+I8 -> 0 | J11: =J4+J8 -> 0 | K11: =SUM(G11:J11) -> 0 | L11: =L4+L8 -> 0 | M11: =M4+M8 -> 0 | N11: =N4+N8 -> 0 | O11: =O4+O8 -> 0 | P11: =SUM(L11:O11) -> 0 | Q11: =Q4+Q8 -> 0 | R11: =R4+R8 -> 0 | S11: =S4+S8 -> 0 | T11: =T4+T8 -> 0 | U11: =SUM(Q11:T11) -> 0 | V11: =V4+V8 -> 0 | W11: =W4+W8 -> 0 | X11: =X4+X8 -> 0 | Y11: =Y4+Y8 -> 0 | Z11: =SUM(V11:Y11) -> 0 | AA11: =AA4+AA8 -> 0 | AB11: =AB4+AB8 -> 0 | AC11: =AC4+AC8 -> 0 | AD11: =AD4+AD8 -> 0 | AE11: =SUM(AA11:AD11) -> 0 | AF11: =AF4+AF8 -> 0 | AG11: =AG4+AG8 -> 0 | AH11: =AH4+AH8 -> 0 | AI11: =239557.567 -> 239557.57 | AJ11: =SUM(AF11:AI11) -> 239557.57 | AK11: =AK4+AK8 -> 0 | AL11: =AL4+AL8 -> 0 | AM11: =AM4+AM8 -> 0 | AN11: =424371.389 -> 424371.39 | AO11: =SUM(AK11:AN11) -> 424371.39 | AP11: =AP4+AP8 -> 0 | AQ11: =AQ4+AQ8 -> 0 | AR11: =AR4+AR8 -> 0 | AS11: =483969.357 -> 483969.36 | AT11: =SUM(AP11:AS11) -> 483969.36 | AU11: =AU4+AU8 -> 0 | AV11: =AV4+AV8 -> 0 | AW11: =AW4+AW8 -> 0 | AX11: =737421.178 -> 737421.18 | AY11: =SUM(AU11:AX11) -> 737421.18 | AZ11: =AZ4+AZ8 -> 0 | BA11: =BA4+BA8 -> 0 | BB11: =BB4+BB8 -> 0 | BC11: =BC4+BC8 -> 899371 | BD11: =SUM(AZ11:BC11) -> 899371 | BE11: =BE4+BE8 -> 0 | BF11: =BF4+BF8 -> 0 | BG11: =BG4+BG8 -> 0 | BH11: =BH4+BH8 -> 860415 | BI11: =SUM(BE11:BH11) -> 860415 | BJ11: =BJ4+BJ8 -> 0 | BK11: =BK4+BK8 -> 0 | BL11: =BL4+BL8 -> 0 | BM11: =BM4+BM8 -> 808763 | BN11: =SUM(BJ11:BM11) -> 808763 | BO11: =BO4+BO8 -> 0 | BP11: =BP4+BP8 -> 0 | BQ11: =BQ4+BQ8 -> 0 | BR11: =BR4+BR8 -> 814385 | BS11: =SUM(BO11:BR11) -> 814385 | BT11: =BT4+BT8 -> 0 | BU11: =BU4+BU8 -> 0 | BV11: =BV4+BV8 -> 0 | BW11: =BW4+BW8 -> 920253 | BX11: =SUM(BT11:BW11) -> 920253 | BY11: =BY4+BY8 -> 188370 | BZ11: =BZ4+BZ8 -> 267733 | CA11: =CA4+CA8 -> 261524 | CB11: =CB4+CB8 -> 301650 | CC11: =SUM(BY11:CB11) -> 1019277 | CD11: =CD4+CD8 -> 227321 | CE11: =CE4+CE8 -> 246204 | CF11: =CF4+CF8 -> 325897 | CG11: =CG4+CG8 -> 345260 | CH11: =SUM(CD11:CG11) -> 1144682 | CI11: =CI4+CI8 -> 339286 | CJ11: =CJ4+CJ8 -> 451337 | CK11: =CK4+CK8 -> 456449 | CL11: =CL4+CL8 -> 491223 | CM11: =SUM(CI11:CL11) -> 1738295 | CN11: =CN4+CN8 -> 447374 | CO11: =CO4+CO8 -> 602783 | CP11: =CP4+CP8 -> 626659 | CQ11: =CQ4+CQ8 -> 580478 | CR11: =SUM(CN11:CQ11) -> 2257294 | CS11: =CS4+CS8 -> 594956 | CT11: =CT4+CT8 -> 727746 | CU11: =CU4+CU8 -> 751874 | CV11: =CV4+CV8 -> 811596 | CW11: =SUM(CS11:CV11) -> 2886172 | CX11: =CX4+CX8 -> 837382 | CY11: =CY4+CY8 -> 998085 | CZ11: =CZ4+CZ8 -> 1055872 | DA11: =DA4+DA8 -> 1034971 | DB11: =SUM(CX11:DA11) -> 3926310 | DC11: =DC4+DC8 -> 1216184 | DD11: =DD4+DD8 -> 1346599 | DE11: =DE4+DE8 -> 1416926 | DF11: =DF4+DF8 -> 1419715 | DG11: =SUM(DC11:DF11) -> 5399424 | DH11: =DH4+DH8 -> 1612571 | DI11: =DI4+DI8 -> 1690594 | DJ11: =DJ4+DJ8 -> 1681801.1 | DK11: =DK4+DK8 -> 1821142.2 | DL11: =SUM(DH11:DK11) -> 6806108.3 | DM11: =DM4+DM8 -> 1860403.4 | DN11: =DN4+DN8 -> 1921666.3 | DO11: =DO4+DO8 -> 1973638.8 | DP11: =DP4+DP8 -> 2021612.5 | DQ11: =SUM(DM11:DP11) -> 7777321 | DR11: =DR4+DR8 -> 2066631.9 | DS11: =DS4+DS8 -> 2109421.7 | DT11: =DT4+DT8 -> 2150453 | DU11: =DU4+DU8 -> 2190051.4 | DV11: =SUM(DR11:DU11) -> 8516558.1 | DW11: =DW4+DW8 -> 2228456.1 | DX11: =DX4+DX8 -> 2265852.2 | DY11: =DY4+DY8 -> 2302390.5 | DZ11: =DZ4+DZ8 -> 2338197.6 | EA11: =SUM(DW11:DZ11) -> 9134896.4 | EB11: =EB4+EB8 -> 2373383.2 | EC11: =EC4+EC8 -> 2408043.4 | ED11: =ED4+ED8 -> 2442263.9 | EE11: =EE4+EE8 -> 2476121.4 | EF11: =SUM(EB11:EE11) -> 9699811.9
