Workbook

Sheet Cover
B6: =Valuation!$B$5&" -"&" "&Valuation!$B$18&" Rating - TP R$"&Valuation!$B$16&"/sh" -> CURY3 - Outperform Rating - TP R$44/sh
B8: Brazil - Homebuilders
B10: Itaú BBA - Real Estate
B11: Elvis Credendio
B12: Cel.: +55 11 3073-3032
B14: Daniel Gasparete
B15: Cel.: +55 11 3073-3906
B17: Mariangela Castro
B18: Cel.: +55 11 3073-3102
B20: Juliana Veiga
B21: Cel.: +55 11 3073-2025

Sheet Macro
A2: ="CURY3 | "&"TP R$"&Valuation!$B$16&"/sh" -> CURY3 | TP R$44/sh
A3: Macro variables | B3: =B5&RIGHT(B4,2)&B6 -> 1Q10 | C3: =C5&RIGHT(C4,2)&C6 -> 2Q10 | D3: =D5&RIGHT(D4,2)&D6 -> 3Q10 | E3: =E5&RIGHT(E4,2)&E6 -> 4Q10 | F3: =F4&F6 -> 2010 | G3: =G5&RIGHT(G4,2)&G6 -> 1Q11 | H3: =H5&RIGHT(H4,2)&H6 -> 2Q11 | I3: =I5&RIGHT(I4,2)&I6 -> 3Q11 | J3: =J5&RIGHT(J4,2)&J6 -> 4Q11 | K3: =K4&K6 -> 2011 | L3: =L5&RIGHT(L4,2)&L6 -> 1Q12 | M3: =M5&RIGHT(M4,2)&M6 -> 2Q12 | N3: =N5&RIGHT(N4,2)&N6 -> 3Q12 | O3: =O5&RIGHT(O4,2)&O6 -> 4Q12 | P3: =P4&P6 -> 2012 | Q3: =Q5&RIGHT(Q4,2)&Q6 -> 1Q13 | R3: =R5&RIGHT(R4,2)&R6 -> 2Q13 | S3: =S5&RIGHT(S4,2)&S6 -> 3Q13 | T3: =T5&RIGHT(T4,2)&T6 -> 4Q13 | U3: =U4&U6 -> 2013 | V3: =V5&RIGHT(V4,2)&V6 -> 1Q14 | W3: =W5&RIGHT(W4,2)&W6 -> 2Q14 | X3: =X5&RIGHT(X4,2)&X6 -> 3Q14 | Y3: =Y5&RIGHT(Y4,2)&Y6 -> 4Q14 | Z3: =Z4&Z6 -> 2014 | AA3: =AA5&RIGHT(AA4,2)&AA6 -> 1Q15 | AB3: =AB5&RIGHT(AB4,2)&AB6 -> 2Q15 | AC3: =AC5&RIGHT(AC4,2)&AC6 -> 3Q15 | AD3: =AD5&RIGHT(AD4,2)&AD6 -> 4Q15 | AE3: =AE4&AE6 -> 2015 | AF3: =AF5&RIGHT(AF4,2)&AF6 -> 1Q16 | AG3: =AG5&RIGHT(AG4,2)&AG6 -> 2Q16 | AH3: =AH5&RIGHT(AH4,2)&AH6 -> 3Q16 | AI3: =AI5&RIGHT(AI4,2)&AI6 -> 4Q16 | AJ3: =AJ4&AJ6 -> 2016 | AK3: =AK5&RIGHT(AK4,2)&AK6 -> 1Q17 | AL3: =AL5&RIGHT(AL4,2)&AL6 -> 2Q17 | AM3: =AM5&RIGHT(AM4,2)&AM6 -> 3Q17 | AN3: =AN5&RIGHT(AN4,2)&AN6 -> 4Q17 | AO3: =AO4&AO6 -> 2017 | AP3: =AP5&RIGHT(AP4,2)&AP6 -> 1Q18 | AQ3: =AQ5&RIGHT(AQ4,2)&AQ6 -> 2Q18 | AR3: =AR5&RIGHT(AR4,2)&AR6 -> 3Q18 | AS3: =AS5&RIGHT(AS4,2)&AS6 -> 4Q18 | AT3: =AT4&AT6 -> 2018 | AU3: =AU5&RIGHT(AU4,2)&AU6 -> 1Q19 | AV3: =AV5&RIGHT(AV4,2)&AV6 -> 2Q19 | AW3: =AW5&RIGHT(AW4,2)&AW6 -> 3Q19 | AX3: =AX5&RIGHT(AX4,2)&AX6 -> 4Q19 | AY3: =AY4&AY6 -> 2019 | AZ3: =AZ5&RIGHT(AZ4,2)&AZ6 -> 1Q20 | BA3: =BA5&RIGHT(BA4,2)&BA6 -> 2Q20 | BB3: =BB5&RIGHT(BB4,2)&BB6 -> 3Q20 | BC3: =BC5&RIGHT(BC4,2)&BC6 -> 4Q20 | BD3: =BD4&BD6 -> 2020 | BE3: =BE5&RIGHT(BE4,2)&BE6 -> 1Q21 | BF3: =BF5&RIGHT(BF4,2)&BF6 -> 2Q21 | BG3: =BG5&RIGHT(BG4,2)&BG6 -> 3Q21 | BH3: =BH5&RIGHT(BH4,2)&BH6 -> 4Q21 | BI3: =BI4&BI6 -> 2021 | BJ3: =BJ5&RIGHT(BJ4,2)&BJ6 -> 1Q22 | BK3: =BK5&RIGHT(BK4,2)&BK6 -> 2Q22 | BL3: =BL5&RIGHT(BL4,2)&BL6 -> 3Q22 | BM3: =BM5&RIGHT(BM4,2)&BM6 -> 4Q22 | BN3: =BN4&BN6 -> 2022 | BO3: =BO5&RIGHT(BO4,2)&BO6 -> 1Q23 | BP3: =BP5&RIGHT(BP4,2)&BP6 -> 2Q23 | BQ3: =BQ5&RIGHT(BQ4,2)&BQ6 -> 3Q23 | BR3: =BR5&RIGHT(BR4,2)&BR6 -> 4Q23 | BS3: =BS4&BS6 -> 2023 | BT3: =BT5&RIGHT(BT4,2)&BT6 -> 1Q24 | BU3: =BU5&RIGHT(BU4,2)&BU6 -> 2Q24 | BV3: =BV5&RIGHT(BV4,2)&BV6 -> 3Q24 | BW3: =BW5&RIGHT(BW4,2)&BW6 -> 4Q24 | BX3: =BX4&BX6 -> 2024 | BY3: =BY5&RIGHT(BY4,2)&BY6 -> 1Q25 | BZ3: =BZ5&RIGHT(BZ4,2)&BZ6 -> 2Q25 | CA3: =CA5&RIGHT(CA4,2)&CA6 -> 3Q25 | CB3: =CB5&RIGHT(CB4,2)&CB6 -> 4Q25 | CC3: =CC4&CC6 -> 2025 | CD3: =CD5&RIGHT(CD4,2)&CD6 -> 1Q26 | CE3: =CE5&RIGHT(CE4,2)&CE6 -> 2Q26E | CF3: =CF5&RIGHT(CF4,2)&CF6 -> 3Q26E | CG3: =CG5&RIGHT(CG4,2)&CG6 -> 4Q26E | CH3: =CH4&CH6 -> 2026E | CI3: =CI5&RIGHT(CI4,2)&CI6 -> 1Q27E | CJ3: =CJ5&RIGHT(CJ4,2)&CJ6 -> 2Q27E | CK3: =CK5&RIGHT(CK4,2)&CK6 -> 3Q27E | CL3: =CL5&RIGHT(CL4,2)&CL6 -> 4Q27E | CM3: =CM4&CM6 -> 2027E | CN3: =CN5&RIGHT(CN4,2)&CN6 -> 1Q28E | CO3: =CO5&RIGHT(CO4,2)&CO6 -> 2Q28E | CP3: =CP5&RIGHT(CP4,2)&CP6 -> 3Q28E | CQ3: =CQ5&RIGHT(CQ4,2)&CQ6 -> 4Q28E | CR3: =CR4&CR6 -> 2028E | CS3: =CS5&RIGHT(CS4,2)&CS6 -> 1Q29E | CT3: =CT5&RIGHT(CT4,2)&CT6 -> 2Q29E | CU3: =CU5&RIGHT(CU4,2)&CU6 -> 3Q29E | CV3: =CV5&RIGHT(CV4,2)&CV6 -> 4Q29E | CW3: =CW4&CW6 -> 2029E | CX3: =CX5&RIGHT(CX4,2)&CX6 -> 1Q30E | CY3: =CY5&RIGHT(CY4,2)&CY6 -> 2Q30E | CZ3: =CZ5&RIGHT(CZ4,2)&CZ6 -> 3Q30E | DA3: =DA5&RIGHT(DA4,2)&DA6 -> 4Q30E | DB3: =DB4&DB6 -> 2030E
A4: Year | B4: =[1]Macro_Model!B4 -> 2010 | C4: =[1]Macro_Model!C4 -> 2010 | D4: =[1]Macro_Model!D4 -> 2010 | E4: =[1]Macro_Model!E4 -> 2010 | F4: =[1]Macro_Model!F4 -> 2010 | G4: =[1]Macro_Model!G4 -> 2011 | H4: =[1]Macro_Model!H4 -> 2011 | I4: =[1]Macro_Model!I4 -> 2011 | ... DB4: =[1]Macro_Model!DB4 -> 2030
A5: Quarter | B5: =[1]Macro_Model!B5 -> 1Q | C5: =[1]Macro_Model!C5 -> 2Q | D5: =[1]Macro_Model!D5 -> 3Q | E5: =[1]Macro_Model!E5 -> 4Q | F5: =[1]Macro_Model!F5 -> 0 | G5: =[1]Macro_Model!G5 -> 1Q | H5: =[1]Macro_Model!H5 -> 2Q | I5: =[1]Macro_Model!I5 -> 3Q | ... DB5: =[1]Macro_Model!DB5 -> 20
A6: Actual / estimate | CE6: =[1]Macro_Model!CE6 -> E | CF6: =[1]Macro_Model!CF6 -> E | CG6: =[1]Macro_Model!CG6 -> E | CH6: =[1]Macro_Model!CH6 -> E | CI6: =[1]Macro_Model!CI6 -> E | CJ6: =[1]Macro_Model!CJ6 -> E | CK6: =[1]Macro_Model!CK6 -> E | CL6: =[1]Macro_Model!CL6 -> E | ... DB6: =[1]Macro_Model!DB6 -> E
A7: GDP growth y/y | B7: =[1]Macro_Model!B7 -> 0.092091395 | C7: =[1]Macro_Model!C7 -> 0.085177279 | D7: =[1]Macro_Model!D7 -> 0.069071857 | E7: =[1]Macro_Model!E7 -> 0.056893599 | F7: =[1]Macro_Model!F7 -> 0.075282491 | G7: =[1]Macro_Model!G7 -> 0.051951253 | H7: =[1]Macro_Model!H7 -> 0.047004681 | I7: =[1]Macro_Model!I7 -> 0.035373157 | ... DB7: =[1]Macro_Model!DB7 -> 0.017418903
A8: IGP-M q/q | B8: =[1]Macro_Model!B8 -> 0.0277751 | C8: =[1]Macro_Model!C8 -> 0.028275291 | D8: =[1]Macro_Model!D8 -> 0.020898783 | E8: =[1]Macro_Model!E8 -> 0.031799424 | F8: =[1]Macro_Model!F8 -> 0.11323143 | G8: =[1]Macro_Model!G8 -> 0.024312626 | H8: =[1]Macro_Model!H8 -> 0.0069680368 | I8: =[1]Macro_Model!I8 -> 0.0097144444 | ... DB8: =[1]Macro_Model!DB8 -> 0.035
A9: IGP-M y/y | B9: =[1]Macro_Model!B9 -> 0.019435617 | C9: =[1]Macro_Model!C9 -> 0.051669676 | D9: =[1]Macro_Model!D9 -> 0.077734013 | E9: =[1]Macro_Model!E9 -> 0.11323143 | F9: =[1]Macro_Model!F9 -> 0.11323143 | G9: =[1]Macro_Model!G9 -> 0.10948106 | H9: =[1]Macro_Model!H9 -> 0.086491114 | I9: =[1]Macro_Model!I9 -> 0.074588186 | ... DB9: =[1]Macro_Model!DB9 -> 0.035
A10: IPCA q/q | B10: =[1]Macro_Model!B10 -> 0.020635673 | C10: =[1]Macro_Model!C10 -> 0.01002643 | D10: =[1]Macro_Model!D10 -> 0.0049988106 | E10: =[1]Macro_Model!E10 -> 0.02226281 | F10: =[1]Macro_Model!F10 -> 0.059086887 | G10: =[1]Macro_Model!G10 -> 0.02439696 | H10: =[1]Macro_Model!H10 -> 0.013956003 | I10: =[1]Macro_Model!I10 -> 0.010633971 | ... DB10: =[1]Macro_Model!DB10 -> 0.039494898
A11: IPCA y/y | B11: =[1]Macro_Model!B11 -> 0.051660025 | C11: =[1]Macro_Model!C11 -> 0.048410906 | D11: =[1]Macro_Model!D11 -> 0.047042196 | E11: =[1]Macro_Model!E11 -> 0.059086887 | F11: =[1]Macro_Model!F11 -> 0.059086887 | G11: =[1]Macro_Model!G11 -> 0.062989876 | H11: =[1]Macro_Model!H11 -> 0.067125507 | I11: =[1]Macro_Model!I11 -> 0.073109021 | ... DB11: =[1]Macro_Model!DB11 -> 0.039494898
A12: Selic rate (avg) | B12: =[1]Macro_Model!B12 -> 0.0875 | C12: =[1]Macro_Model!C12 -> 0.0975 | D12: =[1]Macro_Model!D12 -> 0.1075 | E12: =[1]Macro_Model!E12 -> 0.1075 | F12: =[1]Macro_Model!F12 -> 0.1 | G12: =[1]Macro_Model!G12 -> 0.11416667 | H12: =[1]Macro_Model!H12 -> 0.12083333 | I12: =[1]Macro_Model!I12 -> 0.12166667 | ... DB12: =[1]Macro_Model!DB12 -> 0.125
A13: CPI q/q
A14: CPI y/y
A15: Treasury rate

Sheet IS
A2: =Valuation!$A$2 -> CURY3 | TP R$44/sh
A3: Income Statement (R$000') | B3: =Macro!B$3 -> 1Q10 | C3: =Macro!C$3 -> 2Q10 | D3: =Macro!D$3 -> 3Q10 | E3: =Macro!E$3 -> 4Q10 | F3: =Macro!F$3 -> 2010 | G3: =Macro!G$3 -> 1Q11 | H3: =Macro!H$3 -> 2Q11 | I3: =Macro!I$3 -> 3Q11 | ... DB3: =Macro!DB$3 -> 2030E
A4: Gross revenues | B4: =B5+B6 -> 0 | C4: =C5+C6 -> 0 | D4: =D5+D6 -> 0 | E4: =E5+E6 -> 0 | F4: =SUM(B4:E4) -> 0 | G4: =G5+G6 -> 0 | H4: =H5+H6 -> 0 | I4: =I5+I6 -> 0 | J4: =J5+J6 -> 0 | K4: =SUM(G4:J4) -> 0 | L4: =L5+L6 -> 0 | M4: =M5+M6 -> 0 | N4: =N5+N6 -> 0 | O4: =O5+O6 -> 0 | P4: =SUM(L4:O4) -> 0 | Q4: =Q5+Q6 -> 0 | R4: =R5+R6 -> 0 | S4: =S5+S6 -> 0 | T4: =T5+T6 -> 0 | U4: =SUM(Q4:T4) -> 0 | V4: =V5+V6 -> 0 | W4: =W5+W6 -> 0 | X4: =X5+X6 -> 0 | Y4: =Y5+Y6 -> 0 | Z4: =SUM(V4:Y4) -> 0 | AA4: =AA5+AA6 -> 0 | AB4: =AB5+AB6 -> 0 | AC4: =AC5+AC6 -> 0 | AD4: =AD5+AD6 -> 0 | AE4: =SUM(AA4:AD4) -> 0 | AF4: =AF5+AF6 -> 0 | AG4: =AG5+AG6 -> 0 | AH4: =AH5+AH6 -> 0 | AI4: =AI5+AI6 -> 0 | AJ4: =SUM(AF4:AI4) -> 0 | AK4: =AK5+AK6 -> 169820.75 | AL4: =AL5+AL6 -> 212580.54 | AM4: =AM5+AM6 -> 221445.97 | AN4: =AN5+AN6 -> 227836.26 | AO4: =SUM(AK4:AN4) -> 831683.52 | AP4: =AP5+AP6 -> 151518.38 | AQ4: =AQ5+AQ6 -> 236895.71 | AR4: =AR5+AR6 -> 268901.91 | AS4: =AS5+AS6 -> 282485.37 | AT4: =SUM(AP4:AS4) -> 939801.36 | AU4: =AU5+AU6 -> 193287 | AV4: =AV5+AV6 -> 273610 | AW4: =AW5+AW6 -> 268175 | AX4: =AX5+AX6 -> 308715 | AY4: =SUM(AU4:AX4) -> 1043787 | AZ4: =AZ5+AZ6 -> 233098 | BA4: =BA5+BA6 -> 252454 | BB4: =BB5+BB6 -> 334505 | BC4: =BC5+BC6 -> 353014 | BD4: =SUM(AZ4:BC4) -> 1173071 | BE4: =BE5+BE6 -> 346976 | BF4: =BF5+BF6 -> 462074 | BG4: =BG5+BG6 -> 466696 | BH4: =BH5+BH6 -> 502424 | BI4: =SUM(BE4:BH4) -> 1778170 | BJ4: =BJ5+BJ6 -> 458170 | BK4: =BK5+BK6 -> 616407 | BL4: =BL5+BL6 -> 640437 | BM4: =BM5+BM6 -> 593421 | BN4: =SUM(BJ4:BM4) -> 2308435 | BO4: =BO5+BO6 -> 607423 | BP4: =BP5+BP6 -> 743352 | BQ4: =BQ5+BQ6 -> 768155 | BR4: =BR5+BR6 -> 829075 | BS4: =SUM(BO4:BR4) -> 2948005 | BT4: =BT5+BT6 -> 854925 | BU4: =BU5+BU6 -> 1017876 | BV4: =BV5+BV6 -> 1078346 | BW4: =BW5+BW6 -> 1056476 | BX4: =SUM(BT4:BW4) -> 4007623 | BY4: =BY5+BY6 -> 1244407 | BZ4: =BZ5+BZ6 -> 1375487 | CA4: =CA5+CA6 -> 1449421 | CB4: =CB5+CB6 -> 1453820 | CC4: =SUM(BY4:CB4) -> 5523135 | CD4: =CD5+CD6 -> 1644474 | CE4: =CE5+CE6 -> 1725754 | CF4: =CF5+CF6 -> 1788351.1 | CG4: =CG5+CG6 -> 1817747 | CH4: =SUM(CD4:CG4) -> 6976326.1 | CI4: =CI5+CI6 -> 1922523.3 | CJ4: =CJ5+CJ6 -> 2187740.6 | CK4: =CK5+CK6 -> 2212729.7 | CL4: =CL5+CL6 -> 2102030.1 | CM4: =SUM(CI4:CL4) -> 8425023.7 | CN4: =CN5+CN6 -> 2209158.7 | CO4: =CO5+CO6 -> 2383613.7 | CP4: =CP5+CP6 -> 2406821.1 | CQ4: =CQ5+CQ6 -> 2350310.3 | CR4: =SUM(CN4:CQ4) -> 9349903.9 | CS4: =CS5+CS6 -> 2431933.4 | CT4: =CT5+CT6 -> 2590266.9 | CU4: =CU5+CU6 -> 2596876.6 | CV4: =CV5+CV6 -> 2524426.7 | CW4: =SUM(CS4:CV4) -> 10143503 | CX4: =CX5+CX6 -> 2598266.2 | CY4: =CY5+CY6 -> 2753812.5 | CZ4: =CZ5+CZ6 -> 2753116.3 | DA4: =DA5+DA6 -> 2671374.3 | DB4: =SUM(CX4:DA4) -> 10776569
A5: Development revenues | F5: =SUM(B5:E5) -> 0 | K5: =SUM(G5:J5) -> 0 | P5: =SUM(L5:O5) -> 0 | U5: =SUM(Q5:T5) -> 0 | Z5: =SUM(V5:Y5) -> 0 | AE5: =SUM(AA5:AD5) -> 0 | AJ5: =SUM(AF5:AI5) -> 0 | AK5: =AK9/(1-AK8) -> 169820.75 | AL5: =AL9/(1-AL8) -> 212580.54 | AM5: =AM9/(1-AM8) -> 221445.97 | AN5: =AN9/(1-AN8) -> 227836.26 | AO5: =SUM(AK5:AN5) -> 831683.52 | AP5: =AP9/(1-AP8) -> 151518.38 | AQ5: =AQ9/(1-AQ8) -> 236895.71 | AR5: =AR9/(1-AR8) -> 268901.91 | AS5: =AS9/(1-AS8) -> 282485.37 | AT5: =SUM(AP5:AS5) -> 939801.36 | AU5: =193732-2076 -> 191656 | AV5: =248291-3205 -> 245086 | AW5: =268629-1695 -> 266934 | AX5: =1063367-24443-8342+100-SUM(AU5:AW5) -> 327006 | AY5: =SUM(AU5:AX5) -> 1030682 | AZ5: =234242-1985 -> 232257 | BA5: =263860-11578-507 -> 251775 | BB5: =830029-8974-3617-SUM(AZ5:BA5) -> 333406 | BC5: =1183813-16767-4243-SUM(AZ5:BB5) -> 345365 | BD5: =SUM(AZ5:BC5) -> 1162803 | BE5: =348556-1130-1564 -> 345862 | BF5: =467360-4492-2158 -> 460710 | BG5: =1290410-12155-6059-SUM(BE5:BF5) -> 465624 | BH5: =1795292-13083-8289-SUM(BE5:BG5) -> 501724 | BI5: =SUM(BE5:BH5) -> 1773920 | BJ5: =459417-740-1572 -> 457105 | BK5: =619527-4298-578 -> 614651 | BL5: =1720898-8316-1765-SUM(BJ5:BK5) -> 639061 | BM5: =2318165-11358-3745-SUM(BJ5:BL5) -> 592245 | BN5: =SUM(BJ5:BM5) -> 2303062 | BO5: =608998-1086-2065 -> 605847 | BP5: =743265-382-704 -> 742179 | BQ5: =767232-2543+1829 -> 766518 | BR5: =2950126-1185-6289-SUM(BO5:BQ5) -> 828108 | BS5: =SUM(BO5:BR5) -> 2942652 | BT5: =851906-1722+2980 -> 853164 | BU5: =1016524+2082-1667 -> 1016939 | BV5: =1084539-6033-160 -> 1078346 | BW5: =4016820+2114-14025-SUM(BT5:BV5) -> 1056460 | BX5: =SUM(BT5:BW5) -> 4004909 | BY5: =1246115-6033-2089 -> 1237993 | BZ5: =1393733-4822-13805 -> 1375106 | CA5: =1461895-3018-11780 -> 1447097 | CB5: =5567252-11984-42968-SUM(BY5:CA5) -> 1452104 | CC5: =SUM(BY5:CB5) -> 5512300 | CD5: =1660432-17750+353 -> 1643035 | CE5: =1742831-3187-14445 -> 1725199 | CF5: =Operating!CF35 -> 1787776 | CG5: =Operating!CG35 -> 1817162.4 | CH5: =SUM(CD5:CG5) -> 6973172.4 | CI5: =Operating!CI35 -> 1921905 | CJ5: =Operating!CJ35 -> 2187037.1 | CK5: =Operating!CK35 -> 2212018.1 | CL5: =Operating!CL35 -> 2101354.1 | CM5: =SUM(CI5:CL5) -> 8422314.3 | CN5: =Operating!CN35 -> 2208448.3 | CO5: =Operating!CO35 -> 2382847.1 | CP5: =Operating!CP35 -> 2406047.1 | CQ5: =Operating!CQ35 -> 2349554.5 | CR5: =SUM(CN5:CQ5) -> 9346897 | CS5: =Operating!CS35 -> 2431151.3 | CT5: =Operating!CT35 -> 2589433.8 | CU5: =Operating!CU35 -> 2596041.4 | CV5: =Operating!CV35 -> 2523614.8 | CW5: =SUM(CS5:CV5) -> 10140241 | CX5: =Operating!CX35 -> 2597430.6 | CY5: =Operating!CY35 -> 2752926.8 | CZ5: =Operating!CZ35 -> 2752230.9 | DA5: =Operating!DA35 -> 2670515.2 | DB5: =SUM(CX5:DA5) -> 10773104
A6: Service revenues | F6: =SUM(B6:E6) -> 0 | K6: =SUM(G6:J6) -> 0 | P6: =SUM(L6:O6) -> 0 | U6: =SUM(Q6:T6) -> 0 | Z6: =SUM(V6:Y6) -> 0 | AE6: =SUM(AA6:AD6) -> 0 | AJ6: =SUM(AF6:AI6) -> 0 | AO6: =SUM(AK6:AN6) -> 0 | AT6: =SUM(AP6:AS6) -> 0 | AU6: 1631 | AV6: 28524 | AW6: 1241 | AX6: =13105-SUM(AU6:AW6) -> -18291 | AY6: =SUM(AU6:AX6) -> 13105 | AZ6: 841 | BA6: 679 | BB6: =2619-SUM(AZ6:BA6) -> 1099 | BC6: =10268-SUM(AZ6:BB6) -> 7649 | BD6: =SUM(AZ6:BC6) -> 10268 | BE6: 1114 | BF6: 1364 | BG6: =3550-SUM(BE6:BF6) -> 1072 | BH6: =4250-SUM(BE6:BG6) -> 700 | BI6: =SUM(BE6:BH6) -> 4250 | BJ6: 1065 | BK6: 1756 | BL6: =4197-SUM(BJ6:BK6) -> 1376 | BM6: =5373-SUM(BJ6:BL6) -> 1176 | BN6: =SUM(BJ6:BM6) -> 5373 | BO6: 1576 | BP6: 1173 | BQ6: 1637 | BR6: =5353-SUM(BO6:BQ6) -> 967 | BS6: =SUM(BO6:BR6) -> 5353 | BT6: 1761 | BU6: 937 | BV6: 0 | BW6: =2714-SUM(BT6:BV6) -> 16 | BX6: =SUM(BT6:BW6) -> 2714 | BY6: 6414 | BZ6: 381 | CA6: 2324 | CB6: =10835-SUM(BY6:CA6) -> 1716 | CC6: =SUM(BY6:CB6) -> 10835 | CD6: 1439 | CE6: 555 | CF6: =Operating!CF41 -> 575.13114 | CG6: =Operating!CG41 -> 584.58482 | CH6: =SUM(CD6:CG6) -> 3153.716 | CI6: =Operating!CI41 -> 618.28072 | CJ6: =Operating!CJ41 -> 703.57424 | CK6: =Operating!CK41 -> 711.61068 | CL6: =Operating!CL41 -> 676.00985 | CM6: =SUM(CI6:CL6) -> 2709.4755 | CN6: =Operating!CN41 -> 710.46226 | CO6: =Operating!CO41 -> 766.56673 | CP6: =Operating!CP41 -> 774.0302 | CQ6: =Operating!CQ41 -> 755.85642 | CR6: =SUM(CN6:CQ6) -> 3006.9156 | CS6: =Operating!CS41 -> 782.10627 | CT6: =Operating!CT41 -> 833.02609 | CU6: =Operating!CU41 -> 835.15176 | CV6: =Operating!CV41 -> 811.85198 | CW6: =SUM(CS6:CV6) -> 3262.1361 | CX6: =Operating!CX41 -> 835.59866 | CY6: =Operating!CY41 -> 885.62212 | CZ6: =Operating!CZ41 -> 885.39824 | DA6: =Operating!DA41 -> 859.11013 | DB6: =SUM(CX6:DA6) -> 3465.7292
A7: Taxes and deductions | F7: =SUM(B7:E7) -> 0 | K7: =SUM(G7:J7) -> 0 | P7: =SUM(L7:O7) -> 0 | U7: =SUM(Q7:T7) -> 0 | Z7: =SUM(V7:Y7) -> 0 | AE7: =SUM(AA7:AD7) -> 0 | AJ7: =SUM(AF7:AI7) -> 0 | AK7: =AK9-AK5 -> -3532.2716 | AL7: =AL9-AL5 -> -4421.6751 | AM7: =AM9-AM5 -> -4606.0762 | AN7: =AN9-AN5 -> -4738.9943 | AO7: =SUM(AK7:AN7) -> -17299.017 | AP7: =AP9-AP5 -> -3151.5822 | AQ7: =AQ9-AQ5 -> -4927.4307 | AR7: =AR9-AR5 -> -5593.1598 | AS7: =AS9-AS5 -> -5875.6957 | AT7: =SUM(AP7:AS7) -> -19547.868 | AU7: -4917 | AV7: -5877 | AW7: -6651 | AX7: =-24510-SUM(AU7:AW7) -> -7065 | AY7: =SUM(AU7:AX7) -> -24510 | AZ7: -5777 | BA7: -6250 | BB7: =-20635-SUM(AZ7:BA7) -> -8608 | BC7: =-28389-SUM(AZ7:BB7) -> -7754 | BD7: =SUM(AZ7:BC7) -> -28389 | BE7: -7690 | BF7: -10737 | BG7: =-28674-SUM(BE7:BF7) -> -10247 | BH7: =-39875-SUM(BE7:BG7) -> -11201 | BI7: =SUM(BE7:BH7) -> -39875 | BJ7: -10796 | BK7: -13624 | BL7: =-38198-SUM(BJ7:BK7) -> -13778 | BM7: =-51141-SUM(BJ7:BL7) -> -12943 | BN7: =SUM(BJ7:BM7) -> -51141 | BO7: -12467 | BP7: -15606 | BQ7: -16281 | BR7: =-61833-SUM(BO7:BQ7) -> -17479 | BS7: =SUM(BO7:BR7) -> -61833 | BT7: -17543 | BU7: -19791 | BV7: -22474 | BW7: =-81313-SUM(BT7:BV7) -> -21505 | BX7: =SUM(BT7:BW7) -> -81313 | BY7: -28223 | BZ7: -28888 | CA7: -32495 | CB7: =-123711-SUM(BY7:CA7) -> -34105 | CC7: =SUM(BY7:CB7) -> -123711 | CD7: -31903 | CE7: -35160 | CF7: =-CF8*CF$4 -> -37197.703 | CG7: =-CG8*CG$4 -> -37809.138 | CH7: =SUM(CD7:CG7) -> -142069.84 | CI7: =-CI8*CI$4 -> -39988.485 | CJ7: =-CJ8*CJ$4 -> -45505.005 | CK7: =-CK8*CK$4 -> -46024.778 | CL7: =-CL8*CL$4 -> -43722.226 | CM7: =SUM(CI7:CL7) -> -175240.49 | CN7: =-CN8*CN$4 -> -45950.501 | CO7: =-CO8*CO$4 -> -49579.165 | CP7: =-CP8*CP$4 -> -50061.879 | CQ7: =-CQ8*CQ$4 -> -48886.455 | CR7: =SUM(CN7:CQ7) -> -194478 | CS7: =-CS8*CS$4 -> -50584.214 | CT7: =-CT8*CT$4 -> -53877.551 | CU7: =-CU8*CU$4 -> -54015.032 | CV7: =-CV8*CV$4 -> -52508.075 | CW7: =SUM(CS7:CV7) -> -210984.87 | CX7: =-CX8*CX$4 -> -54043.937 | CY7: =-CY8*CY$4 -> -57279.299 | CZ7: =-CZ8*CZ$4 -> -57264.819 | DA7: =-DA8*DA$4 -> -55564.586 | DB7: =SUM(CX7:DA7) -> -224152.64
A8: % of gross revenues | B8: =-B7/B$4 -> #DIV/0! | C8: =-C7/C$4 -> #DIV/0! | D8: =-D7/D$4 -> #DIV/0! | E8: =-E7/E$4 -> #DIV/0! | F8: =-F7/F$4 -> #DIV/0! | G8: =-G7/G$4 -> #DIV/0! | H8: =-H7/H$4 -> #DIV/0! | I8: =-I7/I$4 -> #DIV/0! | ... AJ8: =-AJ7/AJ$4 -> #DIV/0! | AK8: 0.0208 | AL8: 0.0208 | AM8: 0.0208 | AN8: 0.0208 | AO8: =-AO7/AO$4 -> 0.0208 | AP8: 0.0208 | AQ8: 0.0208 | AR8: 0.0208 | AS8: 0.0208 | AT8: =-AT7/AT$4 -> 0.0208 | AU8: =-AU7/AU$4 -> 0.025438855 | AV8: =-AV7/AV$4 -> 0.021479478 | AW8: =-AW7/AW$4 -> 0.02480097 | AX8: =-AX7/AX$4 -> 0.022885185 | AY8: =-AY7/AY$4 -> 0.023481802 | AZ8: =-AZ7/AZ$4 -> 0.024783567 | BA8: =-BA7/BA$4 -> 0.024756985 | ... CE8: =-CE7/CE$4 -> 0.020373703 | CF8: 0.0208 | CG8: 0.0208 | CH8: =-CH7/CH$4 -> 0.020364564 | CI8: 0.0208 | CJ8: 0.0208 | CK8: 0.0208 | CL8: 0.0208 | CM8: =-CM7/CM$4 -> 0.0208 | CN8: 0.0208 | CO8: 0.0208 | CP8: 0.0208 | CQ8: 0.0208 | CR8: =-CR7/CR$4 -> 0.0208 | CS8: 0.0208 | CT8: 0.0208 | CU8: 0.0208 | CV8: 0.0208 | CW8: =-CW7/CW$4 -> 0.0208 | CX8: 0.0208 | CY8: 0.0208 | CZ8: 0.0208 | DA8: 0.0208 | DB8: =-DB7/DB$4 -> 0.0208
A9: Net Revenues | B9: =B4+B7 -> 0 | C9: =C4+C7 -> 0 | D9: =D4+D7 -> 0 | E9: =E4+E7 -> 0 | F9: =SUM(B9:E9) -> 0 | G9: =G4+G7 -> 0 | H9: =H4+H7 -> 0 | I9: =I4+I7 -> 0 | J9: =J4+J7 -> 0 | K9: =SUM(G9:J9) -> 0 | L9: =L4+L7 -> 0 | M9: =M4+M7 -> 0 | N9: =N4+N7 -> 0 | O9: =O4+O7 -> 0 | P9: =SUM(L9:O9) -> 0 | Q9: =Q4+Q7 -> 0 | R9: =R4+R7 -> 0 | S9: =S4+S7 -> 0 | T9: =T4+T7 -> 0 | U9: =SUM(Q9:T9) -> 0 | V9: =V4+V7 -> 0 | W9: =W4+W7 -> 0 | X9: =X4+X7 -> 0 | Y9: =Y4+Y7 -> 0 | Z9: =SUM(V9:Y9) -> 0 | AA9: =AA4+AA7 -> 0 | AB9: =AB4+AB7 -> 0 | AC9: =AC4+AC7 -> 0 | AD9: =AD4+AD7 -> 0 | AE9: =SUM(AA9:AD9) -> 0 | AF9: =AF4+AF7 -> 0 | AG9: =AG4+AG7 -> 0 | AH9: =AH4+AH7 -> 0 | AI9: =AI4+AI7 -> 0 | AJ9: =SUM(AF9:AI9) -> 0 | AK9: 166288.48 | AL9: 208158.86 | AM9: 216839.89 | AN9: 223097.27 | AO9: =SUM(AK9:AN9) -> 814384.5 | AP9: 148366.79 | AQ9: 231968.28 | AR9: 263308.75 | AS9: 276609.67 | AT9: =SUM(AP9:AS9) -> 920253.5 | AU9: =AU4+AU7 -> 188370 | AV9: =AV4+AV7 -> 267733 | AW9: =AW4+AW7 -> 261524 | AX9: =AX4+AX7 -> 301650 | AY9: =SUM(AU9:AX9) -> 1019277 | AZ9: =AZ4+AZ7 -> 227321 | BA9: =BA4+BA7 -> 246204 | BB9: =BB4+BB7 -> 325897 | BC9: =BC4+BC7 -> 345260 | BD9: =SUM(AZ9:BC9) -> 1144682 | BE9: =BE4+BE7 -> 339286 | BF9: =BF4+BF7 -> 451337 | BG9: =BG4+BG7 -> 456449 | BH9: =BH4+BH7 -> 491223 | BI9: =SUM(BE9:BH9) -> 1738295 | BJ9: =BJ4+BJ7 -> 447374 | BK9: =BK4+BK7 -> 602783 | BL9: =BL4+BL7 -> 626659 | BM9: =BM4+BM7 -> 580478 | BN9: =SUM(BJ9:BM9) -> 2257294 | BO9: =BO4+BO7 -> 594956 | BP9: =BP4+BP7 -> 727746 | BQ9: =BQ4+BQ7 -> 751874 | BR9: =BR4+BR7 -> 811596 | BS9: =SUM(BO9:BR9) -> 2886172 | BT9: =BT4+BT7 -> 837382 | BU9: =BU4+BU7 -> 998085 | BV9: =BV4+BV7 -> 1055872 | BW9: =BW4+BW7 -> 1034971 | BX9: =SUM(BT9:BW9) -> 3926310 | BY9: =BY4+BY7 -> 1216184 | BZ9: =BZ4+BZ7 -> 1346599 | CA9: =CA4+CA7 -> 1416926 | CB9: =CB4+CB7 -> 1419715 | CC9: =SUM(BY9:CB9) -> 5399424 | CD9: =CD4+CD7 -> 1612571 | CE9: =CE4+CE7 -> 1690594 | CF9: =CF4+CF7 -> 1751153.4 | CG9: =CG4+CG7 -> 1779937.9 | CH9: =SUM(CD9:CG9) -> 6834256.3 | CI9: =CI4+CI7 -> 1882534.8 | CJ9: =CJ4+CJ7 -> 2142235.6 | CK9: =CK4+CK7 -> 2166704.9 | CL9: =CL4+CL7 -> 2058307.9 | CM9: =SUM(CI9:CL9) -> 8249783.2 | CN9: =CN4+CN7 -> 2163208.2 | CO9: =CO4+CO7 -> 2334034.5 | CP9: =CP4+CP7 -> 2356759.2 | CQ9: =CQ4+CQ7 -> 2301423.9 | CR9: =SUM(CN9:CQ9) -> 9155425.9 | CS9: =CS4+CS7 -> 2381349.2 | CT9: =CT4+CT7 -> 2536389.3 | CU9: =CU4+CU7 -> 2542861.5 | CV9: =CV4+CV7 -> 2471918.6 | CW9: =SUM(CS9:CV9) -> 9932518.6 | CX9: =CX4+CX7 -> 2544222.2 | CY9: =CY4+CY7 -> 2696533.2 | CZ9: =CZ4+CZ7 -> 2695851.5 | DA9: =DA4+DA7 -> 2615809.7 | DB9: =SUM(CX9:DA9) -> 10552417
A10: Operating Costs | B10: =B11+B13+B14 -> 0 | C10: =C11+C13+C14 -> 0 | D10: =D11+D13+D14 -> 0 | E10: =E11+E13+E14 -> 0 | F10: =SUM(B10:E10) -> 0 | G10: =G11+G13+G14 -> 0 | H10: =H11+H13+H14 -> 0 | I10: =I11+I13+I14 -> 0 | J10: =J11+J13+J14 -> 0 | K10: =SUM(G10:J10) -> 0 | L10: =L11+L13+L14 -> 0 | M10: =M11+M13+M14 -> 0 | N10: =N11+N13+N14 -> 0 | O10: =O11+O13+O14 -> 0 | P10: =SUM(L10:O10) -> 0 | Q10: =Q11+Q13+Q14 -> 0 | R10: =R11+R13+R14 -> 0 | S10: =S11+S13+S14 -> 0 | T10: =T11+T13+T14 -> 0 | U10: =SUM(Q10:T10) -> 0 | V10: =V11+V13+V14 -> 0 | W10: =W11+W13+W14 -> 0 | X10: =X11+X13+X14 -> 0 | Y10: =Y11+Y13+Y14 -> 0 | Z10: =SUM(V10:Y10) -> 0 | AA10: =AA11+AA13+AA14 -> 0 | AB10: =AB11+AB13+AB14 -> 0 | AC10: =AC11+AC13+AC14 -> 0 | AD10: =AD11+AD13+AD14 -> 0 | AE10: =SUM(AA10:AD10) -> 0 | AF10: =AF11+AF13+AF14 -> 0 | AG10: =AG11+AG13+AG14 -> 0 | AH10: =AH11+AH13+AH14 -> 0 | AI10: =AI11+AI13+AI14 -> 0 | AJ10: =SUM(AF10:AI10) -> 0 | AK10: =AK11+AK13+AK14 -> -128091.89 | AL10: =AL11+AL13+AL14 -> -152984.22 | AM10: =AM11+AM13+AM14 -> -151238.84 | AN10: =AN11+AN13+AN14 -> -138225.36 | AO10: =SUM(AK10:AN10) -> -570540.31 | AP10: =AP11+AP13+AP14 -> -103828.06 | AQ10: =AQ11+AQ13+AQ14 -> -159413.27 | AR10: =AR11+AR13+AR14 -> -165749.62 | AS10: =AS11+AS13+AS14 -> -176534.66 | AT10: =SUM(AP10:AS10) -> -605525.61 | AU10: =AU11+AU13+AU14 -> -133039 | AV10: =AV11+AV13+AV14 -> -166982 | AW10: =AW11+AW13+AW14 -> -180689 | AX10: =AX11+AX13+AX14 -> -182682 | AY10: =SUM(AU10:AX10) -> -663392 | AZ10: =AZ11+AZ13+AZ14 -> -149181 | BA10: =BA11+BA13+BA14 -> -159137 | BB10: =BB11+BB13+BB14 -> -202541 | BC10: =BC11+BC13+BC14 -> -205433 | BD10: =SUM(AZ10:BC10) -> -716292 | BE10: =BE11+BE13+BE14 -> -218944 | BF10: =BF11+BF13+BF14 -> -288421 | BG10: =BG11+BG13+BG14 -> -281478 | BH10: =BH11+BH13+BH14 -> -304781 | BI10: =SUM(BE10:BH10) -> -1093624 | BJ10: =BJ11+BJ13+BJ14 -> -281465 | BK10: =BK11+BK13+BK14 -> -387286 | BL10: =BL11+BL13+BL14 -> -392916 | BM10: =BM11+BM13+BM14 -> -358735 | BN10: =SUM(BJ10:BM10) -> -1420402 | BO10: =BO11+BO13+BO14 -> -371794 | BP10: =BP11+BP13+BP14 -> -453192 | BQ10: =BQ11+BQ13+BQ14 -> -467971 | BR10: =BR11+BR13+BR14 -> -497862 | BS10: =SUM(BO10:BR10) -> -1790819 | BT10: =BT11+BT13+BT14 -> -520773 | BU10: =BU11+BU13+BU14 -> -615554 | BV10: =BV11+BV13+BV14 -> -646426 | BW10: =BW11+BW13+BW14 -> -630617 | BX10: =SUM(BT10:BW10) -> -2413370 | BY10: =BY11+BY13+BY14 -> -741296 | BZ10: =BZ11+BZ13+BZ14 -> -813823 | CA10: =CA11+CA13+CA14 -> -850699 | CB10: =CB11+CB13+CB14 -> -847019 | CC10: =SUM(BY10:CB10) -> -3252837 | CD10: =CD11+CD13+CD14 -> -982915 | CE10: =CE11+CE13+CE14 -> -1022232 | CF10: =CF11+CF13+CF14 -> -1052994.3 | CG10: =CG11+CG13+CG14 -> -1072359 | CH10: =SUM(CD10:CG10) -> -4130500.3 | CI10: =CI11+CI13+CI14 -> -1144943.6 | CJ10: =CJ11+CJ13+CJ14 -> -1292162.2 | CK10: =CK11+CK13+CK14 -> -1297905.5 | CL10: =CL11+CL13+CL14 -> -1228667.6 | CM10: =SUM(CI10:CL10) -> -4963679 | CN10: =CN11+CN13+CN14 -> -1319066.6 | CO10: =CO11+CO13+CO14 -> -1426000.7 | CP10: =CP11+CP13+CP14 -> -1444561.5 | CQ10: =CQ11+CQ13+CQ14 -> -1411852 | CR10: =SUM(CN10:CQ10) -> -5601480.8 | CS10: =CS11+CS13+CS14 -> -1470743.5 | CT10: =CT11+CT13+CT14 -> -1570168.6 | CU10: =CU11+CU13+CU14 -> -1579946.6 | CV10: =CV11+CV13+CV14 -> -1537500.9 | CW10: =SUM(CS10:CV10) -> -6158359.6 | CX10: =CX11+CX13+CX14 -> -1582104.5 | CY10: =CY11+CY13+CY14 -> -1679258.8 | CZ10: =CZ11+CZ13+CZ14 -> -1684471 | DA10: =DA11+DA13+DA14 -> -1635900.3 | DB10: =SUM(CX10:DA10) -> -6581734.5
A11: Development costs | F11: =SUM(B11:E11) -> 0 | K11: =SUM(G11:J11) -> 0 | P11: =SUM(L11:O11) -> 0 | U11: =SUM(Q11:T11) -> 0 | Z11: =SUM(V11:Y11) -> 0 | AE11: =SUM(AA11:AD11) -> 0 | AJ11: =SUM(AF11:AI11) -> 0 | AK11: -128091.89 | AL11: -152984.22 | AM11: -151238.84 | AN11: -138225.36 | AO11: =SUM(AK11:AN11) -> -570540.31 | AP11: -103828.06 | AQ11: -159413.27 | AR11: -165749.62 | AS11: -176534.66 | AT11: =SUM(AP11:AS11) -> -605525.61 | AU11: =-124775-AU13 -> -122991 | AV11: =-158457-AV13 -> -156928 | AW11: =-180689-AW13-AW14 -> -171768 | AX11: =-634880-SUM(AU11:AW11)-SUM(AU13:AX13) -> -176867 | AY11: =SUM(AU11:AX11) -> -628554 | AZ11: =-139488-AZ13 -> -138123 | BA11: =-149870-BA13 -> -148184 | BB11: =-202541-BB13-BB14 -> -196526 | BC11: =-682997-SUM(AZ11:BB11)-SUM(AZ13:BC13) -> -195949 | BD11: =SUM(AZ11:BC11) -> -678782 | BE11: =-213294-BE13+1020-122 -> -212274 | BF11: =-283327+2687 -> -280640 | BG11: =-275625-5853-BG13-BG14 -> -271663 | BH11: =-1082692-SUM(BE11:BG11)-SUM(BE13:BH13) -> -316781 | BI11: =SUM(BE11:BH11) -> -1081358 | BJ11: =-279593-BJ13+604-607 -> -278989 | BK11: =-388579+2608 -> -385971 | BL11: =-391796-1120-BL13-BL14 -> -383036 | BM11: =-1415751-SUM(BJ11:BL11)-SUM(BJ13:BM13) -> -364471 | BN11: =SUM(BJ11:BM11) -> -1412467 | BO11: =-371450-BO13+1477-1299 -> -369973 | BP11: =-452163+725 -> -451438 | BQ11: =-463481-2863 -> -466344 | BR11: =-1789464-SUM(BO11:BQ11)-SUM(BO13:BR13) -> -495745 | BS11: =SUM(BO11:BR11) -> -1783500 | BT11: =-515984-BT13-2219-1856 -> -518203 | BU11: =-611200-1474 -> -612674 | BV11: =-643412+660 -> -642752 | BW11: =-2410748-SUM(BT11:BV11)-SUM(BT13:BW13) -> -628758 | BX11: =SUM(BT11:BW11) -> -2402387 | BY11: =-740484-BY13+1505-1711 -> -738979 | BZ11: =-812123+2758 -> -809365 | CA11: =-848164+1716 -> -846448 | CB11: =-3248989-SUM(BY11:CA11)-SUM(BY13:CB13) -> -841641 | CC11: =SUM(BY11:CB11) -> -3236433 | CD11: =-982117-CD13 -> -977874 | CE11: =-1021269-CE13 -> -1015994 | CF11: =-(1-CF12)*CF5 -> -1050671.7 | CG11: =-(1-CG12)*CG5 -> -1070567 | CH11: =SUM(CD11:CG11) -> -4115106.7 | CI11: =-(1-CI12)*CI5 -> -1134817 | CJ11: =-(1-CJ12)*CJ5 -> -1286483.3 | CK11: =-(1-CK12)*CK5 -> -1292383.2 | CL11: =-(1-CL12)*CL5 -> -1223499.4 | CM11: =SUM(CI11:CL11) -> -4937182.9 | CN11: =-(1-CN12)*CN5 -> -1315759.5 | CO11: =-(1-CO12)*CO5 -> -1424092.8 | CP11: =-(1-CP12)*CP5 -> -1440027.9 | CQ11: =-(1-CQ12)*CQ5 -> -1407292.4 | CR11: =SUM(CN11:CQ11) -> -5587172.7 | CS11: =-(1-CS12)*CS5 -> -1469208.3 | CT11: =-(1-CT12)*CT5 -> -1569730.1 | CU11: =-(1-CU12)*CU5 -> -1576021 | CV11: =-(1-CV12)*CV5 -> -1533238.4 | CW11: =SUM(CS11:CV11) -> -6148197.8 | CX11: =-(1-CX12)*CX5 -> -1581059.4 | CY11: =-(1-CY12)*CY5 -> -1679333.2 | CZ11: =-(1-CZ12)*CZ5 -> -1680614.3 | DA11: =-(1-DA12)*DA5 -> -1631601.8 | DB11: =SUM(CX11:DA11) -> -6572608.7
A12: Development gross margin (%) | B12: =(1+B11/B5) -> #DIV/0! | C12: =(1+C11/C5) -> #DIV/0! | D12: =(1+D11/D5) -> #DIV/0! | E12: =(1+E11/E5) -> #DIV/0! | F12: =(1+F11/F5) -> #DIV/0! | G12: =(1+G11/G5) -> #DIV/0! | H12: =(1+H11/H5) -> #DIV/0! | I12: =(1+I11/I5) -> #DIV/0! | ... CE12: =(1+CE11/CE5) -> 0.41108591 | CF12: =(CF118*Operating!CF37+CE110*Operating!CF39)/Operating!CF35 -> 0.41230238 | CG12: =(CG118*Operating!CG37+CF110*Operating!CG39)/Operating!CG35 -> 0.41085783 | CH12: =(1+CH11/CH5) -> 0.40986592 | CI12: =(CI118*Operating!CI37+CH110*Operating!CI39)/Operating!CI35-0.25% -> 0.40953531 | CJ12: =(CJ118*Operating!CJ37+CI110*Operating!CJ39)/Operating!CJ35+0.25% -> 0.41176889 | CK12: =(CK118*Operating!CK37+CJ110*Operating!CK39)/Operating!CK35+0.75% -> 0.41574474 | CL12: =(CL118*Operating!CL37+CK110*Operating!CL39)/Operating!CL35+1% -> 0.41775669 | CM12: =(1+CM11/CM5) -> 0.41379736 | CN12: =(CN118*Operating!CN37+CM110*Operating!CN39)/Operating!CN35 -> 0.40421537 | CO12: =(CO118*Operating!CO37+CN110*Operating!CO39)/Operating!CO35 -> 0.40235662 | CP12: =(CP118*Operating!CP37+CO110*Operating!CP39)/Operating!CP35 -> 0.40149635 | CQ12: =(CQ118*Operating!CQ37+CP110*Operating!CQ39)/Operating!CQ35 -> 0.40103864 | CR12: =(1+CR11/CR5) -> 0.40224305 | CS12: =(CS118*Operating!CS37+CR110*Operating!CS39)/Operating!CS35 -> 0.39567386 | CT12: =(CT118*Operating!CT37+CS110*Operating!CT39)/Operating!CT35 -> 0.39379408 | CU12: =(CU118*Operating!CU37+CT110*Operating!CU39)/Operating!CU35 -> 0.39291377 | CV12: =(CV118*Operating!CV37+CU110*Operating!CV39)/Operating!CV35 -> 0.39244358 | CW12: =(1+CW11/CW5) -> 0.39368329 | CX12: =(CX118*Operating!CX37+CW110*Operating!CX39)/Operating!CX35 -> 0.3912987 | CY12: =(CY118*Operating!CY37+CX110*Operating!CY39)/Operating!CY35 -> 0.38998261 | CZ12: =(CZ118*Operating!CZ37+CY110*Operating!CZ39)/Operating!CZ35 -> 0.38936291 | DA12: =(DA118*Operating!DA37+CZ110*Operating!DA39)/Operating!DA35 -> 0.38903107 | DB12: =(1+DB11/DB5) -> 0.38990573
A13: Capitalized interest expenses | F13: =SUM(B13:E13) -> 0 | K13: =SUM(G13:J13) -> 0 | P13: =SUM(L13:O13) -> 0 | U13: =SUM(Q13:T13) -> 0 | Z13: =SUM(V13:Y13) -> 0 | AE13: =SUM(AA13:AD13) -> 0 | AJ13: =SUM(AF13:AI13) -> 0 | AO13: =SUM(AK13:AN13) -> 0 | AT13: =SUM(AP13:AS13) -> 0 | AU13: -1784 | AV13: -1529 | AW13: -1146 | AX13: =-6326-SUM(AU13:AW13) -> -1867 | AY13: =SUM(AU13:AX13) -> -6326 | AZ13: -1365 | BA13: -1686 | BB13: -409 | BC13: =-4215-SUM(AZ13:BB13) -> -755 | BD13: =SUM(AZ13:BC13) -> -4215 | BE13: -122 | BF13: -142 | BG13: -339 | BH13: =-1334-SUM(BE13:BG13) -> -731 | BI13: =SUM(BE13:BH13) -> -1334 | BJ13: -607 | BK13: -564 | BL13: -1100 | BM13: =-3284-SUM(BJ13:BL13) -> -1013 | BN13: =SUM(BJ13:BM13) -> -3284 | BO13: -1299 | BP13: -1415 | BQ13: -1489 | BR13: =-5964-SUM(BO13:BQ13) -> -1761 | BS13: =SUM(BO13:BR13) -> -5964 | BT13: -1856 | BU13: -2127 | BV13: -2041 | BW13: =-8361-SUM(BT13:BV13) -> -2337 | BX13: =SUM(BT13:BW13) -> -8361 | BY13: -1711 | BZ13: -3457 | CA13: -3061 | CB13: =-12556-SUM(BY13:CA13) -> -4327 | CC13: =SUM(BY13:CB13) -> -12556 | CD13: -4243 | CE13: -5275 | CF13: =-('BS & FCF'!CE144/(Operating!CE26+Operating!CE27))*Operating!CF37-0.15%*Operating!CF39 -> -1324.691 | CG13: =-('BS & FCF'!CF144/(Operating!CF26+Operating!CF27))*Operating!CG37-0.15%*Operating!CG39 -> -777.64985 | CH13: =SUM(CD13:CG13) -> -11620.341 | CI13: =-('BS & FCF'!CH144/(Operating!CH26+Operating!CH27))*Operating!CI37-1%*Operating!CI39 -> -9053.7812 | CJ13: =-('BS & FCF'!CI144/(Operating!CI26+Operating!CI27))*Operating!CJ37-1%*Operating!CJ39 -> -4458.1304 | CK13: =-('BS & FCF'!CJ144/(Operating!CJ26+Operating!CJ27))*Operating!CK37-1%*Operating!CK39 -> -4287.5977 | CL13: =-('BS & FCF'!CK144/(Operating!CK26+Operating!CK27))*Operating!CL37-1%*Operating!CL39 -> -3995.3233 | CM13: =SUM(CI13:CL13) -> -21794.833 | CN13: =-('BS & FCF'!CM144/(Operating!CM26+Operating!CM27))*Operating!CN37-1%*Operating!CN39 -> -2074.3152 | CO13: =-('BS & FCF'!CN144/(Operating!CN26+Operating!CN27))*Operating!CO37-1%*Operating!CO39 -> -577.8202 | CP13: =-('BS & FCF'!CO144/(Operating!CO26+Operating!CO27))*Operating!CP37-1%*Operating!CP39 -> -3190.4684 | CQ13: =-('BS & FCF'!CP144/(Operating!CP26+Operating!CP27))*Operating!CQ37-1%*Operating!CQ39 -> -3248.0964 | CR13: =SUM(CN13:CQ13) -> -9090.7002 | CS13: =-('BS & FCF'!CR144/(Operating!CR26+Operating!CR27))*Operating!CS37-1%*Operating!CS39 -> -178.17007 | CT13: =-('BS & FCF'!CS144/(Operating!CS26+Operating!CS27))*Operating!CT37-1%*Operating!CT39 -> 1006.9738 | CU13: =-('BS & FCF'!CT144/(Operating!CT26+Operating!CT27))*Operating!CU37-1%*Operating!CU39 -> -2476.5475 | CV13: =-('BS & FCF'!CU144/(Operating!CU26+Operating!CU27))*Operating!CV37-1%*Operating!CV39 -> -2853.8118 | CW13: =SUM(CS13:CV13) -> -4501.5555 | CX13: =-('BS & FCF'!CW144/(Operating!CW26+Operating!CW27))*Operating!CX37-1%*Operating!CX39 -> 404.77316 | CY13: =-('BS & FCF'!CX144/(Operating!CX26+Operating!CX27))*Operating!CY37-1%*Operating!CY39 -> 1611.1276 | CZ13: =-('BS & FCF'!CY144/(Operating!CY26+Operating!CY27))*Operating!CZ37-1%*Operating!CZ39 -> -2320.411 | DA13: =-('BS & FCF'!CZ144/(Operating!CZ26+Operating!CZ27))*Operating!DA37-1%*Operating!DA39 -> -2807.7926 | DB13: =SUM(CX13:DA13) -> -3112.3029
A14: Service costs | F14: =SUM(B14:E14) -> 0 | K14: =SUM(G14:J14) -> 0 | P14: =SUM(L14:O14) -> 0 | U14: =SUM(Q14:T14) -> 0 | Z14: =SUM(V14:Y14) -> 0 | AE14: =SUM(AA14:AD14) -> 0 | AJ14: =SUM(AF14:AI14) -> 0 | AO14: =SUM(AK14:AN14) -> 0 | AT14: =SUM(AP14:AS14) -> 0 | AU14: -8264 | AV14: -8525 | AW14: -7775 | AX14: =-28512-SUM(AU14:AW14) -> -3948 | AY14: =SUM(AU14:AX14) -> -28512 | AZ14: -9693 | BA14: -9267 | BB14: -5606 | BC14: =-33295-SUM(AZ14:BB14) -> -8729 | BD14: =SUM(AZ14:BC14) -> -33295 | BE14: -6548 | BF14: -7639 | BG14: -9476 | BH14: =-10932-SUM(BE14:BG14) -> 12731 | BI14: =SUM(BE14:BH14) -> -10932 | BJ14: -1869 | BK14: -751 | BL14: -8780 | BM14: =-4651-SUM(BJ14:BL14) -> 6749 | BN14: =SUM(BJ14:BM14) -> -4651 | BO14: -522 | BP14: -339 | BQ14: -138 | BR14: =-1355-SUM(BO14:BQ14) -> -356 | BS14: =SUM(BO14:BR14) -> -1355 | BT14: -714 | BU14: -753 | BV14: -1633 | BW14: =-2622-SUM(BT14:BV14) -> 478 | BX14: =SUM(BT14:BW14) -> -2622 | BY14: -606 | BZ14: -1001 | CA14: -1190 | CB14: =-3848-SUM(BY14:CA14) -> -1051 | CC14: =SUM(BY14:CB14) -> -3848 | CD14: -798 | CE14: -963 | CF14: =-CF6*(1-CF15) -> -997.93025 | CG14: =-CG6*(1-CG15) -> -1014.3337 | CH14: =SUM(CD14:CG14) -> -3773.2639 | CI14: =-CI6*(1-CI15) -> -1072.8006 | CJ14: =-CJ6*(1-CJ15) -> -1220.7964 | CK14: =-CK6*(1-CK15) -> -1234.7407 | CL14: =-CL6*(1-CL15) -> -1172.9684 | CM14: =SUM(CI14:CL14) -> -4701.3061 | CN14: =-CN6*(1-CN15) -> -1232.748 | CO14: =-CO6*(1-CO15) -> -1330.0969 | CP14: =-CP6*(1-CP15) -> -1343.047 | CQ14: =-CQ6*(1-CQ15) -> -1311.513 | CR14: =SUM(CN14:CQ14) -> -5217.4049 | CS14: =-CS6*(1-CS15) -> -1357.0601 | CT14: =-CT6*(1-CT15) -> -1445.4128 | CU14: =-CU6*(1-CU15) -> -1449.1012 | CV14: =-CV6*(1-CV15) -> -1408.6729 | CW14: =SUM(CS14:CV14) -> -5660.247 | CX14: =-CX6*(1-CX15) -> -1449.8766 | CY14: =-CY6*(1-CY15) -> -1536.6741 | CZ14: =-CZ6*(1-CZ15) -> -1536.2856 | DA14: =-DA6*(1-DA15) -> -1490.6722 | DB14: =SUM(CX14:DA14) -> -6013.5084
A15: Services gross margin (%) | B15: =(1+B14/B6) -> #DIV/0! | C15: =(1+C14/C6) -> #DIV/0! | D15: =(1+D14/D6) -> #DIV/0! | E15: =(1+E14/E6) -> #DIV/0! | F15: =(1+F14/F6) -> #DIV/0! | G15: =(1+G14/G6) -> #DIV/0! | H15: =(1+H14/H6) -> #DIV/0! | I15: =(1+I14/I6) -> #DIV/0! | ... CE15: =(1+CE14/CE6) -> -0.73513514 | CF15: =CE15 -> -0.73513514 | CG15: =CF15 -> -0.73513514 | CH15: =(1+CH14/CH6) -> -0.19645014 | CI15: =CG15 -> -0.73513514 | CJ15: =CI15 -> -0.73513514 | CK15: =CJ15 -> -0.73513514 | CL15: =CK15 -> -0.73513514 | CM15: =(1+CM14/CM6) -> -0.73513514 | CN15: =CL15 -> -0.73513514 | CO15: =CN15 -> -0.73513514 | CP15: =CO15 -> -0.73513514 | CQ15: =CP15 -> -0.73513514 | CR15: =(1+CR14/CR6) -> -0.73513514 | CS15: =CQ15 -> -0.73513514 | CT15: =CS15 -> -0.73513514 | CU15: =CT15 -> -0.73513514 | CV15: =CU15 -> -0.73513514 | CW15: =(1+CW14/CW6) -> -0.73513514 | CX15: =CV15 -> -0.73513514 | CY15: =CX15 -> -0.73513514 | CZ15: =CY15 -> -0.73513514 | DA15: =CZ15 -> -0.73513514 | DB15: =(1+DB14/DB6) -> -0.73513514
A16: Gross profit | B16: =B9+B10 -> 0 | C16: =C9+C10 -> 0 | D16: =D9+D10 -> 0 | E16: =E9+E10 -> 0 | F16: =SUM(B16:E16) -> 0 | G16: =G9+G10 -> 0 | H16: =H9+H10 -> 0 | I16: =I9+I10 -> 0 | J16: =J9+J10 -> 0 | K16: =SUM(G16:J16) -> 0 | L16: =L9+L10 -> 0 | M16: =M9+M10 -> 0 | N16: =N9+N10 -> 0 | O16: =O9+O10 -> 0 | P16: =SUM(L16:O16) -> 0 | Q16: =Q9+Q10 -> 0 | R16: =R9+R10 -> 0 | S16: =S9+S10 -> 0 | T16: =T9+T10 -> 0 | U16: =SUM(Q16:T16) -> 0 | V16: =V9+V10 -> 0 | W16: =W9+W10 -> 0 | X16: =X9+X10 -> 0 | Y16: =Y9+Y10 -> 0 | Z16: =SUM(V16:Y16) -> 0 | AA16: =AA9+AA10 -> 0 | AB16: =AB9+AB10 -> 0 | AC16: =AC9+AC10 -> 0 | AD16: =AD9+AD10 -> 0 | AE16: =SUM(AA16:AD16) -> 0 | AF16: =AF9+AF10 -> 0 | AG16: =AG9+AG10 -> 0 | AH16: =AH9+AH10 -> 0 | AI16: =AI9+AI10 -> 0 | AJ16: =SUM(AF16:AI16) -> 0 | AK16: =AK9+AK10 -> 38196.587 | AL16: =AL9+AL10 -> 55174.636 | AM16: =AM9+AM10 -> 65601.052 | AN16: =AN9+AN10 -> 84871.913 | AO16: =SUM(AK16:AN16) -> 243844.19 | AP16: =AP9+AP10 -> 44538.737 | AQ16: =AQ9+AQ10 -> 72555.003 | AR16: =AR9+AR10 -> 97559.137 | AS16: =AS9+AS10 -> 100075.01 | AT16: =SUM(AP16:AS16) -> 314727.89 | AU16: =AU9+AU10 -> 55331 | AV16: =AV9+AV10 -> 100751 | AW16: =AW9+AW10 -> 80835 | AX16: =AX9+AX10 -> 118968 | AY16: =SUM(AU16:AX16) -> 355885 | AZ16: =AZ9+AZ10 -> 78140 | BA16: =BA9+BA10 -> 87067 | BB16: =BB9+BB10 -> 123356 | BC16: =BC9+BC10 -> 139827 | BD16: =SUM(AZ16:BC16) -> 428390 | BE16: =BE9+BE10 -> 120342 | BF16: =BF9+BF10 -> 162916 | BG16: =BG9+BG10 -> 174971 | BH16: =BH9+BH10 -> 186442 | BI16: =SUM(BE16:BH16) -> 644671 | BJ16: =BJ9+BJ10 -> 165909 | BK16: =BK9+BK10 -> 215497 | BL16: =BL9+BL10 -> 233743 | BM16: =BM9+BM10 -> 221743 | BN16: =SUM(BJ16:BM16) -> 836892 | BO16: =BO9+BO10 -> 223162 | BP16: =BP9+BP10 -> 274554 | BQ16: =BQ9+BQ10 -> 283903 | BR16: =BR9+BR10 -> 313734 | BS16: =SUM(BO16:BR16) -> 1095353 | BT16: =BT9+BT10 -> 316609 | BU16: =BU9+BU10 -> 382531 | BV16: =BV9+BV10 -> 409446 | BW16: =BW9+BW10 -> 404354 | BX16: =SUM(BT16:BW16) -> 1512940 | BY16: =BY9+BY10 -> 474888 | BZ16: =BZ9+BZ10 -> 532776 | CA16: =CA9+CA10 -> 566227 | CB16: =CB9+CB10 -> 572696 | CC16: =SUM(BY16:CB16) -> 2146587 | CD16: =CD9+CD10 -> 629656 | CE16: =CE9+CE10 -> 668362 | CF16: =CF9+CF10 -> 698159.09 | CG16: =CG9+CG10 -> 707578.88 | CH16: =SUM(CD16:CG16) -> 2703756 | CI16: =CI9+CI10 -> 737591.18 | CJ16: =CJ9+CJ10 -> 850073.46 | CK16: =CK9+CK10 -> 868799.38 | CL16: =CL9+CL10 -> 829640.22 | CM16: =SUM(CI16:CL16) -> 3286104.2 | CN16: =CN9+CN10 -> 844141.63 | CO16: =CO9+CO10 -> 908033.8 | CP16: =CP9+CP10 -> 912197.76 | CQ16: =CQ9+CQ10 -> 889571.92 | CR16: =SUM(CN16:CQ16) -> 3553945.1 | CS16: =CS9+CS10 -> 910605.67 | CT16: =CT9+CT10 -> 966220.75 | CU16: =CU9+CU10 -> 962914.87 | CV16: =CV9+CV10 -> 934417.73 | CW16: =SUM(CS16:CV16) -> 3774159 | CX16: =CX9+CX10 -> 962117.76 | CY16: =CY9+CY10 -> 1017274.4 | CZ16: =CZ9+CZ10 -> 1011380.5 | DA16: =DA9+DA10 -> 979909.45 | DB16: =SUM(CX16:DA16) -> 3970682.1
A17: Operating expenses | B17: =B18+B21+B23+B30+B34 -> 0 | C17: =C18+C21+C23+C30+C34 -> 0 | D17: =D18+D21+D23+D30+D34 -> 0 | E17: =E18+E21+E23+E30+E34 -> 0 | F17: =SUM(B17:E17) -> 0 | G17: =G18+G21+G23+G30+G34 -> 0 | H17: =H18+H21+H23+H30+H34 -> 0 | I17: =I18+I21+I23+I30+I34 -> 0 | J17: =J18+J21+J23+J30+J34 -> 0 | K17: =SUM(G17:J17) -> 0 | L17: =L18+L21+L23+L30+L34 -> 0 | M17: =M18+M21+M23+M30+M34 -> 0 | N17: =N18+N21+N23+N30+N34 -> 0 | O17: =O18+O21+O23+O30+O34 -> 0 | P17: =SUM(L17:O17) -> 0 | Q17: =Q18+Q21+Q23+Q30+Q34 -> 0 | R17: =R18+R21+R23+R30+R34 -> 0 | S17: =S18+S21+S23+S30+S34 -> 0 | T17: =T18+T21+T23+T30+T34 -> 0 | U17: =SUM(Q17:T17) -> 0 | V17: =V18+V21+V23+V30+V34 -> 0 | W17: =W18+W21+W23+W30+W34 -> 0 | X17: =X18+X21+X23+X30+X34 -> 0 | Y17: =Y18+Y21+Y23+Y30+Y34 -> 0 | Z17: =SUM(V17:Y17) -> 0 | AA17: =AA18+AA21+AA23+AA30+AA34 -> 0 | AB17: =AB18+AB21+AB23+AB30+AB34 -> 0 | AC17: =AC18+AC21+AC23+AC30+AC34 -> 0 | AD17: =AD18+AD21+AD23+AD30+AD34 -> 0 | AE17: =SUM(AA17:AD17) -> 0 | AF17: =AF18+AF21+AF23+AF30+AF34 -> 0 | AG17: =AG18+AG21+AG23+AG30+AG34 -> 0 | AH17: =AH18+AH21+AH23+AH30+AH34 -> 0 | AI17: =AI18+AI21+AI23+AI30+AI34 -> 0 | AJ17: =SUM(AF17:AI17) -> 0 | AK17: =AK18+AK21+AK23+AK30+AK34 -> -21731.519 | AL17: =AL18+AL21+AL23+AL30+AL34 -> -35087.854 | AM17: =AM18+AM21+AM23+AM30+AM34 -> -15726.313 | AN17: =AN18+AN21+AN23+AN30+AN34 -> -28703.093 | AO17: =SUM(AK17:AN17) -> -101248.78 | AP17: =AP18+AP21+AP23+AP30+AP34 -> -20941.817 | AQ17: =AQ18+AQ21+AQ23+AQ30+AQ34 -> -27935.059 | AR17: =AR18+AR21+AR23+AR30+AR34 -> -38728.351 | AS17: =AS18+AS21+AS23+AS30+AS34 -> -32661.014 | AT17: =SUM(AP17:AS17) -> -120266.24 | AU17: =AU18+AU21+AU23+AU30+AU34 -> -27074 | AV17: =AV18+AV21+AV23+AV30+AV34 -> -21483 | AW17: =AW18+AW21+AW23+AW30+AW34 -> -35652 | AX17: =AX18+AX21+AX23+AX30+AX34 -> -45581 | AY17: =SUM(AU17:AX17) -> -129790 | AZ17: =AZ18+AZ21+AZ23+AZ30+AZ34 -> -54985 | BA17: =BA18+BA21+BA23+BA30+BA34 -> -41183 | BB17: =BB18+BB21+BB23+BB30+BB34 -> -57238 | BC17: =BC18+BC21+BC23+BC30+BC34 -> -58772 | BD17: =SUM(AZ17:BC17) -> -212178 | BE17: =BE18+BE21+BE23+BE30+BE34 -> -61395 | BF17: =BF18+BF21+BF23+BF30+BF34 -> -77551 | BG17: =BG18+BG21+BG23+BG30+BG34 -> -89995 | BH17: =BH18+BH21+BH23+BH30+BH34 -> -64089 | BI17: =SUM(BE17:BH17) -> -293030 | BJ17: =BJ18+BJ21+BJ23+BJ30+BJ34 -> -90921 | BK17: =BK18+BK21+BK23+BK30+BK34 -> -108110 | BL17: =BL18+BL21+BL23+BL30+BL34 -> -123338 | BM17: =BM18+BM21+BM23+BM30+BM34 -> -109519 | BN17: =SUM(BJ17:BM17) -> -431888 | BO17: =BO18+BO21+BO23+BO30+BO34 -> -113770 | BP17: =BP18+BP21+BP23+BP30+BP34 -> -132289 | BQ17: =BQ18+BQ21+BQ23+BQ30+BQ34 -> -151884 | BR17: =BR18+BR21+BR23+BR30+BR34 -> -129381 | BS17: =SUM(BO17:BR17) -> -527324 | BT17: =BT18+BT21+BT23+BT30+BT34 -> -142353 | BU17: =BU18+BU21+BU23+BU30+BU34 -> -186341 | BV17: =BV18+BV21+BV23+BV30+BV34 -> -205856 | BW17: =BW18+BW21+BW23+BW30+BW34 -> -189794 | BX17: =SUM(BT17:BW17) -> -724344 | BY17: =BY18+BY21+BY23+BY30+BY34 -> -210221 | BZ17: =BZ18+BZ21+BZ23+BZ30+BZ34 -> -234180 | CA17: =CA18+CA21+CA23+CA30+CA34 -> -246254 | CB17: =CB18+CB21+CB23+CB30+CB34 -> -235686 | CC17: =SUM(BY17:CB17) -> -926341 | CD17: =CD18+CD21+CD23+CD30+CD34 -> -237220 | CE17: =CE18+CE21+CE23+CE30+CE34 -> -312057 | CF17: =CF18+CF21+CF23+CF30+CF34 -> -306500.85 | CG17: =CG18+CG21+CG23+CG30+CG34 -> -283458.39 | CH17: =SUM(CD17:CG17) -> -1139236.2 | CI17: =CI18+CI21+CI23+CI30+CI34 -> -295845.95 | CJ17: =CJ18+CJ21+CJ23+CJ30+CJ34 -> -368818.99 | CK17: =CK18+CK21+CK23+CK30+CK34 -> -350803.1 | CL17: =CL18+CL21+CL23+CL30+CL34 -> -324855.76 | CM17: =SUM(CI17:CL17) -> -1340323.8 | CN17: =CN18+CN21+CN23+CN30+CN34 -> -299604.01 | CO17: =CO18+CO21+CO23+CO30+CO34 -> -370651.68 | CP17: =CP18+CP21+CP23+CP30+CP34 -> -352377.65 | CQ17: =CQ18+CQ21+CQ23+CQ30+CQ34 -> -327844.07 | CR17: =SUM(CN17:CQ17) -> -1350477.4 | CS17: =CS18+CS21+CS23+CS30+CS34 -> -321028.56 | CT17: =CT18+CT21+CT23+CT30+CT34 -> -393303.72 | CU17: =CU18+CU21+CU23+CU30+CU34 -> -372906.78 | CV17: =CV18+CV21+CV23+CV30+CV34 -> -345782.47 | CW17: =SUM(CS17:CV17) -> -1433021.5 | CX17: =CX18+CX21+CX23+CX30+CX34 -> -336902.79 | CY17: =CY18+CY21+CY23+CY30+CY34 -> -411263.24 | CZ17: =CZ18+CZ21+CZ23+CZ30+CZ34 -> -389655.31 | DA17: =DA18+DA21+DA23+DA30+DA34 -> -361386.07 | DB17: =SUM(CX17:DA17) -> -1499207.4
A18: Selling expenses | F18: =SUM(B18:E18) -> 0 | K18: =SUM(G18:J18) -> 0 | P18: =SUM(L18:O18) -> 0 | U18: =SUM(Q18:T18) -> 0 | Z18: =SUM(V18:Y18) -> 0 | AE18: =SUM(AA18:AD18) -> 0 | AJ18: =SUM(AF18:AI18) -> 0 | AK18: -19606.696 | AL18: -27523.964 | AM18: -23200.763 | AN18: -33013.443 | AO18: =SUM(AK18:AN18) -> -103344.87 | AP18: -16280.821 | AQ18: -22900 | AR18: -21281.703 | AS18: -25372.387 | AT18: =SUM(AP18:AS18) -> -85834.911 | AU18: -14144 | AV18: -20312 | AW18: -26575 | AX18: =-100668-SUM(AU18:AW18) -> -39637 | AY18: =SUM(AU18:AX18) -> -100668 | AZ18: -22046 | BA18: -26343 | BB18: -27428 | BC18: =-102804-SUM(AZ18:BB18) -> -26987 | BD18: =SUM(AZ18:BC18) -> -102804 | BE18: -30360 | BF18: -38953 | BG18: -47954 | BH18: =-164226-SUM(BE18:BG18) -> -46959 | BI18: =SUM(BE18:BH18) -> -164226 | BJ18: -44417 | BK18: -53835 | BL18: -59384 | BM18: =-212188-SUM(BJ18:BL18) -> -54552 | BN18: =SUM(BJ18:BM18) -> -212188 | BO18: -62031 | BP18: -66728 | BQ18: -80995 | BR18: =-285230-SUM(BO18:BQ18) -> -75476 | BS18: =SUM(BO18:BR18) -> -285230 | BT18: -76092 | BU18: -97945 | BV18: -113852 | BW18: =-391872-SUM(BT18:BV18) -> -103983 | BX18: =SUM(BT18:BW18) -> -391872 | BY18: -106236 | BZ18: -124747 | CA18: -134823 | CB18: =-494891-SUM(BY18:CA18) -> -129085 | CC18: =SUM(BY18:CB18) -> -494891 | CD18: -119070 | CE18: -166790 | CF18: =-CF20*(Operating!CF15+Operating!CF17) -> -163627.19 | CG18: =-CG20*(Operating!CG15+Operating!CG17) -> -154137.4 | CH18: =SUM(CD18:CG18) -> -603624.6 | CI18: =-CI20*(Operating!CI15+Operating!CI17) -> -160924.93 | CJ18: =-CJ20*(Operating!CJ15+Operating!CJ17) -> -210691.65 | CK18: =-CK20*(Operating!CK15+Operating!CK17) -> -187004.39 | CL18: =-CL20*(Operating!CL15+Operating!CL17) -> -176952.22 | CM18: =SUM(CI18:CL18) -> -735573.2 | CN18: =-CN20*(Operating!CN15+Operating!CN17) -> -168185.39 | CO18: =-CO20*(Operating!CO15+Operating!CO17) -> -218522.09 | CP18: =-CP20*(Operating!CP15+Operating!CP17) -> -193750.85 | CQ18: =-CQ20*(Operating!CQ15+Operating!CQ17) -> -184180.09 | CR18: =SUM(CN18:CQ18) -> -764638.41 | CS18: =-CS20*(Operating!CS15+Operating!CS17) -> -179900.41 | CT18: =-CT20*(Operating!CT15+Operating!CT17) -> -231245.68 | CU18: =-CU20*(Operating!CU15+Operating!CU17) -> -203998.04 | CV18: =-CV20*(Operating!CV15+Operating!CV17) -> -193099.5 | CW18: =SUM(CS18:CV18) -> -808243.63 | CX18: =-CX20*(Operating!CX15+Operating!CX17) -> -187825.12 | CY18: =-CY20*(Operating!CY15+Operating!CY17) -> -241040.02 | CZ18: =-CZ20*(Operating!CZ15+Operating!CZ17) -> -212474.19 | DA18: =-DA20*(Operating!DA15+Operating!DA17) -> -200991.77 | DB18: =SUM(CX18:DA18) -> -842331.1
A19: % of net revenues | B19: =-B18/B9 -> #DIV/0! | C19: =-C18/C9 -> #DIV/0! | D19: =-D18/D9 -> #DIV/0! | E19: =-E18/E9 -> #DIV/0! | F19: =-F18/F9 -> #DIV/0! | G19: =-G18/G9 -> #DIV/0! | H19: =-H18/H9 -> #DIV/0! | I19: =-I18/I9 -> #DIV/0! | ... DB19: =-DB18/DB9 -> 0.079823526
A20: % of net sales | B20: =-B18/(Operating!B15+Operating!B17) -> #DIV/0! | C20: =-C18/(Operating!C15+Operating!C17) -> #DIV/0! | D20: =-D18/(Operating!D15+Operating!D17) -> #DIV/0! | E20: =-E18/(Operating!E15+Operating!E17) -> #DIV/0! | F20: =-F18/(Operating!F15+Operating!F17) -> #DIV/0! | G20: =-G18/(Operating!G15+Operating!G17) -> #DIV/0! | H20: =-H18/(Operating!H15+Operating!H17) -> #DIV/0! | I20: =-I18/(Operating!I15+Operating!I17) -> #DIV/0! | ... CE20: =-CE18/(Operating!CE15+Operating!CE17) -> 0.075242478 | CF20: 0.0675 | CG20: =CF20 -> 0.0675 | CH20: =-CH18/(Operating!CH15+Operating!CH17) -> 0.063820081 | CI20: 0.055 | CJ20: 0.07 | CK20: =CJ20 -> 0.07 | CL20: =CK20 -> 0.07 | CM20: =-CM18/(Operating!CM15+Operating!CM17) -> 0.066058558 | CN20: 0.055 | CO20: 0.07 | CP20: =CK20 -> 0.07 | CQ20: =CL20 -> 0.07 | CR20: =-CR18/(Operating!CR15+Operating!CR17) -> 0.066038515 | CS20: =CN20 -> 0.055 | CT20: =CO20 -> 0.07 | CU20: =CP20 -> 0.07 | CV20: =CQ20 -> 0.07 | CW20: =-CW18/(Operating!CW15+Operating!CW17) -> 0.065993896 | CX20: =CS20 -> 0.055 | CY20: =CT20 -> 0.07 | CZ20: =CU20 -> 0.07 | DA20: =CV20 -> 0.07 | DB20: =-DB18/(Operating!DB15+Operating!DB17) -> 0.065987099
A21: G&A expenses | F21: =SUM(B21:E21) -> 0 | K21: =SUM(G21:J21) -> 0 | P21: =SUM(L21:O21) -> 0 | U21: =SUM(Q21:T21) -> 0 | Z21: =SUM(V21:Y21) -> 0 | AE21: =SUM(AA21:AD21) -> 0 | AJ21: =SUM(AF21:AI21) -> 0 | AK21: -7678.198 | AL21: -11511.16 | AM21: -8775.254 | AN21: -15305.771 | AO21: =SUM(AK21:AN21) -> -43270.383 | AP21: -10376.184 | AQ21: -10511.935 | AR21: -15626.307 | AS21: -9316.124 | AT21: =SUM(AP21:AS21) -> -45830.55 | AU21: =-26240-AU32 -> -24386 | AV21: =-27173-AV32 -> -26994 | AW21: =-24843-AW32 -> -24444 | AX21: =-96843-SUM(AU21:AW21)-SUM(AU32:AX32) -> -19864 | AY21: =SUM(AU21:AX21) -> -95688 | AZ21: =-28376-AZ32 -> -25451 | BA21: =-14508-BA32 -> -14201 | BB21: =-25631-BB32 -> -25266 | BC21: =-96892-SUM(AZ21:BB21)-SUM(AZ32:BC32) -> -30415 | BD21: =SUM(AZ21:BC21) -> -95333 | BE21: =-20615-BE32 -> -20280 | BF21: =-24043-BF32 -> -23688 | BG21: =-31117-BG32 -> -30752 | BH21: =-102464-SUM(BE21:BG21)-SUM(BE32:BH32) -> -26306 | BI21: =SUM(BE21:BH21) -> -101026 | BJ21: =-22810-BJ32 -> -22356 | BK21: =-34143-BK32 -> -33684 | BL21: =-49409-BL32 -> -48993 | BM21: =-136568-SUM(BJ21:BL21)-SUM(BJ32:BM32) -> -29683 | BN21: =SUM(BJ21:BM21) -> -134716 | BO21: =-33375-BO32 -> -32599 | BP21: =-42088-BP32 -> -41367 | BQ21: =-54245-BQ32 -> -53549 | BR21: =-165783-SUM(BO21:BQ21)-SUM(BO32:BR32) -> -35293 | BS21: =SUM(BO21:BR21) -> -162808 | BT21: =-41298-BT32 -> -40769 | BU21: =-62203-BU32 -> -61475 | BV21: =-68034-BV32 -> -67309 | BW21: =-224429-SUM(BT21:BV21)-SUM(BT32:BW32) -> -52203 | BX21: =SUM(BT21:BW21) -> -221756 | BY21: =-50355-BY32 -> -50151 | BZ21: =-64402-BZ32 -> -64176 | CA21: =-66007-CA32 -> -65788 | CB21: =-239339-SUM(BY21:CA21)-SUM(BY32:CB32) -> -58359 | CC21: =SUM(BY21:CB21) -> -238474 | CD21: =-64932-CD32 -> -64720 | CE21: =-78364-CE32 -> -78166 | CF21: =CA21*(1+Macro!CF11)*1.15 -> -79327.125 | CG21: =CB21*(1+Macro!CG11)*1.1 -> -67631.616 | CH21: =SUM(CD21:CG21) -> -289844.74 | CI21: =CD21*(1+Macro!CI11)*1.1 -> -74706.251 | CJ21: =CE21*(1+Macro!CJ11)*1.1 -> -89760.345 | CK21: =CF21*(1+Macro!CK11)*1.1 -> -91001.34 | CL21: =CG21*(1+Macro!CL11)*1.1 -> -77777.23 | CM21: =SUM(CI21:CL21) -> -333245.17 | CN21: =CI21*(1+Macro!CN11) -> -78102.864 | CO21: =CJ21*(1+Macro!CO11) -> -93841.412 | CP21: =CK21*(1+Macro!CP11) -> -95138.831 | CQ21: =CL21*(1+Macro!CQ11) -> -81313.47 | CR21: =SUM(CN21:CQ21) -> -348396.58 | CS21: =CN21*(1+Macro!CS11) -> -81226.979 | CT21: =CO21*(1+Macro!CT11) -> -97595.068 | CU21: =CP21*(1+Macro!CU11) -> -98944.384 | CV21: =CQ21*(1+Macro!CV11) -> -84566.009 | CW21: =SUM(CS21:CV21) -> -362332.44 | CX21: =CS21*(1+Macro!CX11) -> -84435.03 | CY21: =CT21*(1+Macro!CY11) -> -101449.58 | CZ21: =CU21*(1+Macro!CZ11) -> -102852.18 | DA21: =CV21*(1+Macro!DA11) -> -87905.934 | DB21: =SUM(CX21:DA21) -> -376642.72
A22: as % of net revenues | B22: =-B21/B9 -> #DIV/0! | C22: =-C21/C9 -> #DIV/0! | D22: =-D21/D9 -> #DIV/0! | E22: =-E21/E9 -> #DIV/0! | F22: =-F21/F9 -> #DIV/0! | G22: =-G21/G9 -> #DIV/0! | H22: =-H21/H9 -> #DIV/0! | I22: =-I21/I9 -> #DIV/0! | ... DB22: =-DB21/DB9 -> 0.035692556
A23: Net financial results | B23: =B24+B26+B28 -> 0 | C23: =C24+C26+C28 -> 0 | D23: =D24+D26+D28 -> 0 | E23: =E24+E26+E28 -> 0 | F23: =SUM(B23:E23) -> 0 | G23: =G24+G26+G28 -> 0 | H23: =H24+H26+H28 -> 0 | I23: =I24+I26+I28 -> 0 | J23: =J24+J26+J28 -> 0 | K23: =SUM(G23:J23) -> 0 | L23: =L24+L26+L28 -> 0 | M23: =M24+M26+M28 -> 0 | N23: =N24+N26+N28 -> 0 | O23: =O24+O26+O28 -> 0 | P23: =SUM(L23:O23) -> 0 | Q23: =Q24+Q26+Q28 -> 0 | R23: =R24+R26+R28 -> 0 | S23: =S24+S26+S28 -> 0 | T23: =T24+T26+T28 -> 0 | U23: =SUM(Q23:T23) -> 0 | V23: =V24+V26+V28 -> 0 | W23: =W24+W26+W28 -> 0 | X23: =X24+X26+X28 -> 0 | Y23: =Y24+Y26+Y28 -> 0 | Z23: =SUM(V23:Y23) -> 0 | AA23: =AA24+AA26+AA28 -> 0 | AB23: =AB24+AB26+AB28 -> 0 | AC23: =AC24+AC26+AC28 -> 0 | AD23: =AD24+AD26+AD28 -> 0 | AE23: =SUM(AA23:AD23) -> 0 | AF23: =AF24+AF26+AF28 -> 0 | AG23: =AG24+AG26+AG28 -> 0 | AH23: =AH24+AH26+AH28 -> 0 | AI23: =AI24+AI26+AI28 -> 0 | AJ23: =SUM(AF23:AI23) -> 0 | AK23: =AK24+AK26+AK28 -> 3661.195 | AL23: =AL24+AL26+AL28 -> 3156.298 | AM23: =AM24+AM26+AM28 -> 5088.347 | AN23: =AN24+AN26+AN28 -> 3151.127 | AO23: =SUM(AK23:AN23) -> 15056.967 | AP23: =AP24+AP26+AP28 -> 2109.936 | AQ23: =AQ24+AQ26+AQ28 -> 1101.435 | AR23: =AR24+AR26+AR28 -> -340.327 | AS23: =AS24+AS26+AS28 -> -408.829 | AT23: =SUM(AP23:AS23) -> 2462.215 | AU23: =AU24+AU26+AU28 -> -453 | AV23: =AV24+AV26+AV28 -> 262 | AW23: =AW24+AW26+AW28 -> -4443 | AX23: =AX24+AX26+AX28 -> -6780 | AY23: =SUM(AU23:AX23) -> -11414 | AZ23: =AZ24+AZ26+AZ28 -> -2175 | BA23: =BA24+BA26+BA28 -> -2892 | BB23: =BB24+BB26+BB28 -> -1211 | BC23: =BC24+BC26+BC28 -> -2532 | BD23: =SUM(AZ23:BC23) -> -8810 | BE23: =BE24+BE26+BE28 -> -5034 | BF23: =BF24+BF26+BF28 -> -5376 | BG23: =BG24+BG26+BG28 -> -1071 | BH23: =BH24+BH26+BH28 -> -13246 | BI23: =SUM(BE23:BH23) -> -24727 | BJ23: =BJ24+BJ26+BJ28 -> -4085 | BK23: =BK24+BK26+BK28 -> -4609 | BL23: =BL24+BL26+BL28 -> -4065 | BM23: =BM24+BM26+BM28 -> -11678 | BN23: =SUM(BJ23:BM23) -> -24437 | BO23: =BO24+BO26+BO28 -> -5444 | BP23: =BP24+BP26+BP28 -> -5601 | BQ23: =BQ24+BQ26+BQ28 -> -3546 | BR23: =BR24+BR26+BR28 -> 680 | BS23: =SUM(BO23:BR23) -> -13911 | BT23: =BT24+BT26+BT28 -> -4917 | BU23: =BU24+BU26+BU28 -> -5749 | BV23: =BV24+BV26+BV28 -> -7613 | BW23: =BW24+BW26+BW28 -> -12805 | BX23: =SUM(BT23:BW23) -> -31084 | BY23: =BY24+BY26+BY28 -> -14580 | BZ23: =BZ24+BZ26+BZ28 -> -15628 | CA23: =CA24+CA26+CA28 -> -8694 | CB23: =CB24+CB26+CB28 -> -8912 | CC23: =SUM(BY23:CB23) -> -47814 | CD23: =CD24+CD26+CD28 -> -10709 | CE23: =CE24+CE26+CE28 -> -22120 | CF23: =CF24+CF26+CF28 -> -6498.0808 | CG23: =CG24+CG26+CG28 -> -3840.7339 | CH23: =SUM(CD23:CG23) -> -43167.815 | CI23: =CI24+CI26+CI28 -> 459.79597 | CJ23: =CJ24+CJ26+CJ28 -> -441.87402 | CK23: =CK24+CK26+CK28 -> -4204.8966 | CL23: =CL24+CL26+CL28 -> -4592.2103 | CM23: =SUM(CI23:CL23) -> -8779.185 | CN23: =CN24+CN26+CN28 -> 6678.4524 | CO23: =CO24+CO26+CO28 -> 6480.1804 | CP23: =CP24+CP26+CP28 -> 1915.7566 | CQ23: =CQ24+CQ26+CQ28 -> 1487.5283 | CR23: =SUM(CN23:CQ23) -> 16561.918 | CS23: =CS24+CS26+CS28 -> 6140.5866 | CT23: =CT24+CT26+CT28 -> 5910.9847 | CU23: =CU24+CU26+CU28 -> 590.91023 | CV23: =CV24+CV26+CV28 -> 441.03986 | CW23: =SUM(CS23:CV23) -> 13083.521 | CX23: =CX24+CX26+CX28 -> 5908.8803 | CY23: =CY24+CY26+CY28 -> 6042.1781 | CZ23: =CZ24+CZ26+CZ28 -> 480.75567 | DA23: =DA24+DA26+DA28 -> 84.544732 | DB23: =SUM(CX23:DA23) -> 12516.359
A24: Financial income | F24: =SUM(B24:E24) -> 0 | K24: =SUM(G24:J24) -> 0 | P24: =SUM(L24:O24) -> 0 | U24: =SUM(Q24:T24) -> 0 | Z24: =SUM(V24:Y24) -> 0 | AE24: =SUM(AA24:AD24) -> 0 | AJ24: =SUM(AF24:AI24) -> 0 | AK24: 4427.36 | AL24: 4201.649 | AM24: 6442 | AN24: 5265.735 | AO24: =SUM(AK24:AN24) -> 20336.744 | AP24: 2670.841 | AQ24: 2209.223 | AR24: 3401.065 | AS24: 2850.52 | AT24: =SUM(AP24:AS24) -> 11131.649 | AU24: 3012 | AV24: 5477 | AW24: 3325 | AX24: =15275-SUM(AU24:AW24) -> 3461 | AY24: =SUM(AU24:AX24) -> 15275 | AZ24: 2784 | BA24: 2827 | BB24: 5428 | BC24: =14673-SUM(AZ24:BB24) -> 3634 | BD24: =SUM(AZ24:BC24) -> 14673 | BE24: 2222 | BF24: 3924 | BG24: 10356 | BH24: =24987-SUM(BE24:BG24) -> 8485 | BI24: =SUM(BE24:BH24) -> 24987 | BJ24: 12977 | BK24: 17605 | BL24: 18795 | BM24: =64031-SUM(BJ24:BL24) -> 14654 | BN24: =SUM(BJ24:BM24) -> 64031 | BO24: 20228 | BP24: 20425 | BQ24: 19668 | BR24: =86216-SUM(BO24:BQ24) -> 25895 | BS24: =SUM(BO24:BR24) -> 86216 | BT24: 19889 | BU24: 25350 | BV24: 32060 | BW24: =106081-SUM(BT24:BV24) -> 28782 | BX24: =SUM(BT24:BW24) -> 106081 | BY24: 36752 | BZ24: 35218 | CA24: 47368 | CB24: =170022-SUM(BY24:CA24) -> 50684 | CC24: =SUM(BY24:CB24) -> 170022 | CD24: 49093 | CE24: 48168 | CF24: =CF25*(AVERAGE('BS & FCF'!CE6:CF6)+AVERAGE('BS & FCF'!CE7:CF7))/4 -> 45176.935 | CG24: =CG25*(AVERAGE('BS & FCF'!CF6:CG6)+AVERAGE('BS & FCF'!CF7:CG7))/4 -> 48044.102 | CH24: =SUM(CD24:CG24) -> 190482.04 | CI24: =CI25*(AVERAGE('BS & FCF'!CH6:CI6)+AVERAGE('BS & FCF'!CH7:CI7))/4 -> 54954.745 | CJ24: =CJ25*(AVERAGE('BS & FCF'!CI6:CJ6)+AVERAGE('BS & FCF'!CI7:CJ7))/4 -> 55568.921 | CK24: =CK25*(AVERAGE('BS & FCF'!CJ6:CK6)+AVERAGE('BS & FCF'!CJ7:CK7))/4 -> 51347.011 | CL24: =CL25*(AVERAGE('BS & FCF'!CK6:CL6)+AVERAGE('BS & FCF'!CK7:CL7))/4 -> 51314.596 | CM24: =SUM(CI24:CL24) -> 213185.27 | CN24: =CN25*(AVERAGE('BS & FCF'!CM6:CN6)+AVERAGE('BS & FCF'!CM7:CN7))/4 -> 57668.519 | CO24: =CO25*(AVERAGE('BS & FCF'!CN6:CO6)+AVERAGE('BS & FCF'!CN7:CO7))/4 -> 59914.559 | CP24: =CP25*(AVERAGE('BS & FCF'!CO6:CP6)+AVERAGE('BS & FCF'!CO7:CP7))/4 -> 56092.829 | CQ24: =CQ25*(AVERAGE('BS & FCF'!CP6:CQ6)+AVERAGE('BS & FCF'!CP7:CQ7))/4 -> 55927.822 | CR24: =SUM(CN24:CQ24) -> 229603.73 | CS24: =CS25*(AVERAGE('BS & FCF'!CR6:CS6)+AVERAGE('BS & FCF'!CR7:CS7))/4 -> 62314.782 | CT24: =CT25*(AVERAGE('BS & FCF'!CS6:CT6)+AVERAGE('BS & FCF'!CS7:CT7))/4 -> 64260.516 | CU24: =CU25*(AVERAGE('BS & FCF'!CT6:CU6)+AVERAGE('BS & FCF'!CT7:CU7))/4 -> 59568.004 | CV24: =CV25*(AVERAGE('BS & FCF'!CU6:CV6)+AVERAGE('BS & FCF'!CU7:CV7))/4 -> 59385.408 | CW24: =SUM(CS24:CV24) -> 245528.71 | CX24: =CX25*(AVERAGE('BS & FCF'!CW6:CX6)+AVERAGE('BS & FCF'!CW7:CX7))/4 -> 66251.237 | CY24: =CY25*(AVERAGE('BS & FCF'!CX6:CY6)+AVERAGE('BS & FCF'!CX7:CY7))/4 -> 68337.271 | CZ24: =CZ25*(AVERAGE('BS & FCF'!CY6:CZ6)+AVERAGE('BS & FCF'!CY7:CZ7))/4 -> 63187.881 | DA24: =DA25*(AVERAGE('BS & FCF'!CZ6:DA6)+AVERAGE('BS & FCF'!CZ7:DA7))/4 -> 62565.668 | DB24: =SUM(CX24:DA24) -> 260342.06
