Workbook

Sheet Cover
B6: =Valuation!B5&" -"&" "&Valuation!B18&" Rating - TP R$"&Valuation!B16&"/sh" -> CYRE3 - Outperform Rating - TP R$35/sh
B8: Brazil - Homebuilders
B10: Itaú BBA - Real Estate
B11: Elvis Credendio
B12: Cel.: +55 11 3073-3032
B14: Daniel Gasparete
B15: Cel.: +55 11 3073-3906
B17: Mariangela Castro
B18: Cel.: +55 11 3073-3102
B20: Juliana Veiga
B21: Cel.: +55 11 3073-2025

Sheet Macro
A2: =Valuation!$A$2 -> CYRE3 | TP R$35/sh
A3: Macro variables | B3: =B5&RIGHT(B4,2)&B6 -> 1Q10 | C3: =C5&RIGHT(C4,2)&C6 -> 2Q10 | D3: =D5&RIGHT(D4,2)&D6 -> 3Q10 | E3: =E5&RIGHT(E4,2)&E6 -> 4Q10 | F3: =F4&F6 -> 2010 | G3: =G5&RIGHT(G4,2)&G6 -> 1Q11 | H3: =H5&RIGHT(H4,2)&H6 -> 2Q11 | I3: =I5&RIGHT(I4,2)&I6 -> 3Q11 | J3: =J5&RIGHT(J4,2)&J6 -> 4Q11 | K3: =K4&K6 -> 2011 | L3: =L5&RIGHT(L4,2)&L6 -> 1Q12 | M3: =M5&RIGHT(M4,2)&M6 -> 2Q12 | N3: =N5&RIGHT(N4,2)&N6 -> 3Q12 | O3: =O5&RIGHT(O4,2)&O6 -> 4Q12 | P3: =P4&P6 -> 2012 | Q3: =Q5&RIGHT(Q4,2)&Q6 -> 1Q13 | R3: =R5&RIGHT(R4,2)&R6 -> 2Q13 | S3: =S5&RIGHT(S4,2)&S6 -> 3Q13 | T3: =T5&RIGHT(T4,2)&T6 -> 4Q13 | U3: =U4&U6 -> 2013 | V3: =V5&RIGHT(V4,2)&V6 -> 1Q14 | W3: =W5&RIGHT(W4,2)&W6 -> 2Q14 | X3: =X5&RIGHT(X4,2)&X6 -> 3Q14 | Y3: =Y5&RIGHT(Y4,2)&Y6 -> 4Q14 | Z3: =Z4&Z6 -> 2014 | AA3: =AA5&RIGHT(AA4,2)&AA6 -> 1Q15 | AB3: =AB5&RIGHT(AB4,2)&AB6 -> 2Q15 | AC3: =AC5&RIGHT(AC4,2)&AC6 -> 3Q15 | AD3: =AD5&RIGHT(AD4,2)&AD6 -> 4Q15 | AE3: =AE4&AE6 -> 2015 | AF3: =AF5&RIGHT(AF4,2)&AF6 -> 1Q16 | AG3: =AG5&RIGHT(AG4,2)&AG6 -> 2Q16 | AH3: =AH5&RIGHT(AH4,2)&AH6 -> 3Q16 | AI3: =AI5&RIGHT(AI4,2)&AI6 -> 4Q16 | AJ3: =AJ4&AJ6 -> 2016 | AK3: =AK5&RIGHT(AK4,2)&AK6 -> 1Q17 | AL3: =AL5&RIGHT(AL4,2)&AL6 -> 2Q17 | AM3: =AM5&RIGHT(AM4,2)&AM6 -> 3Q17 | AN3: =AN5&RIGHT(AN4,2)&AN6 -> 4Q17 | AO3: =AO4&AO6 -> 2017 | AP3: =AP5&RIGHT(AP4,2)&AP6 -> 1Q18 | AQ3: =AQ5&RIGHT(AQ4,2)&AQ6 -> 2Q18 | AR3: =AR5&RIGHT(AR4,2)&AR6 -> 3Q18 | AS3: =AS5&RIGHT(AS4,2)&AS6 -> 4Q18 | AT3: =AT4&AT6 -> 2018 | AU3: =AU5&RIGHT(AU4,2)&AU6 -> 1Q19 | AV3: =AV5&RIGHT(AV4,2)&AV6 -> 2Q19 | AW3: =AW5&RIGHT(AW4,2)&AW6 -> 3Q19 | AX3: =AX5&RIGHT(AX4,2)&AX6 -> 4Q19 | AY3: =AY4&AY6 -> 2019 | AZ3: =AZ5&RIGHT(AZ4,2)&AZ6 -> 1Q20 | BA3: =BA5&RIGHT(BA4,2)&BA6 -> 2Q20 | BB3: =BB5&RIGHT(BB4,2)&BB6 -> 3Q20 | BC3: =BC5&RIGHT(BC4,2)&BC6 -> 4Q20 | BD3: =BD4&BD6 -> 2020 | BE3: =BE5&RIGHT(BE4,2)&BE6 -> 1Q21 | BF3: =BF5&RIGHT(BF4,2)&BF6 -> 2Q21 | BG3: =BG5&RIGHT(BG4,2)&BG6 -> 3Q21 | BH3: =BH5&RIGHT(BH4,2)&BH6 -> 4Q21 | BI3: =BI4&BI6 -> 2021 | BJ3: =BJ5&RIGHT(BJ4,2)&BJ6 -> 1Q22 | BK3: =BK5&RIGHT(BK4,2)&BK6 -> 2Q22 | BL3: =BL5&RIGHT(BL4,2)&BL6 -> 3Q22 | BM3: =BM5&RIGHT(BM4,2)&BM6 -> 4Q22 | BN3: =BN4&BN6 -> 2022 | BO3: =BO5&RIGHT(BO4,2)&BO6 -> 1Q23 | BP3: =BP5&RIGHT(BP4,2)&BP6 -> 2Q23 | BQ3: =BQ5&RIGHT(BQ4,2)&BQ6 -> 3Q23 | BR3: =BR5&RIGHT(BR4,2)&BR6 -> 4Q23 | BS3: =BS4&BS6 -> 2023 | BT3: =BT5&RIGHT(BT4,2)&BT6 -> 1Q24 | BU3: =BU5&RIGHT(BU4,2)&BU6 -> 2Q24 | BV3: =BV5&RIGHT(BV4,2)&BV6 -> 3Q24 | BW3: =BW5&RIGHT(BW4,2)&BW6 -> 4Q24 | BX3: =BX4&BX6 -> 2024 | BY3: =BY5&RIGHT(BY4,2)&BY6 -> 1Q25 | BZ3: =BZ5&RIGHT(BZ4,2)&BZ6 -> 2Q25 | CA3: =CA5&RIGHT(CA4,2)&CA6 -> 3Q25 | CB3: =CB5&RIGHT(CB4,2)&CB6 -> 4Q25 | CC3: =CC4&CC6 -> 2025 | CD3: =CD5&RIGHT(CD4,2)&CD6 -> 1Q26 | CE3: =CE5&RIGHT(CE4,2)&CE6 -> 2Q26 | CF3: =CF5&RIGHT(CF4,2)&CF6 -> 3Q26E | CG3: =CG5&RIGHT(CG4,2)&CG6 -> 4Q26E | CH3: =CH4&CH6 -> 2026E | CI3: =CI5&RIGHT(CI4,2)&CI6 -> 1Q27E | CJ3: =CJ5&RIGHT(CJ4,2)&CJ6 -> 2Q27E | CK3: =CK5&RIGHT(CK4,2)&CK6 -> 3Q27E | CL3: =CL5&RIGHT(CL4,2)&CL6 -> 4Q27E | CM3: =CM4&CM6 -> 2027E | CN3: =CN5&RIGHT(CN4,2)&CN6 -> 1Q28E | CO3: =CO5&RIGHT(CO4,2)&CO6 -> 2Q28E | CP3: =CP5&RIGHT(CP4,2)&CP6 -> 3Q28E | CQ3: =CQ5&RIGHT(CQ4,2)&CQ6 -> 4Q28E | CR3: =CR4&CR6 -> 2028E | CS3: =CS5&RIGHT(CS4,2)&CS6 -> 1Q29E | CT3: =CT5&RIGHT(CT4,2)&CT6 -> 2Q29E | CU3: =CU5&RIGHT(CU4,2)&CU6 -> 3Q29E | CV3: =CV5&RIGHT(CV4,2)&CV6 -> 4Q29E | CW3: =CW4&CW6 -> 2029E | CX3: =CX5&RIGHT(CX4,2)&CX6 -> 1Q30E | CY3: =CY5&RIGHT(CY4,2)&CY6 -> 2Q30E | CZ3: =CZ5&RIGHT(CZ4,2)&CZ6 -> 3Q30E | DA3: =DA5&RIGHT(DA4,2)&DA6 -> 4Q30E | DB3: =DB4&DB6 -> 2030E
A4: Year | B4: 2010 | C4: 2010 | D4: 2010 | E4: 2010 | F4: =E4 -> 2010 | G4: =B4+1 -> 2011 | H4: =C4+1 -> 2011 | I4: =D4+1 -> 2011 | J4: =E4+1 -> 2011 | K4: =J4 -> 2011 | L4: =G4+1 -> 2012 | M4: =H4+1 -> 2012 | N4: =I4+1 -> 2012 | O4: =J4+1 -> 2012 | P4: =O4 -> 2012 | Q4: =L4+1 -> 2013 | R4: =M4+1 -> 2013 | S4: =N4+1 -> 2013 | T4: =O4+1 -> 2013 | U4: =T4 -> 2013 | V4: =Q4+1 -> 2014 | W4: =R4+1 -> 2014 | X4: =S4+1 -> 2014 | Y4: =T4+1 -> 2014 | Z4: =Y4 -> 2014 | AA4: =V4+1 -> 2015 | AB4: =W4+1 -> 2015 | AC4: =X4+1 -> 2015 | AD4: =Y4+1 -> 2015 | AE4: =AD4 -> 2015 | AF4: =AA4+1 -> 2016 | AG4: =AB4+1 -> 2016 | AH4: =AC4+1 -> 2016 | AI4: =AD4+1 -> 2016 | AJ4: =AI4 -> 2016 | AK4: =AF4+1 -> 2017 | AL4: =AG4+1 -> 2017 | AM4: =AH4+1 -> 2017 | AN4: =AI4+1 -> 2017 | AO4: =AN4 -> 2017 | AP4: =AK4+1 -> 2018 | AQ4: =AL4+1 -> 2018 | AR4: =AM4+1 -> 2018 | AS4: =AN4+1 -> 2018 | AT4: =AS4 -> 2018 | AU4: =AP4+1 -> 2019 | AV4: =AQ4+1 -> 2019 | AW4: =AR4+1 -> 2019 | AX4: =AS4+1 -> 2019 | AY4: =AX4 -> 2019 | AZ4: =AU4+1 -> 2020 | BA4: =AV4+1 -> 2020 | BB4: =AW4+1 -> 2020 | BC4: =AX4+1 -> 2020 | BD4: =BC4 -> 2020 | BE4: =AZ4+1 -> 2021 | BF4: =BA4+1 -> 2021 | BG4: =BB4+1 -> 2021 | BH4: =BC4+1 -> 2021 | BI4: =BH4 -> 2021 | BJ4: =BE4+1 -> 2022 | BK4: =BF4+1 -> 2022 | BL4: =BG4+1 -> 2022 | BM4: =BH4+1 -> 2022 | BN4: =BM4 -> 2022 | BO4: =BJ4+1 -> 2023 | BP4: =BK4+1 -> 2023 | BQ4: =BL4+1 -> 2023 | BR4: =BM4+1 -> 2023 | BS4: =BR4 -> 2023 | BT4: =BO4+1 -> 2024 | BU4: =BP4+1 -> 2024 | BV4: =BQ4+1 -> 2024 | BW4: =BR4+1 -> 2024 | BX4: =BW4 -> 2024 | BY4: =BT4+1 -> 2025 | BZ4: =BU4+1 -> 2025 | CA4: =BV4+1 -> 2025 | CB4: =BW4+1 -> 2025 | CC4: =CB4 -> 2025 | CD4: =BY4+1 -> 2026 | CE4: =BZ4+1 -> 2026 | CF4: =CA4+1 -> 2026 | CG4: =CB4+1 -> 2026 | CH4: =CG4 -> 2026 | CI4: =CD4+1 -> 2027 | CJ4: =CE4+1 -> 2027 | CK4: =CF4+1 -> 2027 | CL4: =CG4+1 -> 2027 | CM4: =CL4 -> 2027 | CN4: =CI4+1 -> 2028 | CO4: =CJ4+1 -> 2028 | CP4: =CK4+1 -> 2028 | CQ4: =CL4+1 -> 2028 | CR4: =CQ4 -> 2028 | CS4: =CN4+1 -> 2029 | CT4: =CO4+1 -> 2029 | CU4: =CP4+1 -> 2029 | CV4: =CQ4+1 -> 2029 | CW4: =CV4 -> 2029 | CX4: =CS4+1 -> 2030 | CY4: =CT4+1 -> 2030 | CZ4: =CU4+1 -> 2030 | DA4: =CV4+1 -> 2030 | DB4: =DA4 -> 2030
A5: Quarter | B5: 1Q | C5: 2Q | D5: 3Q | E5: 4Q | G5: 1Q | H5: 2Q | I5: 3Q | J5: 4Q | K5: 20 | L5: 1Q | M5: 2Q | N5: 3Q | O5: 4Q | P5: 20 | Q5: 1Q | R5: 2Q | S5: 3Q | T5: 4Q | U5: 20 | V5: 1Q | W5: 2Q | X5: 3Q | Y5: 4Q | Z5: 20 | AA5: 1Q | AB5: 2Q | AC5: 3Q | AD5: 4Q | AE5: 20 | AF5: 1Q | AG5: 2Q | AH5: 3Q | AI5: 4Q | AJ5: 20 | AK5: 1Q | AL5: 2Q | AM5: 3Q | AN5: 4Q | AO5: 20 | AP5: 1Q | AQ5: 2Q | AR5: 3Q | AS5: 4Q | AT5: 20 | AU5: 1Q | AV5: 2Q | AW5: 3Q | AX5: 4Q | AY5: 20 | AZ5: 1Q | BA5: 2Q | BB5: 3Q | BC5: 4Q | BD5: 20 | BE5: 1Q | BF5: 2Q | BG5: 3Q | BH5: 4Q | BI5: 20 | BJ5: 1Q | BK5: 2Q | BL5: 3Q | BM5: 4Q | BN5: 20 | BO5: 1Q | BP5: 2Q | BQ5: 3Q | BR5: 4Q | BS5: 20 | BT5: 1Q | BU5: 2Q | BV5: 3Q | BW5: 4Q | BX5: 20 | BY5: 1Q | BZ5: 2Q | CA5: 3Q | CB5: 4Q | CC5: 20 | CD5: 1Q | CE5: 2Q | CF5: 3Q | CG5: 4Q | CH5: 20 | CI5: 1Q | CJ5: 2Q | CK5: 3Q | CL5: 4Q | CM5: 20 | CN5: 1Q | CO5: 2Q | CP5: 3Q | CQ5: 4Q | CR5: 20 | CS5: 1Q | CT5: 2Q | CU5: 3Q | CV5: 4Q | CW5: 20 | CX5: 1Q | CY5: 2Q | CZ5: 3Q | DA5: 4Q | DB5: 20
A6: Actual / estimate | CF6: E | CG6: E | CH6: E | CI6: E | CJ6: E | CK6: E | CL6: E | CM6: E | CN6: E | CO6: E | CP6: E | CQ6: E | CR6: E | CS6: E | CT6: E | CU6: E | CV6: E | CW6: E | CX6: E | CY6: E | CZ6: E | DA6: E | DB6: E
A7: GDP growth | B7: =[4]Macro_Model!B7 -> 0.091174884 | C7: =[4]Macro_Model!C7 -> 0.085075937 | D7: =[4]Macro_Model!D7 -> 0.06962323 | E7: =[4]Macro_Model!E7 -> 0.057675173 | F7: =[4]Macro_Model!F7 -> 0.075282491 | G7: =[4]Macro_Model!G7 -> 0.050185202 | H7: =[4]Macro_Model!H7 -> 0.047444346 | I7: =[4]Macro_Model!I7 -> 0.035981126 | ... DB7: =[4]Macro_Model!DB7 -> 0.018
A8: IGP-M | B8: =[4]Macro_Model!B8 -> 0.0277751 | C8: =[4]Macro_Model!C8 -> 0.028275291 | D8: =[4]Macro_Model!D8 -> 0.020898783 | E8: =[4]Macro_Model!E8 -> 0.031799424 | F8: =[4]Macro_Model!F8 -> 0.11323143 | G8: =[4]Macro_Model!G8 -> 0.024312626 | H8: =[4]Macro_Model!H8 -> 0.0069680368 | I8: =[4]Macro_Model!I8 -> 0.0097144444 | ... DB8: =[4]Macro_Model!DB8 -> 0.035
A9: IGP-M y/y | B9: =[4]Macro_Model!B9 -> 0 | C9: =[4]Macro_Model!C9 -> 0 | D9: =[4]Macro_Model!D9 -> 0 | E9: =[4]Macro_Model!E9 -> 0 | F9: =[4]Macro_Model!F9 -> 0.11323143 | G9: =[4]Macro_Model!G9 -> 0 | H9: =[4]Macro_Model!H9 -> 0 | I9: =[4]Macro_Model!I9 -> 0 | ... DB9: =[4]Macro_Model!DB9 -> 0.035
A10: IPCA q/q | B10: =[4]Macro_Model!B10 -> 0.020635673 | C10: =[4]Macro_Model!C10 -> 0.01002643 | D10: =[4]Macro_Model!D10 -> 0.0049988106 | E10: =[4]Macro_Model!E10 -> 0.02226281 | F10: =[4]Macro_Model!F10 -> 0.059086887 | G10: =[4]Macro_Model!G10 -> 0.02439696 | H10: =[4]Macro_Model!H10 -> 0.013956003 | I10: =[4]Macro_Model!I10 -> 0.010633971 | ... DB10: =[4]Macro_Model!DB10 -> 0.035
A11: IPCA y/y | B11: =[4]Macro_Model!B11 -> 0.048630627 | C11: =[4]Macro_Model!C11 -> 0.051065847 | D11: =[4]Macro_Model!D11 -> 0.045967658 | E11: =[4]Macro_Model!E11 -> 0.055795324 | F11: =[4]Macro_Model!F11 -> 0.059086887 | G11: =[4]Macro_Model!G11 -> 0.061020488 | H11: =[4]Macro_Model!H11 -> 0.065918631 | I11: =[4]Macro_Model!I11 -> 0.071362426 | ... DB11: =[4]Macro_Model!DB11 -> 0.035
A12: CDI rate | B12: =[4]Macro_Model!B12 -> 0.0875 | C12: =[4]Macro_Model!C12 -> 0.0975 | D12: =[4]Macro_Model!D12 -> 0.1075 | E12: =[4]Macro_Model!E12 -> 0.1075 | F12: =[4]Macro_Model!F12 -> 0.1 | G12: =[4]Macro_Model!G12 -> 0.11416667 | H12: =[4]Macro_Model!H12 -> 0.12083333 | I12: =[4]Macro_Model!I12 -> 0.12166667 | ... DB12: =[4]Macro_Model!DB12 -> 0.106

Sheet IS
A2: =Valuation!$A$2 -> CYRE3 | TP R$35/sh
A3: Income Statement (R$000') | B3: =Macro!B$3 -> 1Q10 | C3: =Macro!C$3 -> 2Q10 | D3: =Macro!D$3 -> 3Q10 | E3: =Macro!E$3 -> 4Q10 | F3: =Macro!F$3 -> 2010 | G3: =Macro!G$3 -> 1Q11 | H3: =Macro!H$3 -> 2Q11 | I3: =Macro!I$3 -> 3Q11 | ... DB3: =Macro!DB$3 -> 2030E
A4: Gross revenues | B4: =B5+B6 -> 1170169 | C4: =C5+C6 -> 1234539 | D4: =D5+D6 -> 1203539 | E4: =E5+E6 -> 1445304 | F4: =SUM(B4:E4) -> 5053551 | G4: =G5+G6 -> 1248883 | H4: =H5+H6 -> 1438136 | I4: =I5+I6 -> 1619390 | J4: =J5+J6 -> 2069350 | K4: =SUM(G4:J4) -> 6375759 | L4: =L5+L6 -> 1522642 | M4: =M5+M6 -> 1438939 | N4: =N5+N6 -> 1409120 | O4: =O5+O6 -> 1432050 | P4: =SUM(L4:O4) -> 5802751 | Q4: =Q5+Q6 -> 1250942 | R4: =R5+R6 -> 1410150 | S4: =S5+S6 -> 1435138 | T4: =T5+T6 -> 1436106 | U4: =SUM(Q4:T4) -> 5532336 | V4: =V5+V6 -> 1351067 | W4: =W5+W6 -> 1397217 | X4: =X5+X6 -> 1628377 | Y4: =Y5+Y6 -> 1569902 | Z4: =SUM(V4:Y4) -> 5946563 | AA4: =AA5+AA6 -> 1068010 | AB4: =AB5+AB6 -> 1165862 | AC4: =AC5+AC6 -> 1172876 | AD4: =AD5+AD6 -> 1059054 | AE4: =SUM(AA4:AD4) -> 4465802 | AF4: =AF5+AF6 -> 833226 | AG4: =AG5+AG6 -> 662190 | AH4: =AH5+AH6 -> 847384 | AI4: =AI5+AI6 -> 947904 | AJ4: =SUM(AF4:AI4) -> 3290704 | AK4: =AK5+AK6 -> 712412 | AL4: =AL5+AL6 -> 591107 | AM4: =AM5+AM6 -> 614497 | AN4: =AN5+AN6 -> 831905 | AO4: =SUM(AK4:AN4) -> 2749921 | AP4: =AP5+AP6 -> 464152 | AQ4: =AQ5+AQ6 -> 657521 | AR4: =AR5+AR6 -> 744589 | AS4: =AS5+AS6 -> 1111066 | AT4: =SUM(AP4:AS4) -> 2977328 | AU4: =AU5+AU6 -> 847909 | AV4: =AV5+AV6 -> 959639 | AW4: =AW5+AW6 -> 959878 | AX4: =AX5+AX6 -> 1265292 | AY4: =SUM(AU4:AX4) -> 4032718 | AZ4: =AZ5+AZ6 -> 785189 | BA4: =BA5+BA6 -> 860738 | BB4: =BB5+BB6 -> 1192465 | BC4: =BC5+BC6 -> 1087405 | BD4: =SUM(AZ4:BC4) -> 3925797 | BE4: =BE5+BE6 -> 1030234 | BF4: =BF5+BF6 -> 1213954 | BG4: =BG5+BG6 -> 1321796 | BH4: =BH5+BH6 -> 1351676 | BI4: =SUM(BE4:BH4) -> 4917660 | BJ4: =BJ5+BJ6 -> 1259101 | BK4: =BK5+BK6 -> 1284091 | BL4: =BL5+BL6 -> 1600107 | BM4: =BM5+BM6 -> 1412549 | BN4: =SUM(BJ4:BM4) -> 5555848 | BO4: =BO5+BO6 -> 1317322 | BP4: =BP5+BP6 -> 1678440 | BQ4: =BQ5+BQ6 -> 1672991 | BR4: =BR5+BR6 -> 1760921 | BS4: =SUM(BO4:BR4) -> 6429674 | BT4: =BT5+BT6 -> 1614575 | BU4: =BU5+BU6 -> 1909290 | BV4: =BV5+BV6 -> 2086805 | BW4: =BW5+BW6 -> 2574979 | BX4: =SUM(BT4:BW4) -> 8185649 | BY4: =BY5+BY6 -> 2003367 | BZ4: =BZ5+BZ6 -> 2167903 | CA4: =CA5+CA6 -> 2191373 | CB4: =CB5+CB6 -> 3317082 | CC4: =SUM(BY4:CB4) -> 9679725 | CD4: =CD5+CD6 -> 2081306 | CE4: =CE5+CE6 -> 2548922 | CF4: =CF5+CF6 -> 2725182.5 | CG4: =CG5+CG6 -> 2933473.8 | CH4: =SUM(CD4:CG4) -> 10288884 | CI4: =CI5+CI6 -> 2752041.2 | CJ4: =CJ5+CJ6 -> 2805655.7 | CK4: =CK5+CK6 -> 2948222.8 | CL4: =CL5+CL6 -> 3109438.2 | CM4: =SUM(CI4:CL4) -> 11615358 | CN4: =CN5+CN6 -> 3093368.1 | CO4: =CO5+CO6 -> 3128009.5 | CP4: =CP5+CP6 -> 3255981.1 | CQ4: =CQ5+CQ6 -> 3475613.2 | CR4: =SUM(CN4:CQ4) -> 12952972 | CS4: =CS5+CS6 -> 3391188.9 | CT4: =CT5+CT6 -> 3408720 | CU4: =CU5+CU6 -> 3525236 | CV4: =CV5+CV6 -> 3741182.3 | CW4: =SUM(CS4:CV4) -> 14066327 | CX4: =CX5+CX6 -> 3649385.9 | CY4: =CY5+CY6 -> 3657352 | CZ4: =CZ5+CZ6 -> 3772174 | DA4: =DA5+DA6 -> 3988590.2 | DB4: =SUM(CX4:DA4) -> 15067502
A5: Development revenues | B5: =1140556+18091 -> 1158647 | C5: =1191445+26952-C33 -> 1218397 | D5: =1171767+13862 -> 1185629 | E5: =1407331+6543 -> 1413874 | F5: =SUM(B5:E5) -> 4976547 | G5: =1216842+8949 -> 1225791 | H5: =2625160+13076-G5 -> 1412445 | I5: =4207472+17666-G5-H5 -> 1586902 | J5: =6240161+26490-G5-H5-I5 -> 2041513 | K5: =SUM(G5:J5) -> 6266651 | L5: =2915251+4573-M5 -> 1505576 | M5: =1411422+2826 -> 1414248 | N5: =1409120-N6 -> 1394730 | O5: =5701885+14069-L5-M5-N5 -> 1401400 | P5: =SUM(L5:O5) -> 5715954 | Q5: =2603392+20342-R5 -> 1233951 | R5: =1382665+7118 -> 1389783 | S5: =1435138-S6 -> 1414214 | T5: =5532336-SUM(Q5:S5)-SUM(Q6:T6) -> 1410416 | U5: =SUM(Q5:T5) -> 5448364 | V5: =1317983+17433 -> 1335416 | W5: =1366342+14295 -> 1380637 | X5: =1628377-X6 -> 1607593 | Y5: =5946563-SUM(V5:X5)-SUM(V6:Y6) -> 1558582 | Z5: =SUM(V5:Y5) -> 5882228 | AA5: =1031782+22263 -> 1054045 | AB5: =1141593+15312 -> 1156905 | AC5: =1172876-AC6 -> 1164221 | AD5: =4465802-SUM(AA5:AC5)-SUM(AA6:AD6) -> 1046063 | AE5: =SUM(AA5:AD5) -> 4421234 | AF5: =799333+20950 -> 820283 | AG5: =614249+21481 -> 635730 | AH5: =847384-AH6 -> 839121 | AI5: =3290704-SUM(AF5:AH5)-SUM(AF6:AI6) -> 942441 | AJ5: =SUM(AF5:AI5) -> 3237575 | AK5: =678581+16224 -> 694805 | AL5: =573917+11356 -> 585273 | AM5: =614497-AM6 -> 608783 | AN5: =2671670+44168-SUM(AK5:AM5) -> 826977 | AO5: =SUM(AK5:AN5) -> 2715838 | AP5: =445472+14559 -> 460031 | AQ5: =638476+14319 -> 652795 | AR5: =728261+9518 -> 737779 | AS5: =3156039+51958-SUM(AP5:AR5)-254000 -> 1103392 | AT5: =SUM(AP5:AS5) -> 2953997 | AU5: =845764+11907-14195 -> 843476 | AV5: =953167+9105-6610 -> 955662 | AW5: =901500+8113+41796 -> 951409 | AX5: =3867086+34904+105628-SUM(AU5:AW5) -> 1257071 | AY5: =SUM(AU5:AX5) -> 4007618 | AZ5: =724852+9374+39479 -> 773705 | BA5: =826804+3845+16608 -> 847257 | BB5: =1153156+14847+6784 -> 1174787 | BC5: =3765116+41562+48464-SUM(AZ5:BB5) -> 1059393 | BD5: =SUM(AZ5:BC5) -> 3855142 | BE5: =1057818+20802-45161-24355 -> 1009104 | BF5: =1193319+15809-12203-7752 -> 1189173 | BG5: =1288055+11945+2193-5203 -> 1296990 | BH5: =4851226+51769-62954-35986-SUM(BE5:BG5) -> 1308788 | BI5: =SUM(BE5:BH5) -> 4804055 | BJ5: =1270338+6461-43143+5545 -> 1239201 | BK5: =1219902+10977+30436-6907 -> 1254408 | BL5: =1549256+2670+8131+9798 -> 1569855 | BM5: =5440721+23045-15086+6545-SUM(BJ5:BL5) -> 1391761 | BN5: =SUM(BJ5:BM5) -> 5455225 | BO5: =1323506+633-18150-4887 -> 1301102 | BP5: =2967331+1814-2630-7413-BO5 -> 1658000 | BQ5: =4598860+2811+12432-3586-SUM(BO5:BP5) -> 1651415 | BR5: =6373445+3955-30135-3508-SUM(BO5:BQ5) -> 1733240 | BS5: =SUM(BO5:BR5) -> 6343757 | BT5: =1644948+2568-46749-5947 -> 1594820 | BU5: =3509983+3638-29563-3531-BT5 -> 1885707 | BV5: =5585280+2631-45676-236-SUM(BT5:BU5) -> 2061472 | BW5: =8201507+3951-109456-5895-SUM(BT5:BV5) -> 2548108 | BX5: =SUM(BT5:BW5) -> 8090107 | BY5: =2074898+285-99013-914 -> 1975256 | BZ5: =4146252+272-28621-1012-BY5 -> 2141635 | CA5: =6199476+66785+24246-10557-BZ5-BY5 -> 2163059 | CB5: =9498874+90734-12130-9388-SUM(BY5:CA5) -> 3288140 | CC5: =SUM(BY5:CB5) -> 9568090 | CD5: =2110359+10713-68796-2191 -> 2050085 | CE5: =4601478+13577-56471-3916-CD5 -> 2504583 | CF5: =Operating!CF35 -> 2677777.4 | CG5: =Operating!CG35 -> 2882445.5 | CH5: =SUM(CD5:CG5) -> 10114891 | CI5: =Operating!CI35 -> 2704168.9 | CJ5: =Operating!CJ35 -> 2756850.8 | CK5: =Operating!CK35 -> 2896937.9 | CL5: =Operating!CL35 -> 3055348.9 | CM5: =SUM(CI5:CL5) -> 11413306 | CN5: =Operating!CN35 -> 3039558.3 | CO5: =Operating!CO35 -> 3073597.2 | CP5: =Operating!CP35 -> 3199342.7 | CQ5: =Operating!CQ35 -> 3415154.2 | CR5: =SUM(CN5:CQ5) -> 12727652 | CS5: =Operating!CS35 -> 3332198.5 | CT5: =Operating!CT35 -> 3349424.6 | CU5: =Operating!CU35 -> 3463913.9 | CV5: =Operating!CV35 -> 3676103.7 | CW5: =SUM(CS5:CV5) -> 13821641 | CX5: =Operating!CX35 -> 3585904.1 | CY5: =Operating!CY35 -> 3593731.7 | CZ5: =Operating!CZ35 -> 3706556.3 | DA5: =Operating!DA35 -> 3919207.9 | DB5: =SUM(CX5:DA5) -> 14805400
A6: Service revenues | B6: 11522 | C6: 16142 | D6: 17910 | E6: 31430 | F6: =SUM(B6:E6) -> 77004 | G6: 23092 | H6: =48783-G6 -> 25691 | I6: =81271-G6-H6 -> 32488 | J6: =109108-G6-H6-I6 -> 27837 | K6: =SUM(G6:J6) -> 109108 | L6: =41757-M6 -> 17066 | M6: 24691 | N6: 14390 | O6: =86797-L6-M6-N6 -> 30650 | P6: =SUM(L6:O6) -> 86797 | Q6: =37358-R6 -> 16991 | R6: 20367 | S6: 20924 | T6: =83972-SUM(Q6:S6) -> 25690 | U6: =SUM(Q6:T6) -> 83972 | V6: 15651 | W6: 16580 | X6: 20784 | Y6: =64335-SUM(V6:X6) -> 11320 | Z6: =SUM(V6:Y6) -> 64335 | AA6: 13965 | AB6: 8957 | AC6: 8655 | AD6: =44568-SUM(AA6:AC6) -> 12991 | AE6: =SUM(AA6:AD6) -> 44568 | AF6: 12943 | AG6: 26460 | AH6: 8263 | AI6: =53129-SUM(AF6:AH6) -> 5463 | AJ6: =SUM(AF6:AI6) -> 53129 | AK6: 17607 | AL6: 5834 | AM6: 5714 | AN6: =34083-SUM(AK6:AM6) -> 4928 | AO6: =SUM(AK6:AN6) -> 34083 | AP6: 4121 | AQ6: 4726 | AR6: 6810 | AS6: =23331-SUM(AP6:AR6) -> 7674 | AT6: =SUM(AP6:AS6) -> 23331 | AU6: 4433 | AV6: 3977 | AW6: 8469 | AX6: =25100-SUM(AU6:AW6) -> 8221 | AY6: =SUM(AU6:AX6) -> 25100 | AZ6: 11484 | BA6: 13481 | BB6: 17678 | BC6: =70655-SUM(AZ6:BB6) -> 28012 | BD6: =SUM(AZ6:BC6) -> 70655 | BE6: 21130 | BF6: 24781 | BG6: 24806 | BH6: =113605-SUM(BE6:BG6) -> 42888 | BI6: =SUM(BE6:BH6) -> 113605 | BJ6: 19900 | BK6: 29683 | BL6: 30252 | BM6: =100623-SUM(BJ6:BL6) -> 20788 | BN6: =SUM(BJ6:BM6) -> 100623 | BO6: 16220 | BP6: =36660-BO6 -> 20440 | BQ6: =58236-SUM(BO6:BP6) -> 21576 | BR6: =85917-SUM(BO6:BQ6) -> 27681 | BS6: =SUM(BO6:BR6) -> 85917 | BT6: 19755 | BU6: =43338-BT6 -> 23583 | BV6: =68671-SUM(BT6:BU6) -> 25333 | BW6: =95542-SUM(BT6:BV6) -> 26871 | BX6: =SUM(BT6:BW6) -> 95542 | BY6: 28111 | BZ6: =54379-BY6 -> 26268 | CA6: =82693-BZ6-BY6 -> 28314 | CB6: =111635-SUM(BY6:CA6) -> 28942 | CC6: =SUM(BY6:CB6) -> 111635 | CD6: 31221 | CE6: =75560-CD6 -> 44339 | CF6: =Operating!CF41 -> 47405.086 | CG6: =Operating!CG41 -> 51028.355 | CH6: =SUM(CD6:CG6) -> 173993.44 | CI6: =Operating!CI41 -> 47872.298 | CJ6: =Operating!CJ41 -> 48804.934 | CK6: =Operating!CK41 -> 51284.917 | CL6: =Operating!CL41 -> 54089.289 | CM6: =SUM(CI6:CL6) -> 202051.44 | CN6: =Operating!CN41 -> 53809.746 | CO6: =Operating!CO41 -> 54412.342 | CP6: =Operating!CP41 -> 56638.433 | CQ6: =Operating!CQ41 -> 60458.975 | CR6: =SUM(CN6:CQ6) -> 225319.5 | CS6: =Operating!CS41 -> 58990.398 | CT6: =Operating!CT41 -> 59295.355 | CU6: =Operating!CU41 -> 61322.175 | CV6: =Operating!CV41 -> 65078.603 | CW6: =SUM(CS6:CV6) -> 244686.53 | CX6: =Operating!CX41 -> 63481.785 | CY6: =Operating!CY41 -> 63620.358 | CZ6: =Operating!CZ41 -> 65617.709 | DA6: =Operating!DA41 -> 69382.311 | DB6: =SUM(CX6:DA6) -> 262102.16
A7: Taxes and deductions | B7: -37721 | C7: -28704 | D7: -40990 | E7: -56031 | F7: =SUM(B7:E7) -> -163446 | G7: -48141 | H7: =-103393-G7 -> -55252 | I7: =-163181-G7-H7 -> -59788 | J7: =-248978-G7-H7-I7 -> -85797 | K7: =SUM(G7:J7) -> -248978 | L7: =-109975-M7 -> -56299 | M7: -53676 | N7: -59168 | O7: =-170072-L7-M7-N7 -> -929 | P7: =SUM(L7:O7) -> -170072 | Q7: =-73303-R7 -> -35572 | R7: -37731 | S7: -40690 | T7: =-160454-SUM(Q7:S7) -> -46461 | U7: =SUM(Q7:T7) -> -160454 | V7: -35705 | W7: -38886 | X7: -14681 | Y7: =-128636-SUM(V7:X7) -> -39364 | Z7: =SUM(V7:Y7) -> -128636 | AA7: -32796 | AB7: -28179 | AC7: -35143 | AD7: =-124618-SUM(AA7:AC7) -> -28500 | AE7: =SUM(AA7:AD7) -> -124618 | AF7: -22520 | AG7: -21157 | AH7: -22577 | AI7: =-95394-SUM(AF7:AH7) -> -29140 | AJ7: =SUM(AF7:AI7) -> -95394 | AK7: -20025 | AL7: -16351 | AM7: -16670 | AN7: =-76151-SUM(AK7:AM7) -> -23105 | AO7: =SUM(AK7:AN7) -> -76151 | AP7: -13530 | AQ7: -17982 | AR7: -19764 | AS7: =-85171-SUM(AP7:AR7) -> -33895 | AT7: =SUM(AP7:AS7) -> -85171 | AU7: -21673 | AV7: -23017 | AW7: -25119 | AX7: =-101895-SUM(AU7:AW7) -> -32086 | AY7: =SUM(AU7:AX7) -> -101895 | AZ7: -20434 | BA7: -21930 | BB7: -28962 | BC7: =-102101-SUM(AZ7:BB7) -> -30775 | BD7: =SUM(AZ7:BC7) -> -102101 | BE7: -26502 | BF7: -31935 | BG7: -33457 | BH7: =-126827-SUM(BE7:BG7) -> -34933 | BI7: =SUM(BE7:BH7) -> -126827 | BJ7: -27449 | BK7: -34008 | BL7: -40463 | BM7: =-143553-SUM(BJ7:BL7) -> -41633 | BN7: =SUM(BJ7:BM7) -> -143553 | BO7: -33896 | BP7: =-79281-BO7 -> -45385 | BQ7: =-126285-SUM(BO7:BP7) -> -47004 | BR7: =-176975-SUM(BO7:BQ7) -> -50690 | BS7: =SUM(BO7:BR7) -> -176975 | BT7: -41664 | BU7: =-94097-BT7 -> -52433 | BV7: =-151251-SUM(BT7:BU7) -> -57154 | BW7: =-219961-SUM(BT7:BV7) -> -68710 | BX7: =SUM(BT7:BW7) -> -219961 | BY7: -50623 | BZ7: =-111396-BY7 -> -60773 | CA7: =-174323-BZ7-BY7 -> -62927 | CB7: =-256231-SUM(BY7:CA7) -> -81908 | CC7: =SUM(BY7:CB7) -> -256231 | CD7: -56273 | CE7: =-124324-CD7 -> -68051 | CF7: =-CF8*CF$4 -> -68129.563 | CG7: =-CG8*CG$4 -> -73336.846 | CH7: =SUM(CD7:CG7) -> -265790.41 | CI7: =-CI8*CI$4 -> -57242.456 | CJ7: =-CJ8*CJ$4 -> -58357.639 | CK7: =-CK8*CK$4 -> -61323.035 | CL7: =-CL8*CL$4 -> -64676.314 | CM7: =SUM(CI7:CL7) -> -241599.44 | CN7: =-CN8*CN$4 -> -64342.056 | CO7: =-CO8*CO$4 -> -65062.598 | CP7: =-CP8*CP$4 -> -67724.408 | CQ7: =-CQ8*CQ$4 -> -72292.754 | CR7: =SUM(CN7:CQ7) -> -269421.82 | CS7: =-CS8*CS$4 -> -70536.729 | CT7: =-CT8*CT$4 -> -70901.376 | CU7: =-CU8*CU$4 -> -73324.91 | CV7: =-CV8*CV$4 -> -77816.592 | CW7: =SUM(CS7:CV7) -> -292579.61 | CX7: =-CX8*CX$4 -> -75907.226 | CY7: =-CY8*CY$4 -> -76072.922 | CZ7: =-CZ8*CZ$4 -> -78461.219 | DA7: =-DA8*DA$4 -> -82962.676 | DB7: =SUM(CX7:DA7) -> -313404.04
A8: % of gross revenues | B8: =-B7/B$4 -> 0.032235515 | C8: =-C7/C$4 -> 0.023250784 | D8: =-D7/D$4 -> 0.034057891 | E8: =-E7/E$4 -> 0.038767623 | F8: =-F7/F$4 -> 0.032342802 | G8: =-G7/G$4 -> 0.038547246 | H8: =-H7/H$4 -> 0.038419176 | I8: =-I7/I$4 -> 0.036920075 | ... CE8: =-CE7/CE$4 -> 0.026697953 | CF8: 0.025 | CG8: 0.025 | CH8: =-CH7/CH$4 -> 0.025832773 | CI8: 0.0208 | CJ8: 0.0208 | CK8: 0.0208 | CL8: 0.0208 | CM8: =-CM7/CM$4 -> 0.0208 | CN8: 0.0208 | CO8: 0.0208 | CP8: 0.0208 | CQ8: 0.0208 | CR8: =-CR7/CR$4 -> 0.0208 | CS8: 0.0208 | CT8: 0.0208 | CU8: 0.0208 | CV8: 0.0208 | CW8: =-CW7/CW$4 -> 0.0208 | CX8: 0.0208 | CY8: 0.0208 | CZ8: 0.0208 | DA8: 0.0208 | DB8: =-DB7/DB$4 -> 0.0208
A9: Net Revenues | B9: =B4+B7 -> 1132448 | C9: =C4+C7 -> 1205835 | D9: =D4+D7 -> 1162549 | E9: =E4+E7 -> 1389273 | F9: =SUM(B9:E9) -> 4890105 | G9: =G4+G7 -> 1200742 | H9: =H4+H7 -> 1382884 | I9: =I4+I7 -> 1559602 | J9: =J4+J7 -> 1983553 | K9: =SUM(G9:J9) -> 6126781 | L9: =L4+L7 -> 1466343 | M9: =M4+M7 -> 1385263 | N9: =N4+N7 -> 1349952 | O9: =O4+O7 -> 1431121 | P9: =SUM(L9:O9) -> 5632679 | Q9: =Q4+Q7 -> 1215370 | R9: =R4+R7 -> 1372419 | S9: =S4+S7 -> 1394448 | T9: =T4+T7 -> 1389645 | U9: =SUM(Q9:T9) -> 5371882 | V9: =V4+V7 -> 1315362 | W9: =W4+W7 -> 1358331 | X9: =X4+X7 -> 1613696 | Y9: =Y4+Y7 -> 1530538 | Z9: =SUM(V9:Y9) -> 5817927 | AA9: =AA4+AA7 -> 1035214 | AB9: =AB4+AB7 -> 1137683 | AC9: =AC4+AC7 -> 1137733 | AD9: =AD4+AD7 -> 1030554 | AE9: =SUM(AA9:AD9) -> 4341184 | AF9: =AF4+AF7 -> 810706 | AG9: =AG4+AG7 -> 641033 | AH9: =AH4+AH7 -> 824807 | AI9: =AI4+AI7 -> 918764 | AJ9: =SUM(AF9:AI9) -> 3195310 | AK9: =AK4+AK7 -> 692387 | AL9: =AL4+AL7 -> 574756 | AM9: =AM4+AM7 -> 597827 | AN9: =AN4+AN7 -> 808800 | AO9: =SUM(AK9:AN9) -> 2673770 | AP9: =AP4+AP7 -> 450622 | AQ9: =AQ4+AQ7 -> 639539 | AR9: =AR4+AR7 -> 724825 | AS9: =AS4+AS7 -> 1077171 | AT9: =SUM(AP9:AS9) -> 2892157 | AU9: =AU4+AU7 -> 826236 | AV9: =AV4+AV7 -> 936622 | AW9: =AW4+AW7 -> 934759 | AX9: =AX4+AX7 -> 1233206 | AY9: =SUM(AU9:AX9) -> 3930823 | AZ9: =AZ4+AZ7 -> 764755 | BA9: =BA4+BA7 -> 838808 | BB9: =BB4+BB7 -> 1163503 | BC9: =BC4+BC7 -> 1056630 | BD9: =SUM(AZ9:BC9) -> 3823696 | BE9: =BE4+BE7 -> 1003732 | BF9: =BF4+BF7 -> 1182019 | BG9: =BG4+BG7 -> 1288339 | BH9: =BH4+BH7 -> 1316743 | BI9: =SUM(BE9:BH9) -> 4790833 | BJ9: =BJ4+BJ7 -> 1231652 | BK9: =BK4+BK7 -> 1250083 | BL9: =BL4+BL7 -> 1559644 | BM9: =BM4+BM7 -> 1370916 | BN9: =SUM(BJ9:BM9) -> 5412295 | BO9: =BO4+BO7 -> 1283426 | BP9: =BP4+BP7 -> 1633055 | BQ9: =BQ4+BQ7 -> 1625987 | BR9: =BR4+BR7 -> 1710231 | BS9: =SUM(BO9:BR9) -> 6252699 | BT9: =BT4+BT7 -> 1572911 | BU9: =BU4+BU7 -> 1856857 | BV9: =BV4+BV7 -> 2029651 | BW9: =BW4+BW7 -> 2506269 | BX9: =SUM(BT9:BW9) -> 7965688 | BY9: =BY4+BY7 -> 1952744 | BZ9: =BZ4+BZ7 -> 2107130 | CA9: =CA4+CA7 -> 2128446 | CB9: =CB4+CB7 -> 3235174 | CC9: =SUM(BY9:CB9) -> 9423494 | CD9: =CD4+CD7 -> 2025033 | CE9: =CE4+CE7 -> 2480871 | CF9: =CF4+CF7 -> 2657052.9 | CG9: =CG4+CG7 -> 2860137 | CH9: =SUM(CD9:CG9) -> 10023094 | CI9: =CI4+CI7 -> 2694798.7 | CJ9: =CJ4+CJ7 -> 2747298.1 | CK9: =CK4+CK7 -> 2886899.8 | CL9: =CL4+CL7 -> 3044761.9 | CM9: =SUM(CI9:CL9) -> 11373758 | CN9: =CN4+CN7 -> 3029026 | CO9: =CO4+CO7 -> 3062946.9 | CP9: =CP4+CP7 -> 3188256.7 | CQ9: =CQ4+CQ7 -> 3403320.4 | CR9: =SUM(CN9:CQ9) -> 12683550 | CS9: =CS4+CS7 -> 3320652.2 | CT9: =CT4+CT7 -> 3337818.6 | CU9: =CU4+CU7 -> 3451911.1 | CV9: =CV4+CV7 -> 3663365.7 | CW9: =SUM(CS9:CV9) -> 13773748 | CX9: =CX4+CX7 -> 3573478.6 | CY9: =CY4+CY7 -> 3581279.1 | CZ9: =CZ4+CZ7 -> 3693712.8 | DA9: =DA4+DA7 -> 3905627.5 | DB9: =SUM(CX9:DA9) -> 14754098
A10: Operating Costs | B10: =B11+B13+B14 -> -737831 | C10: =C11+C13+C14 -> -812794 | D10: =D11+D13+D14 -> -753585 | E10: =E11+E13+E14 -> -1049265 | F10: =SUM(B10:E10) -> -3353475 | G10: =G11+G13+G14 -> -872029 | H10: =H11+H13+H14 -> -1000388 | I10: =I11+I13+I14 -> -1113641 | J10: =J11+J13+J14 -> -1407233 | K10: =SUM(G10:J10) -> -4393291 | L10: =L11+L13+L14 -> -1006468 | M10: =M11+M13+M14 -> -973692 | N10: =N11+N13+N14 -> -921666 | O10: =O11+O13+O14 -> -912041 | P10: =SUM(L10:O10) -> -3813867 | Q10: =Q11+Q13+Q14 -> -818350 | R10: =R11+R13+R14 -> -924645 | S10: =S11+S13+S14 -> -937198 | T10: =T11+T13+T14 -> -932400 | U10: =SUM(Q10:T10) -> -3612593 | V10: =V11+V13+V14 -> -877707 | W10: =W11+W13+W14 -> -904779 | X10: =X11+X13+X14 -> -1130965 | Y10: =Y11+Y13+Y14 -> -1035730 | Z10: =SUM(V10:Y10) -> -3949181 | AA10: =AA11+AA13+AA14 -> -674603 | AB10: =AB11+AB13+AB14 -> -738627 | AC10: =AC11+AC13+AC14 -> -743219 | AD10: =AD11+AD13+AD14 -> -681656 | AE10: =SUM(AA10:AD10) -> -2838105 | AF10: =AF11+AF13+AF14 -> -528445 | AG10: =AG11+AG13+AG14 -> -387103 | AH10: =AH11+AH13+AH14 -> -563386 | AI10: =AI11+AI13+AI14 -> -653853 | AJ10: =SUM(AF10:AI10) -> -2132787 | AK10: =AK11+AK13+AK14 -> -477370 | AL10: =AL11+AL13+AL14 -> -421167 | AM10: =AM11+AM13+AM14 -> -450495 | AN10: =AN11+AN13+AN14 -> -590225 | AO10: =SUM(AK10:AN10) -> -1939257 | AP10: =AP11+AP13+AP14 -> -325839 | AQ10: =AQ11+AQ13+AQ14 -> -468242 | AR10: =AR11+AR13+AR14 -> -520049 | AS10: =AS11+AS13+AS14 -> -763100 | AT10: =SUM(AP10:AS10) -> -2077230 | AU10: =AU11+AU13+AU14 -> -577347 | AV10: =AV11+AV13+AV14 -> -643662 | AW10: =AW11+AW13+AW14 -> -645832 | AX10: =AX11+AX13+AX14 -> -848268 | AY10: =SUM(AU10:AX10) -> -2715109 | AZ10: =AZ11+AZ13+AZ14 -> -503900 | BA10: =BA11+BA13+BA14 -> -563937 | BB10: =BB11+BB13+BB14 -> -784922 | BC10: =BC11+BC13+BC14 -> -720554 | BD10: =SUM(AZ10:BC10) -> -2573313 | BE10: =BE11+BE13+BE14 -> -657192 | BF10: =BF11+BF13+BF14 -> -749735 | BG10: =BG11+BG13+BG14 -> -841443 | BH10: =BH11+BH13+BH14 -> -876643 | BI10: =SUM(BE10:BH10) -> -3125013 | BJ10: =BJ11+BJ13+BJ14 -> -848102 | BK10: =BK11+BK13+BK14 -> -858752 | BL10: =BL11+BL13+BL14 -> -1031260 | BM10: =BM11+BM13+BM14 -> -940219 | BN10: =SUM(BJ10:BM10) -> -3678333 | BO10: =BO11+BO13+BO14 -> -888959 | BP10: =BP11+BP13+BP14 -> -1105967 | BQ10: =BQ11+BQ13+BQ14 -> -1080523 | BR10: =BR11+BR13+BR14 -> -1133651 | BS10: =SUM(BO10:BR10) -> -4209100 | BT10: =BT11+BT13+BT14 -> -1079389 | BU10: =BU11+BU13+BU14 -> -1246830 | BV10: =BV11+BV13+BV14 -> -1353486 | BW10: =BW11+BW13+BW14 -> -1706118 | BX10: =SUM(BT10:BW10) -> -5385823 | BY10: =BY11+BY13+BY14 -> -1318405 | BZ10: =BZ11+BZ13+BZ14 -> -1417294 | CA10: =CA11+CA13+CA14 -> -1426032 | CB10: =CB11+CB13+CB14 -> -2191794 | CC10: =SUM(BY10:CB10) -> -6353525 | CD10: =CD11+CD13+CD14 -> -1359107 | CE10: =CE11+CE13+CE14 -> -1627952 | CF10: =CF11+CF13+CF14 -> -1759307.7 | CG10: =CG11+CG13+CG14 -> -1894204.9 | CH10: =SUM(CD10:CG10) -> -6640571.6 | CI10: =CI11+CI13+CI14 -> -1774990.7 | CJ10: =CJ11+CJ13+CJ14 -> -1812335.4 | CK10: =CK11+CK13+CK14 -> -1907188.7 | CL10: =CL11+CL13+CL14 -> -2013734.1 | CM10: =SUM(CI10:CL10) -> -7508248.8 | CN10: =CN11+CN13+CN14 -> -2000760.8 | CO10: =CO11+CO13+CO14 -> -2025161 | CP10: =CP11+CP13+CP14 -> -2111089.2 | CQ10: =CQ11+CQ13+CQ14 -> -2258153.8 | CR10: =SUM(CN10:CQ10) -> -8395164.8 | CS10: =CS11+CS13+CS14 -> -2203657.9 | CT10: =CT11+CT13+CT14 -> -2214817.1 | CU10: =CU11+CU13+CU14 -> -2291616.2 | CV10: =CV11+CV13+CV14 -> -2435550 | CW10: =SUM(CS10:CV10) -> -9145641.2 | CX10: =CX11+CX13+CX14 -> -2372527.5 | CY10: =CY11+CY13+CY14 -> -2377266.4 | CZ10: =CZ11+CZ13+CZ14 -> -2452929.4 | DA10: =DA11+DA13+DA14 -> -2597143 | DB10: =SUM(CX10:DA10) -> -9799866.2
A11: Development costs | B11: =-720668-8588-B13 -> -719706 | C11: =-788554-11417-C13 -> -780649 | D11: =-733569-6811-D13 -> -723289 | E11: =-1022857-6899-E13 -> -979524 | F11: =SUM(B11:E11) -> -3203168 | G11: =-872029-G13-G14 -> -814297 | H11: =-1822675-11542-G11-G13-H13 -> -938469 | I11: =-2913877-14933-G11-H11-G13-H13-I13 -> -1033848 | J11: =-4307266-23111-G11-H11-I11-SUM(G13:J13) -> -1351567 | K11: =SUM(G11:J11) -> -4138181 | L11: =-1948429-2281-M11-L13-M13 -> -953589 | M11: =-954640-1681-M13 -> -920832 | N11: =-921666-N13-N14 -> -869668 | O11: =-3752076-7039-L11-M11-N11-SUM(L13:O13) -> -836719 | P11: =SUM(L11:O11) -> -3580808 | Q11: =-1706950-9638-R11-Q13-R13 -> -776189 | R11: =-906964-3456-R13 -> -878136 | S11: =-937198-S13-S14 -> -872421 | T11: =-3612593-SUM(Q11:S11)-SUM(Q13:T13)-SUM(Q14:T14) -> -840276 | U11: =SUM(Q11:T11) -> -3367022 | V11: =-860370-6154-V13 -> -817972 | W11: =-888975-5318-W13 -> -841556 | X11: =-1130965-X13-X14 -> -1065415 | Y11: =-3949181-SUM(V11:X11)-SUM(V13:Y13)-SUM(V14:Y14) -> -971255 | Z11: =SUM(V11:Y11) -> -3696198 | AA11: =-649099-14345-AA13 -> -619379 | AB11: =-723129-8237-AB13 -> -690531 | AC11: =-743219-AC13-AC14 -> -693061 | AD11: =-2838105-SUM(AA11:AC11)-SUM(AA13:AD13)-SUM(AA14:AD14) -> -628303 | AE11: =SUM(AA11:AD11) -> -2631274 | AF11: =-508878-8982-AF13 -> -467503 | AG11: =-355863-9166-AG13 -> -316982 | AH11: =-563386-AH13-AH14 -> -501053 | AI11: =-2132787-SUM(AF11:AH11)-SUM(AF13:AI13)-SUM(AF14:AI14) -> -599914 | AJ11: =SUM(AF11:AI11) -> -1885452 | AK11: =-463095-6748-AK13 -> -424962 | AL11: =-410665-7135-AL13 -> -369701 | AM11: =-450495-AM13-AM14 -> -407556 | AN11: =-1939257-SUM(AK11:AM11)-SUM(AK13:AN13)-SUM(AK14:AN14) -> -545529 | AO11: =SUM(AK11:AN11) -> -1747748 | AP11: =-317073-6374-AP13 -> -297842 | AQ11: =-458811-5796-AQ13 -> -435627 | AR11: =-520049-AR13-AR14 -> -481284 | AS11: =-2311230-SUM(AP11:AR11)-SUM(AP13:AS13)-SUM(AP14:AS14)+167000+67000 -> -735041 | AT11: =SUM(AP11:AS11) -> -1949794 | AU11: =-577017-6070+10468-AU13 -> -548776 | AV11: =-643682-5751+8996-AV13 -> -622178 | AW11: =-608648-5030-30212-AW13 -> -623728 | AX11: =-2715109-SUM(AU11:AW11)-SUM(AU13:AX13)-SUM(AU14:AX14) -> -823979 | AY11: =SUM(AU11:AX11) -> -2618661 | AZ11: =-469844-5517-24451-AZ13 -> -488169 | BA11: =-535625-2042-12517-BA13 -> -533358 | BB11: =-756657-13129-6433-BB13 -> -757962 | BC11: =-2573313-SUM(AZ11:BB11)-SUM(AZ13:BC13)-SUM(AZ14:BC14) -> -690696 | BD11: =SUM(AZ11:BC11) -> -2470185 | BE11: =-668863-8491+32132-BE13 -> -636211 | BF11: =-729733-9928+5283-BF13 -> -724002 | BG11: =-812566-4618-2520-BG13 -> -808109 | BH11: =-3125013-SUM(BE11:BG11)-SUM(BE13:BH13)-SUM(BE14:BH14) -> -846902 | BI11: =SUM(BE11:BH11) -> -3015224 | BJ11: =-852833-1569+23103-BJ13 -> -815032 | BK11: =-815979-3365-16232-BK13 -> -816065 | BL11: =-1002666-736-5819-BL13 -> -986430 | BM11: =-3678333-SUM(BJ11:BL11)-SUM(BJ13:BM13)-SUM(BJ14:BM14) -> -902868 | BN11: =SUM(BJ11:BM11) -> -3520395 | BO11: =-888554-284+9962-BO13 -> -854201 | BP11: =-1979270-547+1850-SUM(BO13:BP13)-BO11 -> -1068710 | BQ11: =-3045353-843-8169-SUM(BO13:BQ13)-SUM(BO11:BP11) -> -1046397 | BR11: =-4209100-SUM(BO11:BQ11)-SUM(BO13:BR13)-SUM(BO14:BR14) -> -1097346 | BS11: =SUM(BO11:BR11) -> -4066654 | BT11: =-1099469-734+32389-BT13 -> -1040695 | BU11: =-2326156-841+20515-SUM(BT13:BU13)-BT11 -> -1203470 | BV11: =-3680152-480+29360-SUM(BT13:BV13)-SUM(BT11:BU11) -> -1308936 | BW11: =-5385823-SUM(BT11:BV11)-SUM(BT13:BW13)-SUM(BT14:BW14) -> -1662991 | BX11: =SUM(BT11:BW11) -> -5216092 | BY11: =-1371838+103+63476-BY13 -> -1271764 | BZ11: =-2741584+532+19610-SUM(BY13:BZ13)-BY11 -> -1367612 | CA11: =-4073434-55402-13316-BZ11-BY11-CA13-BZ13-BY13 -> -1372087 | CB11: =-6353525-SUM(BY11:CA11)-SUM(BY13:CB13)-SUM(BY14:CB14) -> -2141389 | CC11: =SUM(BY11:CB11) -> -6152852 | CD11: =-1387597-7626+43725-CD13 -> -1286258 | CE11: =-2996523-10945+35263-SUM(CD13:CE13)-CD11 -> -1547952 | CF11: =-(1-CF12)*CF5 -> -1705336.8 | CG11: =-(1-CG12)*CG5 -> -1834948 | CH11: =SUM(CD11:CG11) -> -6374494.8 | CI11: =-(1-CI12)*CI5 -> -1726783.4 | CJ11: =-(1-CJ12)*CJ5 -> -1760741.4 | CK11: =-(1-CK12)*CK5 -> -1850633.8 | CL11: =-(1-CL12)*CL5 -> -1952239.7 | CM11: =SUM(CI11:CL11) -> -7290398.2 | CN11: =-(1-CN12)*CN5 -> -1948356.2 | CO11: =-(1-CO12)*CO5 -> -1971094.2 | CP11: =-(1-CP12)*CP5 -> -2052949.2 | CQ11: =-(1-CQ12)*CQ5 -> -2192848.5 | CR11: =SUM(CN11:CQ11) -> -8165248 | CS11: =-(1-CS12)*CS5 -> -2140428.7 | CT11: =-(1-CT12)*CT5 -> -2152106.9 | CU11: =-(1-CU12)*CU5 -> -2226492.9 | CV11: =-(1-CV12)*CV5 -> -2363859.1 | CW11: =SUM(CS11:CV11) -> -8882887.5 | CX11: =-(1-CX12)*CX5 -> -2306141.8 | CY11: =-(1-CY12)*CY5 -> -2311656.5 | CZ11: =-(1-CZ12)*CZ5 -> -2384865.1 | DA11: =-(1-DA12)*DA5 -> -2522426.7 | DB11: =SUM(CX11:DA11) -> -9525090.1
A12: Development gross margin (%) | B12: =(1+B11/B5) -> 0.37883928 | C12: =(1+C11/C5) -> 0.35928191 | D12: =(1+D11/D5) -> 0.38995335 | E12: =(1+E11/E5) -> 0.30720559 | F12: =(1+F11/F5) -> 0.35634728 | G12: =(1+G11/G5) -> 0.33569671 | H12: =(1+H11/H5) -> 0.3355713 | I12: =(1+I11/I5) -> 0.34851175 | ... CE12: =(1+CE11/CE5) -> 0.38195221 | CF12: =(IS!CF118*Operating!CF37+IS!CE110*Operating!CF39)/Operating!CF35 -> 0.36315214 | CG12: =(IS!CG118*Operating!CG37+IS!CF110*Operating!CG39)/Operating!CG35 -> 0.36340584 | CH12: =(1+CH11/CH5) -> 0.36979105 | CI12: =(IS!CI118*Operating!CI37+IS!CH110*Operating!CI39)/Operating!CI35 -> 0.36143655 | CJ12: =(IS!CJ118*Operating!CJ37+IS!CI110*Operating!CJ39)/Operating!CJ35 -> 0.36132149 | CK12: =(IS!CK118*Operating!CK37+IS!CJ110*Operating!CK39)/Operating!CK35 -> 0.36117589 | CL12: =(IS!CL118*Operating!CL37+IS!CK110*Operating!CL39)/Operating!CL35 -> 0.36104198 | CM12: =(1+CM11/CM5) -> 0.36123697 | CN12: =(IS!CN118*Operating!CN37+IS!CM110*Operating!CN39)/Operating!CN35 -> 0.35900024 | CO12: =(IS!CO118*Operating!CO37+IS!CN110*Operating!CO39)/Operating!CO35 -> 0.35870118 | CP12: =(IS!CP118*Operating!CP37+IS!CO110*Operating!CP39)/Operating!CP35 -> 0.35832158 | CQ12: =(IS!CQ118*Operating!CQ37+IS!CP110*Operating!CQ39)/Operating!CQ35 -> 0.35790646 | CR12: =(1+CR11/CR5) -> 0.35846394 | CS12: =(IS!CS118*Operating!CS37+IS!CR110*Operating!CS39)/Operating!CS35 -> 0.35765271 | CT12: =(IS!CT118*Operating!CT37+IS!CS110*Operating!CT39)/Operating!CT35 -> 0.35746968 | CU12: =(IS!CU118*Operating!CU37+IS!CT110*Operating!CU39)/Operating!CU35 -> 0.35723203 | CV12: =(IS!CV118*Operating!CV37+IS!CU110*Operating!CV39)/Operating!CV35 -> 0.35696616 | CW12: =(1+CW11/CW5) -> 0.35732033 | CX12: =(IS!CX118*Operating!CX37+IS!CW110*Operating!CX39)/Operating!CX35 -> 0.35688692 | CY12: =(IS!CY118*Operating!CY37+IS!CX110*Operating!CY39)/Operating!CY35 -> 0.35675318 | CZ12: =(IS!CZ118*Operating!CZ37+IS!CY110*Operating!CZ39)/Operating!CZ35 -> 0.35658199 | DA12: =(IS!DA118*Operating!DA37+IS!CZ110*Operating!DA39)/Operating!DA35 -> 0.35639373 | DB12: =(1+DB11/DB5) -> 0.35664756
A13: Capitalized interest expenses | B13: -9550 | C13: =-28872-B13 -> -19322 | D13: =-45963-C13-B13 -> -17091 | E13: =-96195-D13-C13-B13 -> -50232 | F13: =SUM(B13:E13) -> -96195 | G13: -39087 | H13: =-81451-G13 -> -42364 | I13: =-142196-G13-H13 -> -60745 | J13: -50000 | K13: =SUM(G13:J13) -> -192196 | L13: =-76289-M13 -> -40800 | M13: -35489 | N13: =-119322-L13-M13 -> -43033 | O13: =-178307-L13-M13-N13 -> -58985 | P13: =SUM(L13:O13) -> -178307 | Q13: -29979 | R13: =-62263-Q13 -> -32284 | S13: =-112043-Q13-R13 -> -49780 | T13: =-186376-SUM(Q13:S13) -> -74333 | U13: =SUM(Q13:T13) -> -186376 | V13: -48552 | W13: =-101289-V13 -> -52737 | X13: =-152526-V13-W13 -> -51237 | Y13: =-207728-SUM(V13:X13) -> -55202 | Z13: =SUM(V13:Y13) -> -207728 | AA13: -44065 | AB13: =-84900-AA13 -> -40835 | AC13: =-128001-AA13-AB13 -> -43101 | AD13: -43000 | AE13: =SUM(AA13:AD13) -> -171001 | AF13: -50357 | AG13: =-98404-AF13 -> -48047 | AH13: =-153560-AF13-AG13 -> -55156 | AI13: =-202752-SUM(AF13:AH13) -> -49192 | AJ13: =SUM(AF13:AI13) -> -202752 | AK13: -44881 | AL13: =-92980-AK13 -> -48099 | AM13: =-132347-AK13-AL13 -> -39367 | AN13: =-173966-SUM(AK13:AM13) -> -41619 | AO13: =SUM(AK13:AN13) -> -173966 | AP13: -25605 | AQ13: =-54585-AP13 -> -28980 | AR13: =-87467-AP13-AQ13 -> -32882 | AS13: -22250 | AT13: =SUM(AP13:AS13) -> -109717 | AU13: -23843 | AV13: =-42102-AU13 -> -18259 | AW13: =-62264-AU13-AV13 -> -20162 | AX13: =-81394-AW13-AV13-AU13 -> -19130 | AY13: =SUM(AU13:AX13) -> -81394 | AZ13: -11643 | BA13: =-28469-AZ13 -> -16826 | BB13: =-46726-AZ13-BA13 -> -18257 | BC13: =-67353-BB13-BA13-AZ13 -> -20627 | BD13: =SUM(AZ13:BC13) -> -67353 | BE13: -9011 | BF13: =-19387-BE13 -> -10376 | BG13: =-30982-BE13-BF13 -> -11595 | BH13: =-46249-BG13-BF13-BE13 -> -15267 | BI13: =SUM(BE13:BH13) -> -46249 | BJ13: -16267 | BK13: =-35778-BJ13 -> -19511 | BL13: =-58569-BJ13-BK13 -> -22791 | BM13: =-82014-BL13-BK13-BJ13 -> -23445 | BN13: =SUM(BJ13:BM13) -> -82014 | BO13: -24675 | BP13: =-55056-BO13 -> -30381 | BQ13: =-85057-BO13-BP13 -> -30001 | BR13: =-114687-BQ13-BP13-BO13 -> -29630 | BS13: =SUM(BO13:BR13) -> -114687 | BT13: -27119 | BU13: =-62317-BT13 -> -35198 | BV13: =-98171-BT13-BU13 -> -35854 | BW13: =-133989-BV13-BU13-BT13 -> -35818 | BX13: =SUM(BT13:BW13) -> -133989 | BY13: -36495 | BZ13: =-82066-BY13 -> -45571 | CA13: =-130689-BZ13-BY13 -> -48623 | CB13: =-178230-CA13-BZ13-BY13 -> -47541 | CC13: =SUM(BY13:CB13) -> -178230 | CD13: -65240 | CE13: =-137995-CD13 -> -72755 | CF13: =-('BS & FCF'!CE144/(Operating!CE26+Operating!CE27))*Operating!CF37-2%*Operating!CF39 -> -46224.914 | CG13: =-('BS & FCF'!CF144/(Operating!CF26+Operating!CF27))*Operating!CG37-2%*Operating!CG39 -> -50918.88 | CH13: =SUM(CD13:CG13) -> -235138.79 | CI13: =-('BS & FCF'!CH144/(Operating!CH26+Operating!CH27))*Operating!CI37-1.5%*Operating!CI39 -> -40384.913 | CJ13: =-('BS & FCF'!CI144/(Operating!CI26+Operating!CI27))*Operating!CJ37-1.5%*Operating!CJ39 -> -43619.307 | CK13: =-('BS & FCF'!CJ144/(Operating!CJ26+Operating!CJ27))*Operating!CK37-1.5%*Operating!CK39 -> -48174.93 | CL13: =-('BS & FCF'!CK144/(Operating!CK26+Operating!CK27))*Operating!CL37-1.5%*Operating!CL39 -> -52656.218 | CM13: =SUM(CI13:CL13) -> -184835.37 | CN13: =-('BS & FCF'!CM144/(Operating!CM26+Operating!CM27))*Operating!CN37-1%*Operating!CN39 -> -43612.154 | CO13: =-('BS & FCF'!CN144/(Operating!CN26+Operating!CN27))*Operating!CO37-1%*Operating!CO39 -> -45175.764 | CP13: =-('BS & FCF'!CO144/(Operating!CO26+Operating!CO27))*Operating!CP37-1%*Operating!CP39 -> -48885.282 | CQ13: =-('BS & FCF'!CP144/(Operating!CP26+Operating!CP27))*Operating!CQ37-1%*Operating!CQ39 -> -55426.339 | CR13: =SUM(CN13:CQ13) -> -193099.54 | CS13: =-('BS & FCF'!CR144/(Operating!CR26+Operating!CR27))*Operating!CS37-1%*Operating!CS39 -> -53590.166 | CT13: =-('BS & FCF'!CS144/(Operating!CS26+Operating!CS27))*Operating!CT37-1%*Operating!CT39 -> -53021.345 | CU13: =-('BS & FCF'!CT144/(Operating!CT26+Operating!CT27))*Operating!CU37-1%*Operating!CU39 -> -55103.295 | CV13: =-('BS & FCF'!CU144/(Operating!CU26+Operating!CU27))*Operating!CV37-1%*Operating!CV39 -> -61057.082 | CW13: =SUM(CS13:CV13) -> -222771.89 | CX13: =-('BS & FCF'!CW144/(Operating!CW26+Operating!CW27))*Operating!CX37-1%*Operating!CX39 -> -56012.706 | CY13: =-('BS & FCF'!CX144/(Operating!CX26+Operating!CX27))*Operating!CY37-1%*Operating!CY39 -> -55214.348 | CZ13: =-('BS & FCF'!CY144/(Operating!CY26+Operating!CY27))*Operating!CZ37-1%*Operating!CZ39 -> -57342.395 | DA13: =-('BS & FCF'!CZ144/(Operating!CZ26+Operating!CZ27))*Operating!DA37-1%*Operating!DA39 -> -63379.135 | DB13: =SUM(CX13:DA13) -> -231948.58
A14: Service costs | B14: -8575 | C14: -12823 | D14: -13205 | E14: -19509 | F14: =SUM(B14:E14) -> -54112 | G14: -18645 | H14: =-38200-G14 -> -19555 | I14: =-57248-G14-H14 -> -19048 | J14: =-62914-G14-H14-I14 -> -5666 | K14: =SUM(G14:J14) -> -62914 | L14: =-29450-M14 -> -12079 | M14: -17371 | N14: -8965 | O14: =-54752-L14-M14-N14 -> -16337 | P14: =SUM(L14:O14) -> -54752 | Q14: =-26407-R14 -> -12182 | R14: -14225 | S14: -14997 | T14: =-59195-SUM(Q14:S14) -> -17791 | U14: =SUM(Q14:T14) -> -59195 | V14: -11183 | W14: -10486 | X14: -14313 | Y14: =-45255-SUM(V14:X14) -> -9273 | Z14: =SUM(V14:Y14) -> -45255 | AA14: -11159 | AB14: -7261 | AC14: -7057 | AD14: =-35830-SUM(AA14:AC14) -> -10353 | AE14: =SUM(AA14:AD14) -> -35830 | AF14: -10585 | AG14: -22074 | AH14: -7177 | AI14: =-44583-SUM(AF14:AH14) -> -4747 | AJ14: =SUM(AF14:AI14) -> -44583 | AK14: -7527 | AL14: -3367 | AM14: -3572 | AN14: =-17543-SUM(AK14:AM14) -> -3077 | AO14: =SUM(AK14:AN14) -> -17543 | AP14: -2392 | AQ14: -3635 | AR14: -5883 | AS14: =-17719-SUM(AP14:AR14) -> -5809 | AT14: =SUM(AP14:AS14) -> -17719 | AU14: -4728 | AV14: -3225 | AW14: -1942 | AX14: =-15054-SUM(AU14:AW14) -> -5159 | AY14: =SUM(AU14:AX14) -> -15054 | AZ14: -4088 | BA14: -13753 | BB14: -8703 | BC14: =-35775-SUM(AZ14:BB14) -> -9231 | BD14: =SUM(AZ14:BC14) -> -35775 | BE14: -11970 | BF14: -15357 | BG14: -21739 | BH14: =-63540-SUM(BE14:BG14) -> -14474 | BI14: =SUM(BE14:BH14) -> -63540 | BJ14: -16803 | BK14: -23176 | BL14: -22039 | BM14: =-75924-SUM(BJ14:BL14) -> -13906 | BN14: =SUM(BJ14:BM14) -> -75924 | BO14: -10083 | BP14: =-16959-BO14 -> -6876 | BQ14: =-21084-SUM(BO14:BP14) -> -4125 | BR14: =-27759-SUM(BO14:BQ14) -> -6675 | BS14: =SUM(BO14:BR14) -> -27759 | BT14: -11575 | BU14: =-19737-BT14 -> -8162 | BV14: =-28433-SUM(BT14:BU14) -> -8696 | BW14: =-35742-SUM(BT14:BV14) -> -7309 | BX14: =SUM(BT14:BW14) -> -35742 | BY14: -10146 | BZ14: =-14257-BY14 -> -4111 | CA14: =-19579-BZ14-BY14 -> -5322 | CB14: =-22443-SUM(BY14:CA14) -> -2864 | CC14: =SUM(BY14:CB14) -> -22443 | CD14: -7609 | CE14: =-14854-CD14 -> -7245 | CF14: =-CF6*(1-CF15) -> -7745.999 | CG14: =-CG6*(1-CG15) -> -8338.0417 | CH14: =SUM(CD14:CG14) -> -30938.041 | CI14: =-CI6*(1-CI15) -> -7822.3414 | CJ14: =-CJ6*(1-CJ15) -> -7974.7343 | CK14: =-CK6*(1-CK15) -> -8379.964 | CL14: =-CL6*(1-CL15) -> -8838.1989 | CM14: =SUM(CI14:CL14) -> -33015.239 | CN14: =-CN6*(1-CN15) -> -8792.5215 | CO14: =-CO6*(1-CO15) -> -8890.9857 | CP14: =-CP6*(1-CP15) -> -9254.7294 | CQ14: =-CQ6*(1-CQ15) -> -9879.0067 | CR14: =SUM(CN14:CQ14) -> -36817.243 | CS14: =-CS6*(1-CS15) -> -9639.0409 | CT14: =-CT6*(1-CT15) -> -9688.8709 | CU14: =-CU6*(1-CU15) -> -10020.054 | CV14: =-CV6*(1-CV15) -> -10633.855 | CW14: =SUM(CS14:CV14) -> -39981.82 | CX14: =-CX6*(1-CX15) -> -10372.934 | CY14: =-CY6*(1-CY15) -> -10395.577 | CZ14: =-CZ6*(1-CZ15) -> -10721.945 | DA14: =-DA6*(1-DA15) -> -11337.081 | DB14: =SUM(CX14:DA14) -> -42827.537
A15: Services gross margin (%) | B15: =(1+B14/B6) -> 0.25577157 | C15: =(1+C14/C6) -> 0.20561269 | D15: =(1+D14/D6) -> 0.2627024 | E15: =(1+E14/E6) -> 0.37928731 | F15: =(1+F14/F6) -> 0.29728326 | G15: =(1+G14/G6) -> 0.19257752 | H15: =(1+H14/H6) -> 0.2388385 | I15: =(1+I14/I6) -> 0.41369121 | ... CE15: =(1+CE14/CE6) -> 0.83659983 | CF15: =CE15 -> 0.83659983 | CG15: =CF15 -> 0.83659983 | CH15: =(1+CH14/CH6) -> 0.82218847 | CI15: =CG15 -> 0.83659983 | CJ15: =CI15 -> 0.83659983 | CK15: =CJ15 -> 0.83659983 | CL15: =CK15 -> 0.83659983 | CM15: =(1+CM14/CM6) -> 0.83659983 | CN15: =CL15 -> 0.83659983 | CO15: =CN15 -> 0.83659983 | CP15: =CO15 -> 0.83659983 | CQ15: =CP15 -> 0.83659983 | CR15: =(1+CR14/CR6) -> 0.83659983 | CS15: =CQ15 -> 0.83659983 | CT15: =CS15 -> 0.83659983 | CU15: =CT15 -> 0.83659983 | CV15: =CU15 -> 0.83659983 | CW15: =(1+CW14/CW6) -> 0.83659983 | CX15: =CV15 -> 0.83659983 | CY15: =CX15 -> 0.83659983 | CZ15: =CY15 -> 0.83659983 | DA15: =CZ15 -> 0.83659983 | DB15: =(1+DB14/DB6) -> 0.83659983
A16: Gross profit | B16: =B9+B10 -> 394617 | C16: =C9+C10 -> 393041 | D16: =D9+D10 -> 408964 | E16: =E9+E10 -> 340008 | F16: =SUM(B16:E16) -> 1536630 | G16: =G9+G10 -> 328713 | H16: =H9+H10 -> 382496 | I16: =I9+I10 -> 445961 | J16: =J9+J10 -> 576320 | K16: =SUM(G16:J16) -> 1733490 | L16: =L9+L10 -> 459875 | M16: =M9+M10 -> 411571 | N16: =N9+N10 -> 428286 | O16: =O9+O10 -> 519080 | P16: =SUM(L16:O16) -> 1818812 | Q16: =Q9+Q10 -> 397020 | R16: =R9+R10 -> 447774 | S16: =S9+S10 -> 457250 | T16: =T9+T10 -> 457245 | U16: =SUM(Q16:T16) -> 1759289 | V16: =V9+V10 -> 437655 | W16: =W9+W10 -> 453552 | X16: =X9+X10 -> 482731 | Y16: =Y9+Y10 -> 494808 | Z16: =SUM(V16:Y16) -> 1868746 | AA16: =AA9+AA10 -> 360611 | AB16: =AB9+AB10 -> 399056 | AC16: =AC9+AC10 -> 394514 | AD16: =AD9+AD10 -> 348898 | AE16: =SUM(AA16:AD16) -> 1503079 | AF16: =AF9+AF10 -> 282261 | AG16: =AG9+AG10 -> 253930 | AH16: =AH9+AH10 -> 261421 | AI16: =AI9+AI10 -> 264911 | AJ16: =SUM(AF16:AI16) -> 1062523 | AK16: =AK9+AK10 -> 215017 | AL16: =AL9+AL10 -> 153589 | AM16: =AM9+AM10 -> 147332 | AN16: =AN9+AN10 -> 218575 | AO16: =SUM(AK16:AN16) -> 734513 | AP16: =AP9+AP10 -> 124783 | AQ16: =AQ9+AQ10 -> 171297 | AR16: =AR9+AR10 -> 204776 | AS16: =AS9+AS10 -> 314071 | AT16: =SUM(AP16:AS16) -> 814927 | AU16: =AU9+AU10 -> 248889 | AV16: =AV9+AV10 -> 292960 | AW16: =AW9+AW10 -> 288927 | AX16: =AX9+AX10 -> 384938 | AY16: =SUM(AU16:AX16) -> 1215714 | AZ16: =AZ9+AZ10 -> 260855 | BA16: =BA9+BA10 -> 274871 | BB16: =BB9+BB10 -> 378581 | BC16: =BC9+BC10 -> 336076 | BD16: =SUM(AZ16:BC16) -> 1250383 | BE16: =BE9+BE10 -> 346540 | BF16: =BF9+BF10 -> 432284 | BG16: =BG9+BG10 -> 446896 | BH16: =BH9+BH10 -> 440100 | BI16: =SUM(BE16:BH16) -> 1665820 | BJ16: =BJ9+BJ10 -> 383550 | BK16: =BK9+BK10 -> 391331 | BL16: =BL9+BL10 -> 528384 | BM16: =BM9+BM10 -> 430697 | BN16: =SUM(BJ16:BM16) -> 1733962 | BO16: =BO9+BO10 -> 394467 | BP16: =BP9+BP10 -> 527088 | BQ16: =BQ9+BQ10 -> 545464 | BR16: =BR9+BR10 -> 576580 | BS16: =SUM(BO16:BR16) -> 2043599 | BT16: =BT9+BT10 -> 493522 | BU16: =BU9+BU10 -> 610027 | BV16: =BV9+BV10 -> 676165 | BW16: =BW9+BW10 -> 800151 | BX16: =SUM(BT16:BW16) -> 2579865 | BY16: =BY9+BY10 -> 634339 | BZ16: =BZ9+BZ10 -> 689836 | CA16: =CA9+CA10 -> 702414 | CB16: =CB9+CB10 -> 1043380 | CC16: =SUM(BY16:CB16) -> 3069969 | CD16: =CD9+CD10 -> 665926 | CE16: =CE9+CE10 -> 852919 | CF16: =CF9+CF10 -> 897745.2 | CG16: =CG9+CG10 -> 965932.11 | CH16: =SUM(CD16:CG16) -> 3382522.3 | CI16: =CI9+CI10 -> 919808.04 | CJ16: =CJ9+CJ10 -> 934962.68 | CK16: =CK9+CK10 -> 979711.13 | CL16: =CL9+CL10 -> 1031027.8 | CM16: =SUM(CI16:CL16) -> 3865509.6 | CN16: =CN9+CN10 -> 1028265.2 | CO16: =CO9+CO10 -> 1037785.9 | CP16: =CP9+CP10 -> 1077167.5 | CQ16: =CQ9+CQ10 -> 1145166.6 | CR16: =SUM(CN16:CQ16) -> 4288385.3 | CS16: =CS9+CS10 -> 1116994.3 | CT16: =CT9+CT10 -> 1123001.5 | CU16: =CU9+CU10 -> 1160294.9 | CV16: =CV9+CV10 -> 1227815.7 | CW16: =SUM(CS16:CV16) -> 4628106.4 | CX16: =CX9+CX10 -> 1200951.2 | CY16: =CY9+CY10 -> 1204012.7 | CZ16: =CZ9+CZ10 -> 1240783.4 | DA16: =DA9+DA10 -> 1308484.5 | DB16: =SUM(CX16:DA16) -> 4954231.8
A17: Operating expenses | B17: =B18+B21+B23+B30+B34 -> -178833 | C17: =C18+C21+C23+C30+C34 -> -156810 | D17: =D18+D21+D23+D30+D34 -> -173217 | E17: =E18+E21+E23+E30+E34 -> -199860 | F17: =SUM(B17:E17) -> -708720 | G17: =G18+G21+G23+G30+G34 -> -196754 | H17: =H18+H21+H23+H30+H34 -> -228501 | I17: =I18+I21+I23+I30+I34 -> -221026 | J17: =J18+J21+J23+J30+J34 -> -306811 | K17: =SUM(G17:J17) -> -953092 | L17: =L18+L21+L23+L30+L34 -> -232954 | M17: =M18+M21+M23+M30+M34 -> -180102 | N17: =N18+N21+N23+N30+N34 -> -214192 | O17: =O18+O21+O23+O30+O34 -> -203195 | P17: =SUM(L17:O17) -> -830443 | Q17: =Q18+Q21+Q23+Q30+Q34 -> -161583 | R17: =R18+R21+R23+R30+R34 -> -189478 | S17: =S18+S21+S23+S30+S34 -> -196650 | T17: =T18+T21+T23+T30+T34 -> -187688 | U17: =SUM(Q17:T17) -> -735399 | V17: =V18+V21+V23+V30+V34 -> -209059 | W17: =W18+W21+W23+W30+W34 -> -202724 | X17: =X18+X21+X23+X30+X34 -> -222391 | Y17: =Y18+Y21+Y23+Y30+Y34 -> -258165 | Z17: =SUM(V17:Y17) -> -892339 | AA17: =AA18+AA21+AA23+AA30+AA34 -> -219357 | AB17: =AB18+AB21+AB23+AB30+AB34 -> -190079 | AC17: =AC18+AC21+AC23+AC30+AC34 -> -196105 | AD17: =AD18+AD21+AD23+AD30+AD34 -> -207134 | AE17: =SUM(AA17:AD17) -> -812675 | AF17: =AF18+AF21+AF23+AF30+AF34 -> -175144 | AG17: =AG18+AG21+AG23+AG30+AG34 -> -182593 | AH17: =AH18+AH21+AH23+AH30+AH34 -> -199948 | AI17: =AI18+AI21+AI23+AI30+AI34 -> -186495 | AJ17: =SUM(AF17:AI17) -> -744180 | AK17: =AK18+AK21+AK23+AK30+AK34 -> -165320 | AL17: =AL18+AL21+AL23+AL30+AL34 -> -273570 | AM17: =AM18+AM21+AM23+AM30+AM34 -> -118881 | AN17: =AN18+AN21+AN23+AN30+AN34 -> -122112 | AO17: =SUM(AK17:AN17) -> -679883 | AP17: =AP18+AP21+AP23+AP30+AP34 -> -147683 | AQ17: =AQ18+AQ21+AQ23+AQ30+AQ34 -> -176235 | AR17: =AR18+AR21+AR23+AR30+AR34 -> -283464 | AS17: =AS18+AS21+AS23+AS30+AS34 -> -132985 | AT17: =SUM(AP17:AS17) -> -740367 | AU17: =AU18+AU21+AU23+AU30+AU34 -> -169377 | AV17: =AV18+AV21+AV23+AV30+AV34 -> -131465 | AW17: =AW18+AW21+AW23+AW30+AW34 -> -145997 | AX17: =AX18+AX21+AX23+AX30+AX34 -> -148384 | AY17: =SUM(AU17:AX17) -> -595223 | AZ17: =AZ18+AZ21+AZ23+AZ30+AZ34 -> -195770 | BA17: =BA18+BA21+BA23+BA30+BA34 -> -165614 | BB17: =BB18+BB21+BB23+BB30+BB34 -> 1057582 | BC17: =BC18+BC21+BC23+BC30+BC34 -> -32202 | BD17: =SUM(AZ17:BC17) -> 663996 | BE17: =BE18+BE21+BE23+BE30+BE34 -> -120500 | BF17: =BF18+BF21+BF23+BF30+BF34 -> -120885 | BG17: =BG18+BG21+BG23+BG30+BG34 -> -154069 | BH17: =BH18+BH21+BH23+BH30+BH34 -> -164432 | BI17: =SUM(BE17:BH17) -> -559886 | BJ17: =BJ18+BJ21+BJ23+BJ30+BJ34 -> -186479 | BK17: =BK18+BK21+BK23+BK30+BK34 -> -199209 | BL17: =BL18+BL21+BL23+BL30+BL34 -> -186277 | BM17: =BM18+BM21+BM23+BM30+BM34 -> -180381 | BN17: =SUM(BJ17:BM17) -> -752346 | BO17: =BO18+BO21+BO23+BO30+BO34 -> -171430 | BP17: =BP18+BP21+BP23+BP30+BP34 -> -179239 | BQ17: =BQ18+BQ21+BQ23+BQ30+BQ34 -> -199818 | BR17: =BR18+BR21+BR23+BR30+BR34 -> -230901 | BS17: =SUM(BO17:BR17) -> -781388 | BT17: =BT18+BT21+BT23+BT30+BT34 -> -141678 | BU17: =BU18+BU21+BU23+BU30+BU34 -> -90783 | BV17: =BV18+BV21+BV23+BV30+BV34 -> -83457 | BW17: =BW18+BW21+BW23+BW30+BW34 -> -65465 | BX17: =SUM(BT17:BW17) -> -381383 | BY17: =BY18+BY21+BY23+BY30+BY34 -> -196376 | BZ17: =BZ18+BZ21+BZ23+BZ30+BZ34 -> -161100 | CA17: =CA18+CA21+CA23+CA30+CA34 -> 36389 | CB17: =CB18+CB21+CB23+CB30+CB34 -> -205022 | CC17: =SUM(BY17:CB17) -> -526109 | CD17: =CD18+CD21+CD23+CD30+CD34 -> -254645 | CE17: =CE18+CE21+CE23+CE30+CE34 -> -279186 | CF17: =CF18+CF21+CF23+CF30+CF34 -> -239923.32 | CG17: =CG18+CG21+CG23+CG30+CG34 -> -216697.38 | CH17: =SUM(CD17:CG17) -> -990451.7 | CI17: =CI18+CI21+CI23+CI30+CI34 -> -177121 | CJ17: =CJ18+CJ21+CJ23+CJ30+CJ34 -> -235967.21 | CK17: =CK18+CK21+CK23+CK30+CK34 -> -256236.37 | CL17: =CL18+CL21+CL23+CL30+CL34 -> -231962.64 | CM17: =SUM(CI17:CL17) -> -901287.21 | CN17: =CN18+CN21+CN23+CN30+CN34 -> -174573.79 | CO17: =CO18+CO21+CO23+CO30+CO34 -> -247897.03 | CP17: =CP18+CP21+CP23+CP30+CP34 -> -282346.99 | CQ17: =CQ18+CQ21+CQ23+CQ30+CQ34 -> -275015.97 | CR17: =SUM(CN17:CQ17) -> -979833.78 | CS17: =CS18+CS21+CS23+CS30+CS34 -> -198802.48 | CT17: =CT18+CT21+CT23+CT30+CT34 -> -273823.59 | CU17: =CU18+CU21+CU23+CU30+CU34 -> -304611.87 | CV17: =CV18+CV21+CV23+CV30+CV34 -> -299734.86 | CW17: =SUM(CS17:CV17) -> -1076972.8 | CX17: =CX18+CX21+CX23+CX30+CX34 -> -197644.85 | CY17: =CY18+CY21+CY23+CY30+CY34 -> -280386.18 | CZ17: =CZ18+CZ21+CZ23+CZ30+CZ34 -> -307742.21 | DA17: =DA18+DA21+DA23+DA30+DA34 -> -296732.49 | DB17: =SUM(CX17:DA17) -> -1082505.7
A18: Selling expenses | B18: -94188 | C18: -103019 | D18: -103927 | E18: -100686 | F18: =SUM(B18:E18) -> -401820 | G18: -112616 | H18: =-255554-G18 -> -142938 | I18: =-377323-G18-H18 -> -121769 | J18: =-511246-G18-H18-I18 -> -133923 | K18: =SUM(G18:J18) -> -511246 | L18: =-219037-M18 -> -109229 | M18: -109808 | N18: -110247 | O18: =-457139-L18-M18-N18 -> -127855 | P18: =SUM(L18:O18) -> -457139 | Q18: =-195945-R18 -> -92544 | R18: -103401 | S18: -113426 | T18: =-431373-SUM(Q18:S18) -> -122002 | U18: =SUM(Q18:T18) -> -431373 | V18: -105875 | W18: -110796 | X18: -118305 | Y18: =-466628-SUM(V18:X18) -> -131652 | Z18: =SUM(V18:Y18) -> -466628 | AA18: -107499 | AB18: -114777 | AC18: -119917 | AD18: =-459538-SUM(AA18:AC18) -> -117345 | AE18: =SUM(AA18:AD18) -> -459538 | AF18: -102376 | AG18: -94828 | AH18: -101971 | AI18: =-400579-SUM(AF18:AH18) -> -101404 | AJ18: =SUM(AF18:AI18) -> -400579 | AK18: -87376 | AL18: -87704 | AM18: -88456 | AN18: =-343283-SUM(AK18:AM18) -> -79747 | AO18: =SUM(AK18:AN18) -> -343283 | AP18: -73073 | AQ18: -84139 | AR18: -87973 | AS18: =-332795-SUM(AP18:AR18) -> -87610 | AT18: =SUM(AP18:AS18) -> -332795 | AU18: -87514 | AV18: -98449 | AW18: -95474 | AX18: =-382005-SUM(AU18:AW18) -> -100568 | AY18: =SUM(AU18:AX18) -> -382005 | AZ18: -90755 | BA18: -89321 | BB18: -71523 | BC18: =-326318-SUM(AZ18:BB18) -> -74719 | BD18: =SUM(AZ18:BC18) -> -326318 | BE18: -70578 | BF18: -75141 | BG18: -94562 | BH18: =-347846-SUM(BE18:BG18) -> -107565 | BI18: =SUM(BE18:BH18) -> -347846 | BJ18: -97954 | BK18: -108144 | BL18: -152389 | BM18: =-514969-SUM(BJ18:BL18) -> -156482 | BN18: =SUM(BJ18:BM18) -> -514969 | BO18: -142049 | BP18: -155437 | BQ18: -155053 | BR18: =-628585-SUM(BO18:BQ18) -> -176046 | BS18: =SUM(BO18:BR18) -> -628585 | BT18: -153798 | BU18: -147794 | BV18: -170109 | BW18: =-659284-SUM(BT18:BV18) -> -187583 | BX18: =SUM(BT18:BW18) -> -659284 | BY18: -200780 | BZ18: -225655 | CA18: -237709 | CB18: =-938220-SUM(BY18:CA18) -> -274076 | CC18: =SUM(BY18:CB18) -> -938220 | CD18: -276768 | CE18: -293757 | CF18: =-CF20*(Operating!CF15+Operating!CF17) -> -270429.69 | CG18: =-CG20*(Operating!CG15+Operating!CG17) -> -285969.01 | CH18: =SUM(CD18:CG18) -> -1126923.7 | CI18: =-CI20*(Operating!CI15+Operating!CI17) -> -275710.84 | CJ18: =-CJ20*(Operating!CJ15+Operating!CJ17) -> -279195.59 | CK18: =-CK20*(Operating!CK15+Operating!CK17) -> -300964.49 | CL18: =-CL20*(Operating!CL15+Operating!CL17) -> -315326.89 | CM18: =SUM(CI18:CL18) -> -1171197.8 | CN18: =-CN20*(Operating!CN15+Operating!CN17) -> -286839.33 | CO18: =-CO20*(Operating!CO15+Operating!CO17) -> -302528.99 | CP18: =-CP20*(Operating!CP15+Operating!CP17) -> -325416.41 | CQ18: =-CQ20*(Operating!CQ15+Operating!CQ17) -> -360445.14 | CR18: =SUM(CN18:CQ18) -> -1275229.9 | CS18: =-CS20*(Operating!CS15+Operating!CS17) -> -307495.44 | CT18: =-CT20*(Operating!CT15+Operating!CT17) -> -322259.34 | CU18: =-CU20*(Operating!CU15+Operating!CU17) -> -345289.24 | CV18: =-CV20*(Operating!CV15+Operating!CV17) -> -381401.39 | CW18: =SUM(CS18:CV18) -> -1356445.4 | CX18: =-CX20*(Operating!CX15+Operating!CX17) -> -313583.08 | CY18: =-CY20*(Operating!CY15+Operating!CY17) -> -330767.09 | CZ18: =-CZ20*(Operating!CZ15+Operating!CZ17) -> -356089.49 | DA18: =-DA20*(Operating!DA15+Operating!DA17) -> -394575.27 | DB18: =SUM(CX18:DA18) -> -1395014.9
A19: % of net revenues | B19: =-B18/B9 -> 0.083172031 | C19: =-C18/C9 -> 0.085433745 | D19: =-D18/D9 -> 0.089395802 | E19: =-E18/E9 -> 0.072473877 | F19: =-F18/F9 -> 0.082170015 | G19: =-G18/G9 -> 0.093788674 | H19: =-H18/H9 -> 0.10336225 | I19: =-I18/I9 -> 0.078076971 | ... DB19: =-DB18/DB9 -> 0.094551014
A20: % of net sales | B20: =-B18/Operating!B9 -> 0.088377066 | C20: =-C18/Operating!C9 -> 0.066899728 | D20: =-D18/Operating!D9 -> 0.10135567 | E20: =-E18/Operating!E9 -> 0.039618547 | F20: =-F18/Operating!F9 -> 0.065099389 | G20: =-G18/Operating!G9 -> 0.11277108 | H20: =-H18/Operating!H9 -> 0.085692493 | I20: =-I18/Operating!I9 -> 0.084053149 | ... K20: =-K18/Operating!K9 -> 0.078688338 | L20: =-L18/(Operating!L15+Operating!L17) -> 0.080922257 | M20: =-M18/(Operating!M15+Operating!M17) -> 0.07679691 | N20: =-N18/(Operating!N15+Operating!N17) -> 0.059099441 | O20: =-O18/(Operating!O15+Operating!O17) -> 0.070075076 | P20: =-P18/(Operating!P15+Operating!P17) -> 0.070659075 | Q20: =-Q18/(Operating!Q15+Operating!Q17) -> 0.062985015 | R20: =-R18/(Operating!R15+Operating!R17) -> 0.04501089 | S20: =-S18/(Operating!S15+Operating!S17) -> 0.07615583 | ... CE20: =-CE18/(Operating!CE15+Operating!CE17) -> 0.071875948 | CF20: 0.065 | CG20: 0.065 | CH20: =-CH18/(Operating!CH15+Operating!CH17) -> 0.070021443 | CI20: 0.065 | CJ20: =CI20 -> 0.065 | CK20: =CJ20 -> 0.065 | CL20: =CK20 -> 0.065 | CM20: =-CM18/(Operating!CM15+Operating!CM17) -> 0.065 | CN20: 0.065 | CO20: =CN20 -> 0.065 | CP20: =CO20 -> 0.065 | CQ20: =CP20 -> 0.065 | CR20: =-CR18/(Operating!CR15+Operating!CR17) -> 0.065 | CS20: =CN20 -> 0.065 | CT20: =CO20 -> 0.065 | CU20: =CP20 -> 0.065 | CV20: =CQ20 -> 0.065 | CW20: =-CW18/(Operating!CW15+Operating!CW17) -> 0.065 | CX20: =CS20 -> 0.065 | CY20: =CT20 -> 0.065 | CZ20: =CU20 -> 0.065 | DA20: =CV20 -> 0.065 | DB20: =-DB18/(Operating!DB15+Operating!DB17) -> 0.065
