Workbook
Name _1_0BS_minor: #REF!
Name _1_0BS_minor: #REF!
Name _10_0Interc_Rev_Loc_: #REF!
Name _10_0IS_straightpref: #REF!
Name _10_0IS_straightpref: #REF!
Name _105J–Ï__íÇ: #REF!,#REF!,#REF!,#REF!,#REF!,#REF!,#REF!,#REF!,#REF!,#REF!,#REF!,#REF!
Name _106_0: #REF!,#REF!,#REF!,#REF!,#REF!,#REF!,#REF!,#REF!,#REF!,#REF!,#REF!,#REF!,#REF!,#REF!
Name _106J–Ï__íÇ: #REF!,#REF!,#REF!,#REF!,#REF!,#REF!,#REF!,#REF!,#REF!,#REF!,#REF!,#REF!
Name _106J–Ï__íÇ: #REF!,#REF!,#REF!,#REF!,#REF!,#REF!,#REF!,#REF!,#REF!,#REF!,#REF!,#REF!
Name _107_0: #REF!,#REF!,#REF!,#REF!,#REF!,#REF!,#REF!,#REF!,#REF!,#REF!,#REF!,#REF!,#REF!,#REF!
Name _107_0: #REF!,#REF!,#REF!,#REF!,#REF!,#REF!,#REF!,#REF!,#REF!,#REF!,#REF!,#REF!,#REF!,#REF!
Name _107_0_0BS_minor: #REF!
Name _108_0_0BS_minor: #REF!
Name _108_0_0CF_minor: #REF!
Name _109_0_0CF_minor: #REF!
Name _109_0_0IS_convpref: #REF!
Name _11_0Interc_Rev_LD_: #REF!
Name _11_0OutGoingTraf: #REF!
Name _110_0_0IS_convpref: #REF!
Name _110_0_0IS_intconv: #REF!
Name _111_0_0IS_intconv: #REF!
Name _111_0_0IS_intexist: #REF!
Name _112_0_0IS_intexist: #REF!
Name _112_0_0IS_minor: #REF!
Name _113_0_0IS_minor: #REF!
Name _113_0_0IS_straightpref: #REF!
Name _114_0_0IS_straightpref: #REF!
Name _114_0_0IS_synerg: #REF!
Name _115_0_0IS_synerg: #REF!
Name _115_0IS_synerg: #REF!
Name _116_0IS_synerg: #REF!
Name _116_0s: #REF!
Name _117_0s: #REF!
Name _117_0Sfu: #REF!
Name _118_0Sfu: #REF!
Name _118_1: #REF!
Name _119_1: #REF!
Name _119_1: #REF!
Name _119_10: #REF!
Name _12_0Interc_Rev_Loc_: #REF!
Name _12_0Interc_Rev_Loc_: #REF!
Name _12_0Perc_Reg_of: #REF!
Name _120_10: #REF!
Name _120_10: #REF!
Name _120_11: #REF!
Name _121_11: #REF!
Name _121_11: #REF!
Name _121_12: #REF!
Name _122_12: #REF!
Name _122_13: #REF!
Name _123_13: #REF!
Name _123_14: #REF!
Name _124_14: #REF!
Name _124_15: #REF!
Name _125_15: #REF!
Name _125_16: #REF!
Name _126_16: #REF!
Name _126_17: #REF!
Name _127_17: #REF!
Name _127_18: #REF!

Sheet Macro
A2: =DCF!$A$2 -> Cyrela - TP: R$35
A3: Status | B3: =B4&RIGHT(B5,2)&B6 -> 1Q04 | C3: =C4&RIGHT(C5,2)&C6 -> 2Q04 | D3: =D4&RIGHT(D5,2)&D6 -> 3Q04 | E3: =E4&RIGHT(E5,2)&E6 -> 4Q04 | F3: =F4&RIGHT(F5,2)&F6 -> 2004 | G3: =G4&RIGHT(G5,2)&G6 -> 1Q05 | H3: =H4&RIGHT(H5,2)&H6 -> 2Q05 | I3: =I4&RIGHT(I5,2)&I6 -> 3Q05 | ... EF3: =EF4&RIGHT(EF5,2)&EF6 -> 2030E
A4: Quarter | B4: 1Q | C4: 2Q | D4: 3Q | E4: 4Q | F4: 20 | G4: 1Q | H4: 2Q | I4: 3Q | J4: 4Q | K4: 20 | L4: 1Q | M4: 2Q | N4: 3Q | O4: 4Q | P4: 20 | Q4: 1Q | R4: 2Q | S4: 3Q | T4: 4Q | U4: 20 | V4: 1Q | W4: 2Q | X4: 3Q | Y4: 4Q | Z4: 20 | AA4: 1Q | AB4: 2Q | AC4: 3Q | AD4: 4Q | AE4: 20 | AF4: 1Q | AG4: 2Q | AH4: 3Q | AI4: 4Q | AJ4: 20 | AK4: 1Q | AL4: 2Q | AM4: 3Q | AN4: 4Q | AO4: 20 | AP4: 1Q | AQ4: 2Q | AR4: 3Q | AS4: 4Q | AT4: 20 | AU4: 1Q | AV4: 2Q | AW4: 3Q | AX4: 4Q | AY4: 20 | AZ4: 1Q | BA4: 2Q | BB4: 3Q | BC4: 4Q | BD4: 20 | BE4: 1Q | BF4: 2Q | BG4: 3Q | BH4: 4Q | BI4: 20 | BJ4: 1Q | BK4: 2Q | BL4: 3Q | BM4: 4Q | BN4: 20 | BO4: 1Q | BP4: 2Q | BQ4: 3Q | BR4: 4Q | BS4: 20 | BT4: 1Q | BU4: 2Q | BV4: 3Q | BW4: 4Q | BX4: 20 | BY4: 1Q | BZ4: 2Q | CA4: 3Q | CB4: 4Q | CC4: 20 | CD4: 1Q | CE4: 2Q | CF4: 3Q | CG4: 4Q | CH4: 20 | CI4: 1Q | CJ4: 2Q | CK4: 3Q | CL4: 4Q | CM4: 20 | CN4: 1Q | CO4: 2Q | CP4: 3Q | CQ4: 4Q | CR4: 20 | CS4: 1Q | CT4: 2Q | CU4: 3Q | CV4: 4Q | CW4: 20 | CX4: 1Q | CY4: 2Q | CZ4: 3Q | DA4: 4Q | DB4: 20 | DC4: 1Q | DD4: 2Q | DE4: 3Q | DF4: 4Q | DG4: 20 | DH4: 1Q | DI4: 2Q | DJ4: 3Q | DK4: 4Q | DL4: 20 | DM4: 1Q | DN4: 2Q | DO4: 3Q | DP4: 4Q | DQ4: 20 | DR4: 1Q | DS4: 2Q | DT4: 3Q | DU4: 4Q | DV4: 20 | DW4: 1Q | DX4: 2Q | DY4: 3Q | DZ4: 4Q | EA4: 20 | EB4: 1Q | EC4: 2Q | ED4: 3Q | EE4: 4Q | EF4: 20
A5: Year | B5: 2004 | C5: 2004 | D5: 2004 | E5: 2004 | F5: =E5 -> 2004 | G5: =B5+1 -> 2005 | H5: =C5+1 -> 2005 | I5: =D5+1 -> 2005 | J5: =E5+1 -> 2005 | K5: =J5 -> 2005 | L5: =G5+1 -> 2006 | M5: =H5+1 -> 2006 | N5: =I5+1 -> 2006 | O5: =J5+1 -> 2006 | P5: =O5 -> 2006 | Q5: =L5+1 -> 2007 | R5: =M5+1 -> 2007 | S5: =N5+1 -> 2007 | T5: =O5+1 -> 2007 | U5: =T5 -> 2007 | V5: =Q5+1 -> 2008 | W5: =R5+1 -> 2008 | X5: =S5+1 -> 2008 | Y5: =T5+1 -> 2008 | Z5: =Y5 -> 2008 | AA5: =V5+1 -> 2009 | AB5: =W5+1 -> 2009 | AC5: =X5+1 -> 2009 | AD5: =Y5+1 -> 2009 | AE5: =AD5 -> 2009 | AF5: =AA5+1 -> 2010 | AG5: =AB5+1 -> 2010 | AH5: =AC5+1 -> 2010 | AI5: =AD5+1 -> 2010 | AJ5: =AI5 -> 2010 | AK5: =AF5+1 -> 2011 | AL5: =AG5+1 -> 2011 | AM5: =AH5+1 -> 2011 | AN5: =AI5+1 -> 2011 | AO5: =AN5 -> 2011 | AP5: =AK5+1 -> 2012 | AQ5: =AL5+1 -> 2012 | AR5: =AM5+1 -> 2012 | AS5: =AN5+1 -> 2012 | AT5: =AO5+1 -> 2012 | AU5: =AP5+1 -> 2013 | AV5: =AQ5+1 -> 2013 | AW5: =AR5+1 -> 2013 | ... EF5: =EA5+1 -> 2030
A6: Actual/Estimate | DJ6: E | DK6: E | DL6: E | DM6: E | DN6: E | DO6: E | DP6: E | DQ6: E | DR6: E | DS6: E | DT6: E | DU6: E | DV6: E | DW6: E | DX6: E | DY6: E | DZ6: E | EA6: E | EB6: E | EC6: E | ED6: E | EE6: E | EF6: E
A7: Days in Quarter | B7: 91 | C7: 91 | D7: 92 | E7: 92 | F7: =SUM(B7:E7) -> 366 | G7: 90 | H7: 91 | I7: 92 | J7: 92 | K7: =SUM(G7:J7) -> 365 | L7: 90 | M7: 91 | N7: 92 | O7: 92 | P7: =SUM(L7:O7) -> 365 | Q7: 90 | R7: 91 | S7: 92 | T7: 92 | U7: =SUM(Q7:T7) -> 365 | V7: 91 | W7: 91 | X7: 92 | Y7: 92 | Z7: =SUM(V7:Y7) -> 366 | AA7: 90 | AB7: 91 | AC7: 92 | AD7: 92 | AE7: =SUM(AA7:AD7) -> 365 | AF7: 90 | AG7: 91 | AH7: 92 | AI7: 92 | AJ7: =SUM(AF7:AI7) -> 365 | AK7: 90 | AL7: 91 | AM7: 92 | AN7: 92 | AO7: =SUM(AK7:AN7) -> 365 | AP7: 90 | AQ7: 91 | AR7: 92 | AS7: 92 | AT7: 366 | AU7: 90 | AV7: 91 | AW7: 92 | AX7: 92 | AY7: =SUM(AU7:AX7) -> 365 | AZ7: 90 | BA7: 91 | BB7: 92 | BC7: 92 | BD7: =SUM(AZ7:BC7) -> 365 | BE7: 90 | BF7: 91 | BG7: 92 | BH7: 92 | BI7: =SUM(BE7:BH7) -> 365 | BJ7: 90 | BK7: 91 | BL7: 92 | BM7: 92 | BN7: =SUM(BJ7:BM7) -> 365 | BO7: 90 | BP7: 91 | BQ7: 92 | BR7: 92 | BS7: =SUM(BO7:BR7) -> 365 | BT7: 90 | BU7: 91 | BV7: 92 | BW7: 92 | BX7: =SUM(BT7:BW7) -> 365 | BY7: 90 | BZ7: 91 | CA7: 92 | CB7: 92 | CC7: =SUM(BY7:CB7) -> 365 | CD7: 90 | CE7: 91 | CF7: 92 | CG7: 92 | CH7: =SUM(CD7:CG7) -> 365 | CI7: 90 | CJ7: 91 | CK7: 92 | CL7: 92 | CM7: =SUM(CI7:CL7) -> 365 | CN7: 90 | CO7: 91 | CP7: 92 | CQ7: 92 | CR7: =SUM(CN7:CQ7) -> 365 | CS7: 90 | CT7: 91 | CU7: 92 | CV7: 92 | CW7: =SUM(CS7:CV7) -> 365 | CX7: 90 | CY7: 91 | CZ7: 92 | DA7: 92 | DB7: =SUM(CX7:DA7) -> 365 | DC7: 90 | DD7: 91 | DE7: 92 | DF7: 92 | DG7: =SUM(DC7:DF7) -> 365 | DH7: 90 | DI7: 91 | DJ7: 92 | DK7: 92 | DL7: =SUM(DH7:DK7) -> 365 | DM7: 90 | DN7: 91 | DO7: 92 | DP7: 92 | DQ7: =SUM(DM7:DP7) -> 365 | DR7: 90 | DS7: 91 | DT7: 92 | DU7: 92 | DV7: =SUM(DR7:DU7) -> 365 | DW7: 90 | DX7: 91 | DY7: 92 | DZ7: 92 | EA7: =SUM(DW7:DZ7) -> 365 | EB7: 90 | EC7: 91 | ED7: 92 | EE7: 92 | EF7: =SUM(EB7:EE7) -> 365
A9: Macro variables | B9: =B$3 -> 1Q04 | C9: =C$3 -> 2Q04 | D9: =D$3 -> 3Q04 | E9: =E$3 -> 4Q04 | F9: =F$3 -> 2004 | G9: =G$3 -> 1Q05 | H9: =H$3 -> 2Q05 | I9: =I$3 -> 3Q05 | ... EF9: =EF$3 -> 2030E
A10: GDP Growth | B10: 0.018625076 | C10: 0.034978624 | D10: 0.046182359 | E10: 0.05690445 | F10: 0.05690445 | G10: 0.050839899 | H10: 0.040117662 | I10: 0.035368516 | J10: 0.031478279 | K10: 0.031478279 | L10: 0.035123174 | M10: 0.03287402 | N10: 0.035871317 | O10: 0.039296141 | P10: 0.039296141 | Q10: 0.041838309 | R10: 0.05276138 | S10: 0.0558906 | T10: 0.060872371 | U10: 0.060872371 | V10: 0.063938236 | W10: 0.063785439 | X10: 0.066447177 | Y10: 0.051439409 | Z10: 0.051439409 | AA10: 0.029907003 | AB10: 0.0094328172 | AC10: -0.010336182 | AD10: -0.0017527142 | AE10: -0.0017527142 | AF10: 0.092714294 | AG10: 0.091562714 | AH10: 0.067385174 | AI10: 0.050367589 | AJ10: 0.075 | AK10: 0.04235654 | AL10: 0.03314358 | AM10: 0.021219664 | AN10: 0.013664596 | AO10: 0.027325092 | AP10: 0.007973 | AQ10: 0.005509 | AR10: 0.009444 | AS10: 0.01825 | AT10: 0.01 | AU10: 0.0189 | AV10: 0.0346 | AW10: 0.0243 | AX10: 0.0217 | AY10: 0.025 | AZ10: 0.0191 | BA10: 0.004 | BB10: 0.011 | BC10: 0.01 | BD10: 0.0014458389 | BE10: -0.0081656208 | BF10: -0.017777081 | BG10: -0.02738854 | BH10: -0.037 | BI10: -0.037 | BJ10: -0.03475 | BK10: -0.0325 | BL10: -0.03025 | BM10: -0.028 | BN10: -0.028 | BO10: 0.005 | BP10: 0.005 | BQ10: 0.005 | BR10: 0.005 | BS10: 0.01 | BT10: 0.0032837896 | BU10: 0.0032837896 | BV10: 0.0032837896 | BW10: 0.0032837896 | BX10: 0.0132 | BY10: 0.0027387285 | BZ10: 0.0027387285 | CA10: 0.0027387285 | CB10: 0.0027387285 | CC10: 0.011 | CD10: -0.01 | CE10: -0.01 | CF10: -0.01 | CG10: -0.01 | CH10: -0.041 | CI10: 0.03 | CJ10: 0.03 | CK10: 0.03 | CL10: 0.03 | CM10: 0.046 | CN10: 0.02 | CO10: 0.02 | CP10: 0.02 | CQ10: 0.02 | CR10: 0.03 | CS10: 0.02 | CT10: 0.02 | CU10: 0.02 | CV10: 0.02 | CW10: 0.029 | CX10: 0.02 | CY10: 0.02 | CZ10: 0.02 | DA10: 0.02 | DB10: 0.034 | DC10: 0.02 | DD10: 0.02 | DE10: 0.02 | DF10: 0.02 | DG10: 0.02 | DH10: 0.02 | DI10: 0.02 | DJ10: 0.02 | DK10: 0.02 | DL10: 0.02 | DM10: 0.02 | DN10: 0.02 | DO10: 0.02 | DP10: 0.02 | DQ10: 0.02 | DR10: 0.02 | DS10: 0.02 | DT10: 0.02 | DU10: 0.02 | DV10: 0.02 | DW10: 0.02 | DX10: 0.02 | DY10: 0.02 | DZ10: 0.02 | EA10: 0.02 | EB10: 0.02 | EC10: 0.02 | ED10: 0.02 | EE10: 0.02 | EF10: 0.02
A11: R$/US$ EoP | B11: 2.9086 | C11: 3.1075 | D11: 2.8586 | E11: 2.6544 | F11: 2.6544 | G11: 2.6662 | H11: 2.3504 | I11: 2.2222 | J11: 2.3407 | K11: 2.3407 | L11: 2.1724 | M11: 2.1643 | N11: 2.1742 | O11: 2.138 | P11: 2.138 | Q11: 2.0504 | R11: 1.9262 | S11: 1.8389 | T11: 1.7713 | U11: 1.7713 | V11: 1.7491 | W11: 1.5919 | X11: 1.9143 | Y11: 2.337 | Z11: 2.337 | AA11: 2.3152 | AB11: 1.9516 | AC11: 1.7781 | AD11: 1.7412 | AE11: 1.7412 | AF11: 1.781 | AG11: 1.8015 | AH11: 1.6942 | AI11: 1.7161 | AJ11: 1.6662 | AK11: 1.6318 | AL11: 1.5633 | AM11: 1.8793 | AN11: 1.8668 | AO11: 1.8758 | AP11: 1.82 | AQ11: 2.02 | AR11: 2.03 | AS11: 2.04 | AT11: 2.04 | AU11: 2.0138 | AV11: 2.2156 | AW11: 2.23 | AX11: 2.3426 | AY11: 2.34 | AZ11: 2.263 | BA11: 2.29 | BB11: 2.34 | BC11: 2.4 | BD11: 2.6562 | BE11: 3.208 | BF11: 3.1026 | BG11: 3.9729 | BH11: 3.9048 | BI11: 3.8 | BJ11: 3.5589 | BK11: 3.2098 | BL11: 3.2462 | BM11: 3.2591 | BN11: 3.2591 | BO11: 3.2 | BP11: 3.12 | BQ11: 3.31 | BR11: 3.308 | BS11: 3.308 | BT11: 3.3238 | BU11: 3.8558 | BV11: 4.0039 | BW11: 3.88 | BX11: 3.88 | BY11: 3.9017478 | BZ11: 3.9236175 | CA11: 3.9456098 | CB11: 3.9677253 | CC11: 4.0307 | CD11: 5 | CE11: 5.0084136 | CF11: 5.0168413 | CG11: 5.0252832 | CH11: 4.8 | CI11: 4.872642 | CJ11: 4.9463833 | CK11: 5.0212406 | CL11: 5.0972308 | CM11: 5.5805 | CN11: 5.6316783 | CO11: 5.683326 | CP11: 5.7354473 | CQ11: 5.7880467 | CR11: 5.2177 | CS11: 5.2508591 | CT11: 5.284229 | CU11: 5.3178109 | CV11: 5.3516063 | CW11: 4.8513 | CX11: 4.8845909 | CY11: 4.9181102 | CZ11: 4.9518595 | DA11: 4.9858404 | DB11: 6.1923 | DC11: 5.9623333 | DD11: 5.7323667 | DE11: 5.6173833 | DF11: 5.5024 | DG11: 5.5024 | DH11: 5.5291054 | DI11: 5.5559404 | DJ11: 5.5829056 | DK11: 5.6100017 | DL11: 5.6100017 | DM11: 5.6372293 | DN11: 5.6645891 | DO11: 5.6920817 | DP11: 5.7197077 | DQ11: 5.7197077 | DR11: 5.7474677 | DS11: 5.7753625 | DT11: 5.8033927 | DU11: 5.8315589 | DV11: 5.8315589 | DW11: 5.8598619 | DX11: 5.8883021 | DY11: 5.9168805 | DZ11: 5.9455975 | EA11: 5.9455975 | EB11: 5.9744539 | EC11: 6.0034503 | ED11: 6.0325875 | EE11: 6.0618661 | EF11: 6.0618661
A12: Sequential Change | B12: 0.0067146615 | C12: 0.068383415 | D12: -0.080096541 | E12: -0.071433569 | F12: -0.081268171 | G12: 0.0044454491 | H12: -0.11844573 | I12: -0.054543907 | J12: 0.053325533 | K12: -0.11818113 | L12: -0.071901568 | M12: -0.0037285951 | N12: 0.0045742272 | O12: -0.016649802 | P12: -0.086598026 | Q12: -0.040972872 | R12: -0.060573547 | S12: -0.045322396 | T12: -0.036761107 | U12: -0.17151543 | V12: -0.012533168 | W12: -0.089874793 | X12: 0.20252528 | Y12: 0.22081178 | Z12: 0.31936995 | AA12: -0.0093281985 | AB12: -0.15704907 | AC12: -0.088901414 | AD12: -0.020752489 | AE12: -0.25494223 | AF12: -0.0069287358 | AG12: -0.0069770782 | AH12: -0.0070260998 | AI12: -0.0070758152 | AJ12: -0.027714943 | AK12: -0.049123011 | AL12: -0.041978184 | AM12: 0.20213651 | AN12: -0.0066514128 | AO12: 0.12579522 | AP12: -0.025069638 | AQ12: 0.10989011 | AR12: 0.004950495 | AS12: 0.0049261084 | AT12: 0.087535985 | AU12: -0.012843137 | AV12: 0.10020856 | AW12: 0.0064993681 | AX12: 0.050493274 | AY12: 0.14705882 | AZ12: -0.033979339 | BA12: 0.011931065 | BB12: 0.021834061 | BC12: 0.025641026 | BD12: 0.13512821 | BE12: 0.33666667 | BF12: -0.032855362 | BG12: 0.28050667 | BH12: -0.017141131 | BI12: 0.43061515 | BJ12: -0.088583282 | BK12: -0.098092107 | BL12: 0.01134027 | BM12: 0.0039738771 | BN12: -0.14234209 | BO12: -0.018133841 | BP12: -0.025 | BQ12: 0.060897436 | BR12: -0.00060422961 | BS12: 0.015004142 | BT12: 0.0047762999 | BU12: 0.16005777 | BV12: 0.038409669 | BW12: -0.030944829 | BX12: 0.17291415 | BY12: 0.0056051018 | BZ12: 0.0056051018 | CA12: 0.0056051018 | CB12: 0.0056051018 | CC12: 0.038840206 | CD12: 0.0056051018 | CE12: 0.0056051018 | CF12: 0.0056051018 | CG12: 0.0056051018 | CH12: 0.19086015 | CI12: 0.0056051018 | CJ12: 0.0056051018 | CK12: 0.0056051018 | CL12: 0.0056051018 | CM12: 0.16260417 | CN12: 0.0056051018 | CO12: 0.0056051018 | CP12: 0.0056051018 | CQ12: 0.0056051018 | CR12: -0.065012096 | CS12: 0.0056051018 | CT12: 0.0056051018 | CU12: 0.0056051018 | CV12: 0.0056051018 | CW12: -0.070222512 | CX12: 0.0056051018 | CY12: 0.0056051018 | CZ12: 0.0056051018 | DA12: 0.0056051018 | DB12: 0.27642075 | DC12: 0.0056051018 | DD12: 0.0056051018 | DE12: 0.0056051018 | DF12: 0.0056051018 | DG12: -0.11141256 | DH12: 0.0056051018 | DI12: 0.0056051018 | DJ12: 0.0056051018 | DK12: 0.0056051018 | DL12: 0.019555417 | DM12: 0.0056051018 | DN12: 0.0056051018 | DO12: 0.0056051018 | DP12: 0.0056051018 | DQ12: 0.019555417 | DR12: 0.0056051018 | DS12: 0.0056051018 | DT12: 0.0056051018 | DU12: 0.0056051018 | DV12: 0.019555417 | DW12: 0.0056051018 | DX12: 0.0056051018 | DY12: 0.0056051018 | DZ12: 0.0056051018 | EA12: 0.019555417 | EB12: 0.0056051018 | EC12: 0.0056051018 | ED12: 0.0056051018 | EE12: 0.0056051018 | EF12: 0.019555417
A13: R$/US$ Average | B13: 2.8958667 | C13: 3.0451667 | D13: 2.9769333 | E13: 2.7857 | F13: 2.9259167 | G13: 2.6651667 | H13: 2.4818333 | I13: 2.3428333 | J13: 2.2509333 | K13: 2.4351917 | L13: 2.1959333 | M13: 2.1852333 | N13: 2.1713 | O13: 2.1520333 | P13: 2.176125 | Q13: 2.1078167 | R13: 1.9818333 | S13: 1.9161333 | T13: 1.7856333 | U13: 1.9478542 | V13: 1.7365333 | W13: 1.6561 | X13: 1.6677667 | Y13: 2.2778667 | Z13: 1.8345667 | AA13: 2.3113 | AB13: 2.0748 | AC13: 1.8659333 | AD13: 1.7383667 | AE13: 1.9976 | AF13: 1.8416333 | AG13: 1.8131905 | AH13: 1.7595636 | AI13: 1.71333 | AJ13: 1.7593 | AK13: 1.6668306 | AL13: 1.5953516 | AM13: 1.6363954 | AN13: 1.8029258 | AO13: 1.6746 | AP13: 1.7687873 | AQ13: 1.9633 | AR13: 2.0279 | AS13: 2.06 | AT13: 1.9549968 | AU13: 1.9957333 | AV13: 2.07 | AW13: 2.2883 | AX13: 2.2765 | AY13: 2.1576333 | AZ13: 2.3639965 | BA13: 2.268832 | BB13: 2.33 | BC13: 2.38 | BD13: 2.3357071 | BE13: 2.8691 | BF13: 3.0709 | BG13: 3.5399 | BH13: 3.8471 | BI13: 3.33175 | BJ13: 3.67945 | BK13: 3.38435 | BL13: 3.228 | BM13: 3.25265 | BN13: 3.3861125 | BO13: 3.22955 | BP13: 3.16 | BQ13: 3.215 | BR13: 3.309 | BS13: 3.2283875 | BT13: 3.3159 | BU13: 3.5898 | BV13: 3.92985 | BW13: 3.94195 | BX13: 3.694375 | BY13: 3.8908739 | BZ13: 3.9126826 | CA13: 3.9346136 | CB13: 3.9566675 | CC13: 3.9237094 | CD13: 4.51535 | CE13: 5.0042068 | CF13: 5.0126274 | CG13: 5.0210622 | CH13: 4.8883116 | CI13: 4.836321 | CJ13: 4.9095126 | CK13: 4.983812 | CL13: 5.0592357 | CM13: 4.9472203 | CN13: 5.6060892 | CO13: 5.6575022 | CP13: 5.7093867 | CQ13: 5.761747 | CR13: 5.6836813 | CS13: 5.2342796 | CT13: 5.2675441 | CU13: 5.3010199 | CV13: 5.3347086 | CW13: 5.284388 | CX13: 4.8679454 | CY13: 4.9013505 | CZ13: 4.9349848 | DA13: 4.96885 | DB13: 4.9182827 | DC13: 6.0773167 | DD13: 5.84735 | DE13: 5.674875 | DF13: 5.5598917 | DG13: 5.7898583 | DH13: 5.5157527 | DI13: 5.5425229 | DJ13: 5.569423 | DK13: 5.5964537 | DL13: 5.5560381 | DM13: 5.6236155 | DN13: 5.6509092 | DO13: 5.6783354 | DP13: 5.7058947 | DQ13: 5.6646887 | DR13: 5.7335877 | DS13: 5.7614151 | DT13: 5.7893776 | DU13: 5.8174758 | DV13: 5.7754641 | DW13: 5.8457104 | DX13: 5.874082 | DY13: 5.9025913 | DZ13: 5.931239 | EA13: 5.8884057 | EB13: 5.9600257 | EC13: 5.9889521 | ED13: 6.0180189 | EE13: 6.0472268 | EF13: 6.0035559
A14: Sequential Change | B14: -0.0014941498 | C14: 0.051556241 | D14: -0.022407093 | E14: -0.064238366 | F14: -0.049497285 | G14: -0.043268598 | H14: -0.068788694 | I14: -0.056006984 | J14: -0.039226008 | K14: -0.16771667 | L14: -0.024434309 | M14: -0.0048726434 | N14: -0.0063761307 | O14: -0.0088733324 | P14: -0.10638451 | Q14: -0.02054646 | R14: -0.059769588 | S14: -0.033151123 | T14: -0.068105908 | U14: -0.10489785 | V14: -0.027497247 | W14: -0.046318335 | X14: 0.0070446632 | Y14: 0.36581856 | Z14: -0.058160155 | AA14: 0.014677476 | AB14: -0.10232337 | AC14: -0.10066834 | AD14: -0.068366144 | AE14: 0.088867489 | AF14: -0.04434007 | AG14: -0.006952823 | AH14: -0.0070015032 | AI14: -0.0070508699 | AJ14: -0.15792685 | AK14: -0.027139754 | AL14: -0.0428832 | AM14: 0.025727101 | AN14: 0.10176662 | AO14: -0.048144148 | AP14: -0.018935058 | AQ14: 0.10996952 | AR14: 0.032903784 | AS14: 0.015829183 | AT14: 0.16744108 | AU14: -0.031197411 | AV14: 0.03721272 | AW14: 0.10545894 | AX14: -0.0051566665 | AY14: 0.10365056 | AZ14: 0.038434655 | BA14: -0.040255779 | BB14: 0.02696014 | BC14: 0.021459227 | BD14: 0.082531995 | BE14: 0.2055042 | BF14: 0.070335645 | BG14: 0.15272396 | BH14: 0.086782112 | BI14: 0.42644169 | BJ14: -0.043578286 | BK14: -0.080202198 | BL14: -0.046197941 | BM14: 0.0076363073 | BN14: 0.016316499 | BO14: -0.0071019015 | BP14: -0.021535508 | BQ14: 0.017405063 | BR14: 0.029237947 | BS14: -0.046579963 | BT14: 0.027107186 | BU14: 0.082602009 | BV14: 0.094726726 | BW14: 0.0030789979 | BX14: 0.14434063 | BY14: 0.0030789979 | BZ14: 0.0030789979 | CA14: 0.0030789979 | CB14: 0.0030789979 | CC14: 0.06207665 | CD14: 0.0030789979 | CE14: 0.0030789979 | CF14: 0.0030789979 | CG14: 0.0030789979 | CH14: 0.24583935 | CI14: 0.0030789979 | CJ14: 0.0030789979 | CK14: 0.0030789979 | CL14: 0.0030789979 | CM14: 0.012050932 | CN14: 0.0030789979 | CO14: 0.0030789979 | CP14: 0.0030789979 | CQ14: 0.0030789979 | CR14: 0.14886358 | CS14: 0.0030789979 | CT14: 0.0030789979 | CU14: 0.0030789979 | CV14: 0.0030789979 | CW14: -0.07025257 | CX14: 0.0030789979 | CY14: 0.0030789979 | CZ14: 0.0030789979 | DA14: 0.0030789979 | DB14: -0.069280557 | DC14: 0.0030789979 | DD14: 0.0030789979 | DE14: 0.0030789979 | DF14: 0.0030789979 | DG14: 0.17721138 | DH14: 0.0030789979 | DI14: 0.0030789979 | DJ14: 0.0030789979 | DK14: 0.0030789979 | DL14: -0.040384455 | DM14: 0.0030789979 | DN14: 0.0030789979 | DO14: 0.0030789979 | DP14: 0.0030789979 | DQ14: 0.019555417 | DR14: 0.0030789979 | DS14: 0.0030789979 | DT14: 0.0030789979 | DU14: 0.0030789979 | DV14: 0.019555417 | DW14: 0.0030789979 | DX14: 0.0030789979 | DY14: 0.0030789979 | DZ14: 0.0030789979 | EA14: 0.019555417 | EB14: 0.0030789979 | EC14: 0.0030789979 | ED14: 0.0030789979 | EE14: 0.0030789979 | EF14: 0.019555417
A15: IGP-M | B15: 0.027238816 | C15: 0.039508457 | D15: 0.032535493 | E15: 0.019621757 | F15: 0.12419987 | G15: 0.015470449 | H15: 0.0019530032 | I15: -0.015125547 | J15: 0.0099229976 | K15: 0.012007603 | L15: 0.0069795279 | M15: 0.0070809203 | N15: 0.0084226293 | O15: 0.015474403 | P15: 0.03847626 | Q15: 0.011139726 | R15: 0.0034022404 | S15: 0.025690334 | T15: 0.035379965 | U15: 0.077462737 | V15: 0.023778077 | W15: 0.04336869 | X15: 0.015459458 | Y15: 0.012319512 | Z15: 0.098054313 | AA15: -0.0091980353 | AB15: -0.0031967511 | AC15: -0.003717635 | AD15: -0.0011034013 | AE15: -0.017122754 | AF15: 0.027745179 | AG15: 0.028359009 | AH15: 0.020817483 | AI15: 0.031817201 | AJ15: 0.113 | AK15: 0.024312626 | AL15: 0.0069680368 | AM15: 0.0097144444 | AN15: 0.0091198891 | AO15: 0.05096813 | AP15: 0.0061573961 | AQ15: 0.025570914 | AR15: 0.037862169 | AS15: 0.0066992596 | AT15: 0.0782 | AU15: 0.0084 | AV15: 0.009 | AW15: 0.0192 | AX15: 0.0176 | AY15: 0.055 | AZ15: 0.025462165 | BA15: 0 | BB15: 0.014 | BC15: 0.012 | BD15: 0.0369 | BE15: 0.020221661 | BF15: 0.022654151 | BG15: 0.019311654 | BH15: 0.039455778 | BI15: 0.107 | BJ15: 0.029665632 | BK15: 0.028562255 | BL15: 0.0051997258 | BM15: 0.0067134119 | BN15: 0.071729083 | BO15: -0.0013025427 | BP15: -0.0013025427 | BQ15: -0.0013025427 | BR15: -0.0013025427 | BS15: -0.0052 | BT15: 0.018244601 | BU15: 0.018244601 | BV15: 0.018244601 | BW15: 0.018244601 | BX15: 0.075 | BY15: 0.017813112 | BZ15: 0.017813112 | CA15: 0.017813112 | CB15: 0.017813112 | CC15: 0.073179 | CD15: 0.053413777 | CE15: 0.053413777 | CF15: 0.053413777 | CG15: 0.053413777 | CH15: 0.231391 | CI15: 0.041760503 | CJ15: 0.041760503 | CK15: 0.041760503 | CL15: 0.041760503 | CM15: 0.1778 | CN15: 0.013355073 | CO15: 0.013355073 | CP15: 0.013355073 | CQ15: 0.013355073 | CR15: 0.0545 | CS15: -0.0080466017 | CT15: -0.0080466017 | CU15: -0.0080466017 | CV15: -0.0080466017 | CW15: -0.0318 | CX15: 0.015963658 | CY15: 0.015963658 | CZ15: 0.015963658 | DA15: 0.015963658 | DB15: 0.0654 | DC15: -0.0026353997 | DD15: -0.0026353997 | DE15: -0.0026353997 | DF15: -0.0026353997 | DG15: -0.0105 | DH15: 0.01106499 | DI15: 0.01106499 | DJ15: 0.01106499 | DK15: 0.01106499 | DL15: 0.045 | DM15: 0.01106499 | DN15: 0.01106499 | DO15: 0.01106499 | DP15: 0.01106499 | DQ15: 0.045 | DR15: 0.01106499 | DS15: 0.01106499 | DT15: 0.01106499 | DU15: 0.01106499 | DV15: 0.045 | DW15: 0.01106499 | DX15: 0.01106499 | DY15: 0.01106499 | DZ15: 0.01106499 | EA15: 0.045 | EB15: 0.01106499 | EC15: 0.01106499 | ED15: 0.01106499 | EE15: 0.01106499 | EF15: 0.045
A16: IPCA | B16: 0.018510968 | C16: 0.015981484 | D16: 0.019415797 | E16: 0.020027801 | F16: 0.076006441 | G16: 0.017905799 | H16: 0.013439901 | I16: 0.0077189649 | J16: 0.016688199 | K16: 0.056897333 | L16: 0.014367294 | M16: 0.00099558559 | N16: 0.004505992 | O16: 0.011240999 | P16: 0.03141775 | Q16: 0.012551992 | R16: 0.0081218596 | S16: 0.0089240803 | T16: 0.014261804 | U16: 0.044573304 | V16: 0.015176027 | W16: 0.020942932 | X16: 0.010735939 | Y16: 0.010938925 | Z16: 0.059023134 | AA16: 0.012347053 | AB16: 0.013156841 | AC16: 0.0063129686 | AD16: 0.010637052 | AE16: 0.043120283 | AF16: 0.020638364 | AG16: 0.01002451 | AH16: 0.0050022902 | AI16: 0.022262182 | AJ16: 0.0591 | AK16: 0.02439696 | AL16: 0.013956003 | AM16: 0.010634041 | AN16: 0.014569972 | AO16: 0.065033527 | AP16: 0.01224539 | AQ16: 0.0108289 | AR16: 0.01416561 | AS16: 0.01992 | AT16: 0.0584 | AU16: 0.019420463 | AV16: 0.011844323 | AW16: 0.0062 | AX16: 0.0204 | AY16: 0.059 | AZ16: 0.021752379 | BA16: 0.0154 | BB16: 0.0066 | BC16: 0.0191 | BD16: 0.0641 | BE16: 0.038277997 | BF16: 0.022567505 | BG16: 0.013859074 | BH16: 0.028159295 | BI16: 0.107 | BJ16: 0.026208101 | BK16: 0.017496397 | BL16: 0.010430578 | BM16: 0.007417894 | BN16: 0.062880551 | BO16: 0.0072947902 | BP16: 0.0072947902 | BQ16: 0.0072947902 | BR16: 0.0072947902 | BS16: 0.0295 | BT16: 0.0092459757 | BU16: 0.0092459757 | BV16: 0.0092459757 | BW16: 0.0092459757 | BX16: 0.0375 | BY16: 0.010605102 | BZ16: 0.010605102 | CA16: 0.010605102 | CB16: 0.010605102 | CC16: 0.0431 | CD16: 0.0066827131 | CE16: 0.0066827131 | CF16: 0.0066827131 | CG16: 0.0066827131 | CH16: 0.027 | CI16: 0.020133746 | CJ16: 0.020133746 | CK16: 0.020133746 | CL16: 0.020133746 | CM16: 0.083 | CN16: 0.014170922 | CO16: 0.014170922 | CP16: 0.014170922 | CQ16: 0.014170922 | CR16: 0.0579 | CS16: 0.011355123 | CT16: 0.011355123 | CU16: 0.011355123 | CV16: 0.011355123 | CW16: 0.0462 | CX16: 0.011862256 | CY16: 0.011862256 | CZ16: 0.011862256 | DA16: 0.011862256 | DB16: 0.0483 | DC16: 0.010483974 | DD16: 0.010483974 | DE16: 0.010483974 | DF16: 0.010483974 | DG16: 0.0426 | DH16: 0.0098534065 | DI16: 0.0098534065 | DJ16: 0.0098534065 | DK16: 0.0098534065 | DL16: 0.04 | DM16: 0.0098534065 | DN16: 0.0098534065 | DO16: 0.0098534065 | DP16: 0.0098534065 | DQ16: 0.04 | DR16: 0.0098534065 | DS16: 0.0098534065 | DT16: 0.0098534065 | DU16: 0.0098534065 | DV16: 0.04 | DW16: 0.0098534065 | DX16: 0.0098534065 | DY16: 0.0098534065 | DZ16: 0.0098534065 | EA16: 0.04 | EB16: 0.0098534065 | EC16: 0.0098534065 | ED16: 0.0098534065 | EE16: 0.0098534065 | EF16: 0.04
A17: CDI | B17: 0.15891187 | C17: 0.15435042 | D17: 0.16350861 | E17: 0.16948771 | F17: 0.16155114 | G17: 0.1778254 | H17: 0.19514372 | I17: 0.20317559 | J17: 0.1838907 | K17: 0.18996837 | L17: 0.17179576 | M17: 0.15115659 | N17: 0.14797492 | O17: 0.13084663 | P17: 0.15035162 | Q17: 0.12681933 | R17: 0.1205915 | S17: 0.11615637 | T17: 0.10910245 | U17: 0.11814874 | V17: 0.10734371 | W17: 0.11439214 | X17: 0.13443413 | Y17: 0.1393809 | Z17: 0.12380815 | AA17: 0.12058908 | AB17: 0.098592428 | AC17: 0.08990374 | AD17: 0.086015281 | AE17: 0.098694035 | AF17: 0.0875 | AG17: 0.0975 | AH17: 0.1075 | AI17: 0.1075 | AJ17: 0.1 | AK17: 0.11333333 | AL17: 0.12012097 | AM17: 0.12280769 | AN17: 0.11415385 | AO17: 0.11708333 | AP17: 0.1025 | AQ17: 0.086666667 | AR17: 0.076666667 | AS17: 0.0725 | AT17: 0.08458 | AU17: 0.0725 | AV17: 0.078333333 | AW17: 0.088333333 | AX17: 0.098333333 | AY17: 0.0844 | AZ17: 0.10666667 | BA17: 0.11 | BB17: 0.11 | BC17: 0.11 | BD17: 0.11020833 | BE17: 0.1225 | BF17: 0.1325 | BG17: 0.14 | BH17: 0.1425 | BI17: 0.13583333 | BJ17: 0.1425 | BK17: 0.1425 | BL17: 0.1425 | BM17: 0.14 | BN17: 0.14 | BO17: 0.13 | BP17: 0.1125 | BQ17: 0.095 | BR17: 0.07875 | BS17: 0.095625 | BT17: 0.069166667 | BU17: 0.0675 | BV17: 0.065833333 | BW17: 0.065 | BX17: 0.06625 | BY17: 0.0625 | BZ17: 0.0575 | CA17: 0.0525 | CB17: 0.0475 | CC17: 0.0525 | CD17: 0.04125 | CE17: 0.03375 | CF17: 0.02625 | CG17: 0.0225 | CH17: 0.028125 | CI17: 0.031875 | CJ17: 0.050625 | CK17: 0.069375 | CL17: 0.088125 | CM17: 0.069375 | CN17: 0.1075 | CO17: 0.125 | CP17: 0.135 | CQ17: 0.1375 | CR17: 0.13125 | CS17: 0.135 | CT17: 0.13 | CU17: 0.125 | CV17: 0.12 | CW17: 0.125 | CX17: 0.114375 | CY17: 0.108125 | CZ17: 0.10625 | DA17: 0.115 | DB17: 0.1115625 | DC17: 0.1325 | DD17: 0.14625 | DE17: 0.15 | DF17: 0.15 | DG17: 0.148125 | DH17: 0.1475 | DI17: 0.1425 | DJ17: 0.1375 | DK17: 0.1325 | DL17: 0.1375 | DM17: 0.13 | DN17: 0.13 | DO17: 0.13 | DP17: 0.13 | DQ17: 0.13 | DR17: 0.13 | DS17: 0.13 | DT17: 0.13 | DU17: 0.13 | DV17: 0.13 | DW17: 0.13 | DX17: 0.13 | DY17: 0.13 | DZ17: 0.13 | EA17: 0.13 | EB17: 0.13 | EC17: 0.13 | ED17: 0.13 | EE17: 0.13 | EF17: 0.13
B19: =#REF!+#REF!+#REF!+B15 -> #REF! | C19: =#REF!+#REF!+B15+C15 -> #REF! | D19: =#REF!+B15+C15+D15 -> #REF! | E19: =B15+C15+D15+E15 -> 0.11890452 | F19: =F15 -> 0.12419987 | G19: =C15+D15+E15+G15 -> 0.10713616 | H19: =D15+E15+G15+H15 -> 0.069580702 | I19: =E15+G15+H15+I15 -> 0.021919662 | J19: =G15+H15+I15+J15 -> 0.012220903 | K19: =K15 -> 0.012007603 | L19: =H15+I15+J15+L15 -> 0.0037299816 | M19: =I15+J15+L15+M15 -> 0.0088578987 | N19: =J15+L15+M15+N15 -> 0.032406075 | O19: =L15+M15+N15+O15 -> 0.03795748 | P19: =P15 -> 0.03847626 | Q19: =M15+N15+O15+Q15 -> 0.042117678 | R19: =N15+O15+Q15+R15 -> 0.038438998 | S19: =O15+Q15+R15+S15 -> 0.055706703 | T19: =Q15+R15+S15+T15 -> 0.075612265 | U19: =U15 -> 0.077462737 | V19: =R15+S15+T15+V15 -> 0.088250617 | W19: =S15+T15+V15+W15 -> 0.12821707 | X19: =T15+V15+W15+X15 -> 0.11798619 | Y19: =V15+W15+X15+Y15 -> 0.094925737 | Z19: =Z15 -> 0.098054313 | AA19: =W15+X15+Y15+AA15 -> 0.061949624 | AB19: =X15+Y15+AA15+AB15 -> 0.015384183 | AC19: =Y15+AA15+AB15+AC15 -> -0.0037929098 | AD19: =AA15+AB15+AC15+AD15 -> -0.017215823 | AE19: =AE15 -> -0.017122754 | AF19: =AB15+AC15+AD15+AF15 -> 0.019727391 | AG19: =AC15+AD15+AF15+AG15 -> 0.051283151 | AH19: =AD15+AF15+AG15+AH15 -> 0.075818269 | AI19: =AF15+AG15+AH15+AI15 -> 0.10873887 | AJ19: =AJ15 -> 0.113 | AK19: =AG15+AH15+AI15+AK15 -> 0.10530632 | AL19: =AH15+AI15+AK15+AL15 -> 0.083915347 | AM19: =AI15+AK15+AL15+AM15 -> 0.072812308 | AN19: =AK15+AL15+AM15+AN15 -> 0.050114997 | AO19: =AO15 -> 0.05096813 | AP19: =AL15+AM15+AN15+AP15 -> 0.031959766 | AQ19: =AM15+AN15+AP15+AQ15 -> 0.050562644 | AR19: =AN15+AP15+AQ15+AR15 -> 0.078710368 | AS19: =AP15+AQ15+AR15+AS15 -> 0.076289739 | AT19: =AT15 -> 0.0782 | AU19: =AQ15+AR15+AS15+AU15 -> 0.078532343 | AV19: =AR15+AS15+AU15+AV15 -> 0.061961428 | AW19: =AS15+AU15+AV15+AW15 -> 0.04329926 | AX19: =AU15+AV15+AW15+AX15 -> 0.0542 | AY19: =AY15 -> 0.055 | AZ19: =AV15+AW15+AX15+AZ15 -> 0.071262165 | BA19: =AW15+AX15+AZ15+BA15 -> 0.062262165 | BB19: =AX15+AZ15+BA15+BB15 -> 0.057062165 | BC19: =AZ15+BA15+BB15+BC15 -> 0.051462165 | BD19: =BD15 -> 0.0369 | BE19: =BA15+BB15+BC15+BE15 -> 0.046221661 | BF19: =BB15+BC15+BE15+BF15 -> 0.068875812 | BG19: =BC15+BE15+BF15+BG15 -> 0.074187466 | BH19: =BE15+BF15+BG15+BH15 -> 0.10164324 | BI19: =BI15 -> 0.107 | BJ19: =BF15+BG15+BH15+BJ15 -> 0.11108721 | BK19: =BG15+BH15+BJ15+BK15 -> 0.11699532 | BL19: =BH15+BJ15+BK15+BL15 -> 0.10288339 | BM19: =BJ15+BK15+BL15+BM15 -> 0.070141024 | BN19: =BN15 -> 0.071729083 | BO19: =BK15+BL15+BM15+BO15 -> 0.03917285 | BP19: =BL15+BM15+BO15+BP15 -> 0.0093080523 | BQ19: =BM15+BO15+BP15+BQ15 -> 0.0028057838 | BR19: =BO15+BP15+BQ15+BR15 -> -0.0052101709 | BS19: =BS15 -> -0.0052 | BT19: =BP15+BQ15+BR15+BT15 -> 0.014336973 | BU19: =BQ15+BR15+BT15+BU15 -> 0.033884117 | BV19: =BR15+BT15+BU15+BV15 -> 0.053431261 | BW19: =BT15+BU15+BV15+BW15 -> 0.072978404 | BX19: =BX15 -> 0.075 | BY19: =BU15+BV15+BW15+BY15 -> 0.072546915 | BZ19: =BV15+BW15+BY15+BZ15 -> 0.072115427 | CA19: =BW15+BY15+BZ15+CA15 -> 0.071683938 | CB19: =BY15+BZ15+CA15+CB15 -> 0.071252449 | CC19: =CC15 -> 0.073179 | CD19: =BZ15+CA15+CB15+CD15 -> 0.10685311 | CE19: =CA15+CB15+CD15+CE15 -> 0.14245378 | CF19: =CB15+CD15+CE15+CF15 -> 0.17805444 | CG19: =CD15+CE15+CF15+CG15 -> 0.21365511 | CH19: =CH15 -> 0.231391 | CI19: =CE15+CF15+CG15+CI15 -> 0.20200183 | CJ19: =CF15+CG15+CI15+CJ15 -> 0.19034856 | CK19: =CG15+CI15+CJ15+CK15 -> 0.17869528 | CL19: =CI15+CJ15+CK15+CL15 -> 0.16704201 | CM19: =CM15 -> 0.1778 | CN19: =CJ15+CK15+CL15+CN15 -> 0.13863658 | CO19: =CK15+CL15+CN15+CO15 -> 0.11023115 | CP19: =CL15+CN15+CO15+CP15 -> 0.081825722 | CQ19: =CN15+CO15+CP15+CQ15 -> 0.053420292 | CR19: =CR15 -> 0.0545 | CS19: =CO15+CP15+CQ15+CS15 -> 0.032018618 | CT19: =CP15+CQ15+CS15+CT15 -> 0.010616943 | CU19: =CQ15+CS15+CT15+CU15 -> -0.010784732 | CV19: =CS15+CT15+CU15+CV15 -> -0.032186407 | CW19: =CW15 -> -0.0318 | CX19: =CT15+CU15+CV15+CX15 -> -0.0081761472 | CY19: =CU15+CV15+CX15+CY15 -> 0.015834113 | CZ19: =CV15+CX15+CY15+CZ15 -> 0.039844372 | DA19: =CX15+CY15+CZ15+DA15 -> 0.063854632 | DB19: =DB15 -> 0.0654 | DC19: =CY15+CZ15+DA15+DC15 -> 0.045255574 | DD19: =CZ15+DA15+DC15+DD15 -> 0.026656517 | DE19: =DA15+DC15+DD15+DE15 -> 0.0080574589 | DF19: =DC15+DD15+DE15+DF15 -> -0.010541599 | DG19: =DG15 -> -0.0105 | DH19: =DD15+DE15+DF15+DH15 -> 0.0031587914 | DI19: =DE15+DF15+DH15+DI15 -> 0.016859182 | DJ19: =DF15+DH15+DI15+DJ15 -> 0.030559572 | DK19: =DH15+DI15+DJ15+DK15 -> 0.044259962 | DL19: =DL15 -> 0.045 | DM19: =DI15+DJ15+DK15+DM15 -> 0.044259962 | DN19: =DJ15+DK15+DM15+DN15 -> 0.044259962 | DO19: =DK15+DM15+DN15+DO15 -> 0.044259962 | DP19: =DM15+DN15+DO15+DP15 -> 0.044259962 | DQ19: =DQ15 -> 0.045 | DR19: =DN15+DO15+DP15+DR15 -> 0.044259962 | DS19: =DO15+DP15+DR15+DS15 -> 0.044259962 | DT19: =DP15+DR15+DS15+DT15 -> 0.044259962 | DU19: =DR15+DS15+DT15+DU15 -> 0.044259962 | DV19: =DV15 -> 0.045 | DW19: =DS15+DT15+DU15+DW15 -> 0.044259962 | DX19: =DT15+DU15+DW15+DX15 -> 0.044259962 | DY19: =DU15+DW15+DX15+DY15 -> 0.044259962 | DZ19: =DW15+DX15+DY15+DZ15 -> 0.044259962 | EA19: =EA15 -> 0.045 | EB19: =DX15+DY15+DZ15+EB15 -> 0.044259962 | EC19: =DY15+DZ15+EB15+EC15 -> 0.044259962 | ED19: =DZ15+EB15+EC15+ED15 -> 0.044259962 | EE19: =EB15+EC15+ED15+EE15 -> 0.044259962 | EF19: =EF15 -> 0.045

Sheet Income Statement
BS1: =48+16-31 -> 33 | DB1: =DB10/CW10-1 -> 0.27395993 | DG1: =DG10/DB10-1 -> 0.18301068
A2: =DCF!$A$2 -> Cyrela - TP: R$35 | U2: =U15/U10 -> 0.38877 | Z2: =Z15/Z10 -> 0.38019401 | AE2: =AE15/AE10 -> 0.34474421 | AJ2: =AJ15/AJ10 -> 0.31423252 | AK2: =AK15/AK10 -> 0.27375823 | AL2: =AL15/AL10 -> 0.27659298 | AM2: =AM15/AM10 -> 0.28594539 | AN2: =AN15/AN10 -> 0.29054933 | AO2: =AO15/AO10 -> 0.2829365 | AT2: =AT15/AT10 -> 0.32290354 | AW2: =AW15/AW10 -> 0.32790753 | AX2: =AX15/AX10 -> 0.32903727 | AY2: =AY15/AY10 -> 0.32749956 | AZ2: =AZ15/AZ10 -> 0.3327259 | BA2: =BA15/BA10 -> 0.33390389 | BB2: =BB15/BB10 -> 0.29914618 | BC2: =BC15/BC10 -> 0.32329024 | BD2: =BD15/BD10 -> 0.32120479 | ... EF2: =EF15/EF10 -> 0.32784266
B3: =Macro!B$3 -> 1Q04 | C3: =Macro!C$3 -> 2Q04 | D3: =Macro!D$3 -> 3Q04 | E3: =Macro!E$3 -> 4Q04 | F3: =Macro!F$3 -> 2004 | G3: =Macro!G$3 -> 1Q05 | H3: =Macro!H$3 -> 2Q05 | I3: =Macro!I$3 -> 3Q05 | ... EF3: =Macro!EF$3 -> 2030E
A4: Gross Revenues | B4: =B5+B6 -> 116483.5 | C4: =C5+C6 -> 116483.5 | D4: =D5+D6 -> 127779 | E4: =E5+E6 -> 196256 | F4: =SUM(B4:E4) -> 557002 | G4: =G5+G6 -> 178056 | H4: =H5+H6 -> 154333 | I4: =I5+I6 -> 263879 | J4: =J5+J6 -> 128931 | K4: =SUM(G4:J4) -> 725199 | L4: =L5+L6 -> 241448 | M4: =M5+M6 -> 275347 | N4: =N5+N6 -> 237808 | O4: =O5+O6 -> 402165 | P4: =SUM(L4:O4) -> 1156768 | Q4: =Q5+Q6 -> 299261 | R4: =R5+R6 -> 387298 | S4: =S5+S6 -> 431668 | T4: =T5+T6 -> 961212 | U4: =SUM(Q4:T4) -> 2079439 | V4: =V5+V6 -> 572579 | W4: =W5+W6 -> 830119 | X4: =X5+X6 -> 773992 | Y4: =Y5+Y6 -> 790759 | Z4: =SUM(V4:Y4) -> 2967449 | AA4: =AA5+AA6 -> 698996 | AB4: =AB5+AB6 -> 909715 | AC4: =AC5+AC6 -> 1396986 | AD4: =AD5+AD6 -> 1228296 | AE4: =SUM(AA4:AD4) -> 4233993 | AF4: =AF5+AF6 -> 1170169 | AG4: =AG5+AG6 -> 1234539 | AH4: =AH5+AH6 -> 1203539 | AI4: =AI5+AI6 -> 1445304 | AJ4: =SUM(AF4:AI4) -> 5053551 | AK4: =AK5+AK6 -> 1248883 | AL4: =AL5+AL6 -> 1438136 | AM4: =AM5+AM6 -> 1619390 | AN4: =AN5+AN6 -> 2069350 | AO4: =SUM(AK4:AN4) -> 6375759 | AP4: =AP5+AP6 -> 1522642 | AQ4: =AQ5+AQ6 -> 1438939 | AR4: =AR5+AR6 -> 1409120 | AS4: =AS5+AS6 -> 1432050 | AT4: =SUM(AP4:AS4) -> 5802751 | AU4: =AU5+AU6 -> 1250942 | AV4: =AV5+AV6 -> 1410150 | AW4: =AW5+AW6 -> 1435138 | AX4: =AX5+AX6 -> 1436106 | AY4: =SUM(AU4:AX4) -> 5532336 | AZ4: =AZ5+AZ6 -> 1351067 | BA4: =BA5+BA6 -> 1397217 | BB4: =BB5+BB6 -> 1628377 | BC4: =BC5+BC6 -> 1569902 | BD4: =SUM(AZ4:BC4) -> 5946563 | BE4: =BE5+BE6 -> 1068010 | BF4: =BF5+BF6 -> 1165862 | BG4: =BG5+BG6 -> 1172876 | BH4: =BH5+BH6 -> 1059054 | BI4: =SUM(BE4:BH4) -> 4465802 | BJ4: =BJ5+BJ6 -> 833226 | BK4: =BK5+BK6 -> 662190 | BL4: =BL5+BL6 -> 847384 | BM4: =BM5+BM6 -> 947904 | BN4: =SUM(BJ4:BM4) -> 3290704 | BO4: =BO5+BO6 -> 712412 | BP4: =BP5+BP6 -> 591107 | BQ4: =BQ5+BQ6 -> 614497 | BR4: =BR5+BR6 -> 831905 | BS4: =SUM(BO4:BR4) -> 2749921 | BT4: =BT5+BT6 -> 464152 | BU4: =BU5+BU6 -> 657521 | BV4: =BV5+BV6 -> 744589 | BW4: =BW5+BW6 -> 1111066 | BX4: =SUM(BT4:BW4) -> 2977328 | BY4: =BY5+BY6 -> 847909 | BZ4: =BZ5+BZ6 -> 959639 | CA4: =CA5+CA6 -> 959878 | CB4: =CB5+CB6 -> 1265292 | CC4: =SUM(BY4:CB4) -> 4032718 | CD4: =CD5+CD6 -> 785189 | CE4: =CE5+CE6 -> 860738 | CF4: =CF5+CF6 -> 1192465 | CG4: =CG5+CG6 -> 1087405 | CH4: =SUM(CD4:CG4) -> 3925797 | CI4: =CI5+CI6 -> 1030234 | CJ4: =CJ5+CJ6 -> 1213954 | CK4: =CK5+CK6 -> 1321796 | CL4: =CL5+CL6 -> 1351676 | CM4: =SUM(CI4:CL4) -> 4917660 | CN4: =CN5+CN6 -> 1259101 | CO4: =CO5+CO6 -> 1284091 | CP4: =CP5+CP6 -> 1600107 | CQ4: =CQ5+CQ6 -> 1412549 | CR4: =SUM(CN4:CQ4) -> 5555848 | CS4: =CS5+CS6 -> 1317322 | CT4: =CT5+CT6 -> 1678440 | CU4: =CU5+CU6 -> 1672991 | CV4: =CV5+CV6 -> 1760921 | CW4: =SUM(CS4:CV4) -> 6429674 | CX4: =CX5+CX6 -> 1614575 | CY4: =CY5+CY6 -> 1909290 | CZ4: =CZ5+CZ6 -> 2086805 | DA4: =DA5+DA6 -> 2574979 | DB4: =SUM(CX4:DA4) -> 8185649 | DC4: =DC5+DC6 -> 2003367 | DD4: =DD5+DD6 -> 2167903 | DE4: =DE5+DE6 -> 2191373 | DF4: =DF5+DF6 -> 3317082 | DG4: =SUM(DC4:DF4) -> 9679725 | DH4: =DH5+DH6 -> 2081306 | DI4: =DI5+DI6 -> 2548922 | DJ4: =DJ5+DJ6 -> 2779665.8 | DK4: =DK5+DK6 -> 3085867.8 | DL4: =SUM(DH4:DK4) -> 10495762 | DM4: =DM5+DM6 -> 2904177.2 | DN4: =DN5+DN6 -> 3030696.4 | DO4: =DO5+DO6 -> 3135918.4 | DP4: =DP5+DP6 -> 3413246 | DQ4: =SUM(DM4:DP4) -> 12484038 | DR4: =DR5+DR6 -> 3232579.8 | DS4: =DS5+DS6 -> 3342174.3 | DT4: =DT5+DT6 -> 3438345.6 | DU4: =DU5+DU6 -> 3716019 | DV4: =SUM(DR4:DU4) -> 13729119 | DW4: =DW5+DW6 -> 3508456.3 | DX4: =DX5+DX6 -> 3616040.7 | DY4: =DY5+DY6 -> 3707760.8 | DZ4: =DZ5+DZ6 -> 3991703.6 | EA4: =SUM(DW4:DZ4) -> 14823961 | EB4: =EB5+EB6 -> 3765591.1 | EC4: =EC5+EC6 -> 3873478.4 | ED4: =ED5+ED6 -> 3962578.6 | EE4: =EE5+EE6 -> 4251973.9 | EF4: =SUM(EB4:EE4) -> 15853622
A5: Development Sales | B5: =(482261+31373-SUM(D5:E5))/2 -> 105655 | C5: =B5 -> 105655 | D5: 113887 | E5: 188437 | F5: =SUM(B5:E5) -> 513634 | G5: 167756 | H5: 143200 | I5: 245810 | J5: 114407 | K5: =SUM(G5:J5) -> 671173 | L5: 227048 | M5: =481169-L5 -> 254121 | N5: =698102-SUM(L5:M5) -> 216933 | O5: =1082508-SUM(L5:N5) -> 384406 | P5: =SUM(L5:O5) -> 1082508 | Q5: 293395 | R5: =668065-Q5 -> 374670 | S5: 418305 | T5: =2021962+8363-SUM(Q5:S5) -> 943955 | U5: =SUM(Q5:T5) -> 2030325 | V5: =559757+3794 -> 563551 | W5: =818418+4241 -> 822659 | X5: =761546+4301 -> 765847 | Y5: =2907848+22974-SUM(V5:X5) -> 778765 | Z5: =SUM(V5:Y5) -> 2930822 | AA5: =685017+5225 -> 690242 | AB5: =887540+13379 -> 900919 | AC5: =1370602+13033 -> 1383635 | AD5: =1201078+16442 -> 1217520 | AE5: =SUM(AA5:AD5) -> 4192316 | AF5: =1140556+18091 -> 1158647 | AG5: =1191445+26952-AG34 -> 1218397 | AH5: =1171767+13862 -> 1185629 | AI5: =1407331+6543 -> 1413874 | AJ5: =SUM(AF5:AI5) -> 4976547 | AK5: =1216842+8949 -> 1225791 | AL5: =2625160+13076-AK5 -> 1412445 | AM5: =4207472+17666-AK5-AL5 -> 1586902 | AN5: =6240161+26490-AK5-AL5-AM5 -> 2041513 | AO5: =SUM(AK5:AN5) -> 6266651 | AP5: =2915251+4573-AQ5 -> 1505576 | AQ5: =1411422+2826 -> 1414248 | AR5: =1409120-AR6 -> 1394730 | AS5: =5701885+14069-AP5-AQ5-AR5 -> 1401400 | AT5: =SUM(AP5:AS5) -> 5715954 | AU5: =2603392+20342-AV5 -> 1233951 | AV5: =1382665+7118 -> 1389783 | AW5: =1435138-AW6 -> 1414214 | AX5: =5532336-SUM(AU5:AW5)-SUM(AU6:AX6) -> 1410416 | AY5: =SUM(AU5:AX5) -> 5448364 | AZ5: =1317983+17433 -> 1335416 | BA5: =1366342+14295 -> 1380637 | BB5: =1628377-BB6 -> 1607593 | BC5: =5946563-SUM(AZ5:BB5)-SUM(AZ6:BC6) -> 1558582 | BD5: =SUM(AZ5:BC5) -> 5882228 | BE5: =1031782+22263 -> 1054045 | BF5: =1141593+15312 -> 1156905 | BG5: =1172876-BG6 -> 1164221 | BH5: =4465802-SUM(BE5:BG5)-SUM(BE6:BH6) -> 1046063 | BI5: =SUM(BE5:BH5) -> 4421234 | BJ5: =799333+20950 -> 820283 | BK5: =614249+21481 -> 635730 | BL5: =847384-BL6 -> 839121 | BM5: =3290704-SUM(BJ5:BL5)-SUM(BJ6:BM6) -> 942441 | BN5: =SUM(BJ5:BM5) -> 3237575 | BO5: =678581+16224 -> 694805 | BP5: =573917+11356 -> 585273 | BQ5: =614497-BQ6 -> 608783 | BR5: =2671670+44168-SUM(BO5:BQ5) -> 826977 | BS5: =SUM(BO5:BR5) -> 2715838 | BT5: =445472+14559 -> 460031 | BU5: =638476+14319 -> 652795 | BV5: =728261+9518 -> 737779 | BW5: =3156039+51958-SUM(BT5:BV5)-254000 -> 1103392 | BX5: =SUM(BT5:BW5) -> 2953997 | BY5: =845764+11907-14195 -> 843476 | BZ5: =953167+9105-6610 -> 955662 | CA5: =901500+8113+41796 -> 951409 | CB5: =3867086+34904+105628-SUM(BY5:CA5) -> 1257071 | CC5: =SUM(BY5:CB5) -> 4007618 | CD5: =724852+9374+39479 -> 773705 | CE5: =826804+3845+16608 -> 847257 | CF5: =1153156+14847+6784 -> 1174787 | CG5: =3765116+41562+48464-SUM(CD5:CF5) -> 1059393 | CH5: =SUM(CD5:CG5) -> 3855142 | CI5: =1057818+20802-45161-24355 -> 1009104 | CJ5: =1193319+15809-12203-7752 -> 1189173 | CK5: =1288055+11945+2193-5203 -> 1296990 | CL5: =4851226+51769-62954-35986-SUM(CI5:CK5) -> 1308788 | CM5: =SUM(CI5:CL5) -> 4804055 | CN5: =1270338+6461-43143+5545 -> 1239201 | CO5: =1219902+10977+30436-6907 -> 1254408 | CP5: =1549256+2670+8131+9798 -> 1569855 | CQ5: =5440721+23045-15086+6545-SUM(CN5:CP5) -> 1391761 | CR5: =SUM(CN5:CQ5) -> 5455225 | CS5: =1323506+633-18150-4887 -> 1301102 | CT5: =2967331+1814-2630-7413-CS5 -> 1658000 | CU5: =4598860+2811+12432-3586-SUM(CS5:CT5) -> 1651415 | CV5: =6373445+3955-30135-3508-SUM(CS5:CU5) -> 1733240 | CW5: =SUM(CS5:CV5) -> 6343757 | CX5: =1644948+2568-46749-5947 -> 1594820 | CY5: =3509983+3638-29563-3531-CX5 -> 1885707 | CZ5: =5585280+2631-45676-236-SUM(CX5:CY5) -> 2061472 | DA5: =8201507+3951-109456-5895-SUM(CX5:CZ5) -> 2548108 | DB5: =SUM(CX5:DA5) -> 8090107 | DC5: =2074898+285-99013-914 -> 1975256 | DD5: =4146252+272-28621-1012-DC5 -> 2141635 | DE5: =6199476+66785+24246-10557-SUM(DC5:DD5) -> 2163059 | DF5: =9498874+90734-12130-9388-SUM(DC5:DE5) -> 3288140 | DG5: =SUM(DC5:DF5) -> 9568090 | DH5: =2110359+10713-68796-2191 -> 2050085 | DI5: =4601478+13577-56471-3916-DH5 -> 2504583 | DJ5: =Forecasts!DJ36 -> 2746705.3 | DK5: =Forecasts!DK36 -> 3049276.4 | DL5: =SUM(DH5:DK5) -> 10350650 | DM5: =Forecasts!DM36 -> 2875422.9 | DN5: =Forecasts!DN36 -> 3000689.5 | DO5: =Forecasts!DO36 -> 3104869.7 | DP5: =Forecasts!DP36 -> 3379451.4 | DQ5: =SUM(DM5:DP5) -> 12360434 | DR5: =Forecasts!DR36 -> 3200574.1 | DS5: =Forecasts!DS36 -> 3309083.4 | DT5: =Forecasts!DT36 -> 3404302.6 | DU5: =Forecasts!DU36 -> 3679226.7 | DV5: =SUM(DR5:DU5) -> 13593187 | DW5: =Forecasts!DW36 -> 3473719.1 | DX5: =Forecasts!DX36 -> 3580238.3 | DY5: =Forecasts!DY36 -> 3671050.3 | DZ5: =Forecasts!DZ36 -> 3952181.8 | EA5: =SUM(DW5:DZ5) -> 14677190 | EB5: =Forecasts!EB36 -> 3728308.1 | EC5: =Forecasts!EC36 -> 3835127.2 | ED5: =Forecasts!ED36 -> 3923345.2 | EE5: =Forecasts!EE36 -> 4209875.1 | EF5: =SUM(EB5:EE5) -> 15696656
A6: Services | B6: =(21672+14671+7025-SUM(D6:E6))/2 -> 10828.5 | C6: =B6 -> 10828.5 | D6: 13892 | E6: 7819 | F6: =SUM(B6:E6) -> 43368 | G6: 10300 | H6: 11133 | I6: 18069 | J6: 14524 | K6: =SUM(G6:J6) -> 54026 | L6: 14400 | M6: 21226 | N6: =40123+16378-SUM(L6:M6) -> 20875 | O6: =52423+21837-SUM(L6:N6) -> 17759 | P6: =SUM(L6:O6) -> 74260 | Q6: 5866 | R6: =18494-Q6 -> 12628 | S6: 13363 | T6: =16559+698 -> 17257 | U6: =SUM(Q6:T6) -> 49114 | V6: 9028 | W6: 7460 | X6: 8145 | Y6: =11994 -> 11994 | Z6: =SUM(V6:Y6) -> 36627 | AA6: 8754 | AB6: 8796 | AC6: 13351 | AD6: 10776 | AE6: =SUM(AA6:AD6) -> 41677 | AF6: 11522 | AG6: 16142 | AH6: 17910 | AI6: 31430 | AJ6: =SUM(AF6:AI6) -> 77004 | AK6: 23092 | AL6: =48783-AK6 -> 25691 | AM6: =81271-AK6-AL6 -> 32488 | AN6: =109108-AK6-AL6-AM6 -> 27837 | AO6: =SUM(AK6:AN6) -> 109108 | AP6: =41757-AQ6 -> 17066 | AQ6: 24691 | AR6: 14390 | AS6: =86797-AP6-AQ6-AR6 -> 30650 | AT6: =SUM(AP6:AS6) -> 86797 | AU6: =37358-AV6 -> 16991 | AV6: 20367 | AW6: 20924 | AX6: =83972-SUM(AU6:AW6) -> 25690 | AY6: =SUM(AU6:AX6) -> 83972 | AZ6: 15651 | BA6: 16580 | BB6: 20784 | BC6: =64335-SUM(AZ6:BB6) -> 11320 | BD6: =SUM(AZ6:BC6) -> 64335 | BE6: 13965 | BF6: 8957 | BG6: 8655 | BH6: =44568-SUM(BE6:BG6) -> 12991 | BI6: =SUM(BE6:BH6) -> 44568 | BJ6: 12943 | BK6: 26460 | BL6: 8263 | BM6: =53129-SUM(BJ6:BL6) -> 5463 | BN6: =SUM(BJ6:BM6) -> 53129 | BO6: 17607 | BP6: 5834 | BQ6: 5714 | BR6: =34083-SUM(BO6:BQ6) -> 4928 | BS6: =SUM(BO6:BR6) -> 34083 | BT6: 4121 | BU6: 4726 | BV6: 6810 | BW6: =23331-SUM(BT6:BV6) -> 7674 | BX6: =SUM(BT6:BW6) -> 23331 | BY6: 4433 | BZ6: 3977 | CA6: 8469 | CB6: =25100-SUM(BY6:CA6) -> 8221 | CC6: =SUM(BY6:CB6) -> 25100 | CD6: 11484 | CE6: 13481 | CF6: 17678 | CG6: =70655-SUM(CD6:CF6) -> 28012 | CH6: =SUM(CD6:CG6) -> 70655 | CI6: 21130 | CJ6: 24781 | CK6: 24806 | CL6: =113605-SUM(CI6:CK6) -> 42888 | CM6: =SUM(CI6:CL6) -> 113605 | CN6: 19900 | CO6: 29683 | CP6: 30252 | CQ6: =100623-SUM(CN6:CP6) -> 20788 | CR6: =SUM(CN6:CQ6) -> 100623 | CS6: 16220 | CT6: =36660-CS6 -> 20440 | CU6: =58236-SUM(CS6:CT6) -> 21576 | CV6: =85917-SUM(CS6:CU6) -> 27681 | CW6: =SUM(CS6:CV6) -> 85917 | CX6: 19755 | CY6: =43338-CX6 -> 23583 | CZ6: =68671-SUM(CX6:CY6) -> 25333 | DA6: =95542-SUM(CX6:CZ6) -> 26871 | DB6: =SUM(CX6:DA6) -> 95542 | DC6: 28111 | DD6: =54379-DC6 -> 26268 | DE6: =82693-SUM(DC6:DD6) -> 28314 | DF6: =111635-SUM(DC6:DE6) -> 28942 | DG6: =SUM(DC6:DF6) -> 111635 | DH6: 31221 | DI6: =75560-DH6 -> 44339 | DJ6: =Forecasts!DJ42 -> 32960.464 | DK6: =Forecasts!DK42 -> 36591.317 | DL6: =SUM(DH6:DK6) -> 145111.78 | DM6: =Forecasts!DM42 -> 28754.229 | DN6: =Forecasts!DN42 -> 30006.895 | DO6: =Forecasts!DO42 -> 31048.697 | DP6: =Forecasts!DP42 -> 33794.514 | DQ6: =SUM(DM6:DP6) -> 123604.34 | DR6: =Forecasts!DR42 -> 32005.741 | DS6: =Forecasts!DS42 -> 33090.834 | DT6: =Forecasts!DT42 -> 34043.026 | DU6: =Forecasts!DU42 -> 36792.267 | DV6: =SUM(DR6:DU6) -> 135931.87 | DW6: =Forecasts!DW42 -> 34737.191 | DX6: =Forecasts!DX42 -> 35802.383 | DY6: =Forecasts!DY42 -> 36710.503 | DZ6: =Forecasts!DZ42 -> 39521.818 | EA6: =SUM(DW6:DZ6) -> 146771.9 | EB6: =Forecasts!EB42 -> 37283.081 | EC6: =Forecasts!EC42 -> 38351.272 | ED6: =Forecasts!ED42 -> 39233.452 | EE6: =Forecasts!EE42 -> 42098.751 | EF6: =SUM(EB6:EE6) -> 156966.56
A7: Deductions | B7: =B8 -> -6878 | C7: =C8 -> -6878 | D7: =D8 -> -5069 | E7: =E8 -> -13740 | F7: =SUM(B7:E7) -> -32565 | G7: =G8 -> -7917 | H7: =H8 -> -11628 | I7: =I8 -> -10928 | J7: =J8 -> -5878 | K7: =SUM(G7:J7) -> -36351 | L7: =L8 -> -10369 | M7: =M8 -> -13345 | N7: =N8 -> -4993 | O7: =O8 -> -11380 | P7: =SUM(L7:O7) -> -40087 | Q7: =Q8 -> -11770 | R7: =R8 -> -16002 | S7: =S8 -> -16844 | T7: =T8 -> -36284 | U7: =SUM(Q7:T7) -> -80900 | V7: =V8 -> -21734 | W7: =W8 -> -35238 | X7: =X8 -> -23275 | Y7: =Y8 -> -39761 | Z7: =SUM(V7:Y7) -> -120008 | AA7: =AA8 -> -27542 | AB7: =AB8 -> -34115 | AC7: =AC8 -> -48118 | AD7: =AD8 -> -36393 | AE7: =SUM(AA7:AD7) -> -146168 | AF7: =AF8 -> -37721 | AG7: =AG8 -> -28704 | AH7: =AH8 -> -40990 | AI7: =AI8 -> -56031 | AJ7: =SUM(AF7:AI7) -> -163446 | AK7: =AK8 -> -48141 | AL7: =AL8 -> -55252 | AM7: =AM8 -> -59788 | AN7: =AN8 -> -85797 | AO7: =SUM(AK7:AN7) -> -248978 | AP7: =AP8 -> -56299 | AQ7: =AQ8 -> -53676 | AR7: =AR8 -> -59168 | AS7: =AS8 -> -929 | AT7: =SUM(AP7:AS7) -> -170072 | AU7: =AU8 -> -35572 | AV7: =AV8 -> -37731 | AW7: =AW8 -> -40690 | AX7: =AX8 -> -46461 | AY7: =SUM(AU7:AX7) -> -160454 | AZ7: =AZ8 -> -35705 | BA7: =BA8 -> -38886 | BB7: =BB8 -> -14681 | BC7: =BC8 -> -39364 | BD7: =SUM(AZ7:BC7) -> -128636 | BE7: =BE8 -> -32796 | BF7: =BF8 -> -28179 | BG7: =BG8 -> -35143 | BH7: =BH8 -> -28500 | BI7: =SUM(BE7:BH7) -> -124618 | BJ7: =BJ8 -> -22520 | BK7: =BK8 -> -21157 | BL7: =BL8 -> -22577 | BM7: =BM8 -> -29140 | BN7: =SUM(BJ7:BM7) -> -95394 | BO7: =BO8 -> -20025 | BP7: =BP8 -> -16351 | BQ7: =BQ8 -> -16670 | BR7: =BR8 -> -23105 | BS7: =SUM(BO7:BR7) -> -76151 | BT7: =BT8 -> -13530 | BU7: =BU8 -> -17982 | BV7: =BV8 -> -19764 | BW7: =BW8 -> -33895 | BX7: =SUM(BT7:BW7) -> -85171 | BY7: =BY8 -> -21673 | BZ7: =BZ8 -> -23017 | CA7: =CA8 -> -25119 | CB7: =CB8 -> -32086 | CC7: =SUM(BY7:CB7) -> -101895 | CD7: =CD8 -> -20434 | CE7: =CE8 -> -21930 | CF7: =CF8 -> -28962 | CG7: =CG8 -> -30775 | CH7: =SUM(CD7:CG7) -> -102101 | CI7: =CI8 -> -26502 | CJ7: =CJ8 -> -31935 | CK7: =CK8 -> -33457 | CL7: =CL8 -> -34933 | CM7: =SUM(CI7:CL7) -> -126827 | CN7: =CN8 -> -27449 | CO7: =CO8 -> -34008 | CP7: =CP8 -> -40463 | CQ7: =CQ8 -> -41633 | CR7: =SUM(CN7:CQ7) -> -143553 | CS7: =CS8 -> -33896 | CT7: =CT8 -> -45385 | CU7: =CU8 -> -47004 | CV7: =CV8 -> -50690 | CW7: =SUM(CS7:CV7) -> -176975 | CX7: =CX8 -> -41664 | CY7: =CY8 -> -52433 | CZ7: =CZ8 -> -57154 | DA7: =DA8 -> -68710 | DB7: =SUM(CX7:DA7) -> -219961 | DC7: =DC8 -> -50623 | DD7: =DD8 -> -60773 | DE7: =DE8 -> -62927 | DF7: =DF8 -> -81908 | DG7: =SUM(DC7:DF7) -> -256231 | DH7: =DH8 -> -56273 | DI7: =DI8 -> -68051 | DJ7: =DJ8 -> -70932.519 | DK7: =DK8 -> -75834.244 | DL7: =SUM(DH7:DK7) -> -271090.76 | DM7: =DM8 -> -60406.885 | DN7: =DN8 -> -63038.485 | DO7: =DO8 -> -65227.103 | DP7: =DP8 -> -70995.516 | DQ7: =SUM(DM7:DP7) -> -259667.99 | DR7: =DR8 -> -67237.66 | DS7: =DS8 -> -69517.225 | DT7: =DT8 -> -71517.589 | DU7: =DU8 -> -77293.195 | DV7: =SUM(DR7:DU7) -> -285565.67 | DW7: =DW8 -> -72975.892 | DX7: =DX8 -> -75213.646 | DY7: =DY8 -> -77121.426 | DZ7: =DZ8 -> -83027.435 | EA7: =SUM(DW7:DZ7) -> -308338.4 | EB7: =EB8 -> -78324.296 | EC7: =EC8 -> -80568.351 | ED7: =ED8 -> -82421.635 | EE7: =EE8 -> -88441.057 | EF7: =SUM(EB7:EE7) -> -329755.34
A8: Taxes and other deductions | B8: =(-18825-SUM(D8))/2 -> -6878 | C8: =B8 -> -6878 | D8: -5069 | E8: -13740 | F8: =SUM(B8:E8) -> -32565 | G8: =-7917 -> -7917 | H8: =-11628 -> -11628 | I8: =-10928 -> -10928 | J8: =-5878 -> -5878 | K8: =SUM(G8:J8) -> -36351 | L8: =-10369 -> -10369 | M8: =-13345 -> -13345 | N8: =-28707-L8-M8 -> -4993 | O8: =-40087-SUM(L8:N8) -> -11380 | P8: =SUM(L8:O8) -> -40087 | Q8: -11770 | R8: =-27772-Q8 -> -16002 | S8: -16844 | T8: =-80900-SUM(Q8:S8) -> -36284 | U8: =SUM(Q8:T8) -> -80900 | V8: -21734 | W8: -35238 | X8: -23275 | Y8: =-120008-SUM(V8:X8) -> -39761 | Z8: =SUM(V8:Y8) -> -120008 | AA8: -27542 | AB8: -34115 | AC8: -48118 | AD8: -36393 | AE8: =SUM(AA8:AD8) -> -146168 | AF8: -37721 | AG8: -28704 | AH8: -40990 | AI8: -56031 | AJ8: =SUM(AF8:AI8) -> -163446 | AK8: -48141 | AL8: =-103393-AK8 -> -55252 | AM8: =-163181-AK8-AL8 -> -59788 | AN8: =-248978-AK8-AL8-AM8 -> -85797 | AO8: =SUM(AK8:AN8) -> -248978 | AP8: =-109975-AQ8 -> -56299 | AQ8: -53676 | AR8: -59168 | AS8: =-170072-AP8-AQ8-AR8 -> -929 | AT8: =SUM(AP8:AS8) -> -170072 | AU8: =-73303-AV8 -> -35572 | AV8: -37731 | AW8: -40690 | AX8: =-160454-SUM(AU8:AW8) -> -46461 | AY8: =SUM(AU8:AX8) -> -160454 | AZ8: -35705 | BA8: -38886 | BB8: -14681 | BC8: =-128636-SUM(AZ8:BB8) -> -39364 | BD8: =SUM(AZ8:BC8) -> -128636 | BE8: -32796 | BF8: -28179 | BG8: -35143 | BH8: =-124618-SUM(BE8:BG8) -> -28500 | BI8: =SUM(BE8:BH8) -> -124618 | BJ8: -22520 | BK8: -21157 | BL8: -22577 | BM8: =-95394-SUM(BJ8:BL8) -> -29140 | BN8: =SUM(BJ8:BM8) -> -95394 | BO8: -20025 | BP8: -16351 | BQ8: -16670 | BR8: =-76151-SUM(BO8:BQ8) -> -23105 | BS8: =SUM(BO8:BR8) -> -76151 | BT8: -13530 | BU8: -17982 | BV8: -19764 | BW8: =-85171-SUM(BT8:BV8) -> -33895 | BX8: =SUM(BT8:BW8) -> -85171 | BY8: -21673 | BZ8: -23017 | CA8: -25119 | CB8: =-101895-SUM(BY8:CA8) -> -32086 | CC8: =SUM(BY8:CB8) -> -101895 | CD8: -20434 | CE8: -21930 | CF8: -28962 | CG8: =-102101-SUM(CD8:CF8) -> -30775 | CH8: =SUM(CD8:CG8) -> -102101 | CI8: -26502 | CJ8: -31935 | CK8: -33457 | CL8: =-126827-SUM(CI8:CK8) -> -34933 | CM8: =SUM(CI8:CL8) -> -126827 | CN8: -27449 | CO8: -34008 | CP8: -40463 | CQ8: =-143553-SUM(CN8:CP8) -> -41633 | CR8: =SUM(CN8:CQ8) -> -143553 | CS8: -33896 | CT8: =-79281-CS8 -> -45385 | CU8: =-126285-SUM(CS8:CT8) -> -47004 | CV8: =-176975-SUM(CS8:CU8) -> -50690 | CW8: =SUM(CS8:CV8) -> -176975 | CX8: -41664 | CY8: =-94097-CX8 -> -52433 | CZ8: =-151251-SUM(CX8:CY8) -> -57154 | DA8: =-219961-SUM(CX8:CZ8) -> -68710 | DB8: =SUM(CX8:DA8) -> -219961 | DC8: -50623 | DD8: =-111396-DC8 -> -60773 | DE8: =-174323-SUM(DC8:DD8) -> -62927 | DF8: =-256231-SUM(DC8:DE8) -> -81908 | DG8: =SUM(DC8:DF8) -> -256231 | DH8: -56273 | DI8: =-124324-DH8 -> -68051 | DJ8: =-DJ9*DJ$4 -> -70932.519 | DK8: =-DK9*DK$4 -> -75834.244 | DL8: =SUM(DH8:DK8) -> -271090.76 | DM8: =-DM9*DM$4 -> -60406.885 | DN8: =-DN9*DN$4 -> -63038.485 | DO8: =-DO9*DO$4 -> -65227.103 | DP8: =-DP9*DP$4 -> -70995.516 | DQ8: =SUM(DM8:DP8) -> -259667.99 | DR8: =-DR9*DR$4 -> -67237.66 | DS8: =-DS9*DS$4 -> -69517.225 | DT8: =-DT9*DT$4 -> -71517.589 | DU8: =-DU9*DU$4 -> -77293.195 | DV8: =SUM(DR8:DU8) -> -285565.67 | DW8: =-DW9*DW$4 -> -72975.892 | DX8: =-DX9*DX$4 -> -75213.646 | DY8: =-DY9*DY$4 -> -77121.426 | DZ8: =-DZ9*DZ$4 -> -83027.435 | EA8: =SUM(DW8:DZ8) -> -308338.4 | EB8: =-EB9*EB$4 -> -78324.296 | EC8: =-EC9*EC$4 -> -80568.351 | ED8: =-ED9*ED$4 -> -82421.635 | EE8: =-EE9*EE$4 -> -88441.057 | EF8: =SUM(EB8:EE8) -> -329755.34
A9: % of Gross Revenues | B9: =-B8/B$4 -> 0.059046989 | C9: =-C8/C$4 -> 0.059046989 | D9: =-D8/D$4 -> 0.039670055 | E9: =-E8/E$4 -> 0.070010598 | F9: =-F8/F$4 -> 0.058464781 | G9: =-G8/G$4 -> 0.04446354 | H9: =-H8/H$4 -> 0.075343575 | I9: =-I8/I$4 -> 0.04141292 | ... DI9: =-DI8/DI$4 -> 0.026697953 | DJ9: =DI9*80%+20%*2.08% -> 0.025518362 | DK9: =DJ9*80%+20%*2.08% -> 0.02457469 | DL9: =-DL8/DL$4 -> 0.025828594 | DM9: 0.0208 | DN9: =DM9 -> 0.0208 | DO9: =DN9 -> 0.0208 | DP9: =DO9 -> 0.0208 | DQ9: =-DQ8/DQ$4 -> 0.0208 | DR9: =DP9 -> 0.0208 | DS9: =DR9 -> 0.0208 | DT9: =DS9 -> 0.0208 | DU9: =DT9 -> 0.0208 | DV9: =-DV8/DV$4 -> 0.0208 | DW9: =DU9 -> 0.0208 | DX9: =DW9 -> 0.0208 | DY9: =DX9 -> 0.0208 | DZ9: =DY9 -> 0.0208 | EA9: =-EA8/EA$4 -> 0.0208 | EB9: =DZ9 -> 0.0208 | EC9: =EB9 -> 0.0208 | ED9: =EC9 -> 0.0208 | EE9: =ED9 -> 0.0208 | EF9: =-EF8/EF$4 -> 0.0208
A10: Net Revenues | B10: =B4+B7 -> 109605.5 | C10: =C4+C7 -> 109605.5 | D10: =D4+D7 -> 122710 | E10: =E4+E7 -> 182516 | F10: =SUM(B10:E10) -> 524437 | G10: =G4+G7 -> 170139 | H10: =H4+H7 -> 142705 | I10: =I4+I7 -> 252951 | J10: =J4+J7 -> 123053 | K10: =SUM(G10:J10) -> 688848 | L10: =L4+L7 -> 231079 | M10: =M4+M7 -> 262002 | N10: =N4+N7 -> 232815 | O10: =O4+O7 -> 390785 | P10: =SUM(L10:O10) -> 1116681 | Q10: =Q4+Q7 -> 287491 | R10: =R4+R7 -> 371296 | S10: =S4+S7 -> 414824 | T10: =T4+T7 -> 924928 | U10: =SUM(Q10:T10) -> 1998539 | V10: =V4+V7 -> 550845 | W10: =W4+W7 -> 794881 | X10: =X4+X7 -> 750717 | Y10: =Y4+Y7 -> 750998 | Z10: =SUM(V10:Y10) -> 2847441 | AA10: =AA4+AA7 -> 671454 | AB10: =AB4+AB7 -> 875600 | AC10: =AC4+AC7 -> 1348868 | AD10: =AD4+AD7 -> 1191903 | AE10: =SUM(AA10:AD10) -> 4087825 | AF10: =AF4+AF7 -> 1132448 | AG10: =AG4+AG7 -> 1205835 | AH10: =AH4+AH7 -> 1162549 | AI10: =AI4+AI7 -> 1389273 | AJ10: =SUM(AF10:AI10) -> 4890105 | AK10: =AK4+AK7 -> 1200742 | AL10: =AL4+AL7 -> 1382884 | AM10: =AM4+AM7 -> 1559602 | AN10: =AN4+AN7 -> 1983553 | AO10: =SUM(AK10:AN10) -> 6126781 | AP10: =AP4+AP7 -> 1466343 | AQ10: =AQ4+AQ7 -> 1385263 | AR10: =AR4+AR7 -> 1349952 | AS10: =AS4+AS7 -> 1431121 | AT10: =SUM(AP10:AS10) -> 5632679 | AU10: =AU4+AU7 -> 1215370 | AV10: =AV4+AV7 -> 1372419 | AW10: =AW4+AW7 -> 1394448 | AX10: =AX4+AX7 -> 1389645 | AY10: =SUM(AU10:AX10) -> 5371882 | AZ10: =AZ4+AZ7 -> 1315362 | BA10: =BA4+BA7 -> 1358331 | BB10: =BB4+BB7 -> 1613696 | BC10: =BC4+BC7 -> 1530538 | BD10: =SUM(AZ10:BC10) -> 5817927 | BE10: =BE4+BE7 -> 1035214 | BF10: =BF4+BF7 -> 1137683 | BG10: =BG4+BG7 -> 1137733 | BH10: =BH4+BH7 -> 1030554 | BI10: =SUM(BE10:BH10) -> 4341184 | BJ10: =BJ4+BJ7 -> 810706 | BK10: =BK4+BK7 -> 641033 | BL10: =BL4+BL7 -> 824807 | BM10: =BM4+BM7 -> 918764 | BN10: =SUM(BJ10:BM10) -> 3195310 | BO10: =BO4+BO7 -> 692387 | BP10: =BP4+BP7 -> 574756 | BQ10: =BQ4+BQ7 -> 597827 | BR10: =BR4+BR7 -> 808800 | BS10: =SUM(BO10:BR10) -> 2673770 | BT10: =BT4+BT7 -> 450622 | BU10: =BU4+BU7 -> 639539 | BV10: =BV4+BV7 -> 724825 | BW10: =BW4+BW7 -> 1077171 | BX10: =SUM(BT10:BW10) -> 2892157 | BY10: =BY4+BY7 -> 826236 | BZ10: =BZ4+BZ7 -> 936622 | CA10: =CA4+CA7 -> 934759 | CB10: =CB4+CB7 -> 1233206 | CC10: =SUM(BY10:CB10) -> 3930823 | CD10: =CD4+CD7 -> 764755 | CE10: =CE4+CE7 -> 838808 | CF10: =CF4+CF7 -> 1163503 | CG10: =CG4+CG7 -> 1056630 | CH10: =SUM(CD10:CG10) -> 3823696 | CI10: =CI4+CI7 -> 1003732 | CJ10: =CJ4+CJ7 -> 1182019 | CK10: =CK4+CK7 -> 1288339 | CL10: =CL4+CL7 -> 1316743 | CM10: =SUM(CI10:CL10) -> 4790833 | CN10: =CN4+CN7 -> 1231652 | CO10: =CO4+CO7 -> 1250083 | CP10: =CP4+CP7 -> 1559644 | CQ10: =CQ4+CQ7 -> 1370916 | CR10: =SUM(CN10:CQ10) -> 5412295 | CS10: =CS4+CS7 -> 1283426 | CT10: =CT4+CT7 -> 1633055 | CU10: =CU4+CU7 -> 1625987 | CV10: =CV4+CV7 -> 1710231 | CW10: =SUM(CS10:CV10) -> 6252699 | CX10: =CX4+CX7 -> 1572911 | CY10: =CY4+CY7 -> 1856857 | CZ10: =CZ4+CZ7 -> 2029651 | DA10: =DA4+DA7 -> 2506269 | DB10: =SUM(CX10:DA10) -> 7965688 | DC10: =DC4+DC7 -> 1952744 | DD10: =DD4+DD7 -> 2107130 | DE10: =DE4+DE7 -> 2128446 | DF10: =DF4+DF7 -> 3235174 | DG10: =SUM(DC10:DF10) -> 9423494 | DH10: =DH4+DH7 -> 2025033 | DI10: =DI4+DI7 -> 2480871 | DJ10: =DJ4+DJ7 -> 2708733.3 | DK10: =DK4+DK7 -> 3010033.5 | DL10: =SUM(DH10:DK10) -> 10224671 | DM10: =DM4+DM7 -> 2843770.3 | DN10: =DN4+DN7 -> 2967657.9 | DO10: =DO4+DO7 -> 3070691.3 | DP10: =DP4+DP7 -> 3342250.4 | DQ10: =SUM(DM10:DP10) -> 12224370 | DR10: =DR4+DR7 -> 3165342.2 | DS10: =DS4+DS7 -> 3272657 | DT10: =DT4+DT7 -> 3366828 | DU10: =DU4+DU7 -> 3638725.8 | DV10: =SUM(DR10:DU10) -> 13443553 | DW10: =DW4+DW7 -> 3435480.4 | DX10: =DX4+DX7 -> 3540827 | DY10: =DY4+DY7 -> 3630639.4 | DZ10: =DZ4+DZ7 -> 3908676.2 | EA10: =SUM(DW10:DZ10) -> 14515623 | EB10: =EB4+EB7 -> 3687266.9 | EC10: =EC4+EC7 -> 3792910.1 | ED10: =ED4+ED7 -> 3880157 | EE10: =EE4+EE7 -> 4163532.8 | EF10: =SUM(EB10:EE10) -> 15523867
